{
  "version": 8,
  "blockIdVersion": 11,
  "anchorX": 0,
  "anchorY": 3,
  "anchorZ": 0,
  "blocks": [
    {
      "x": -1,
      "y": 0,
      "z": -1,
      "name": "Brick"
    },
    {
      "x": -1,
      "y": 1,
      "z": -1,
      "name": "Brick"
    },
    {
      "x": -1,
      "y": 2,
      "z": -1,
      "name": "Brick"
    },
    {
      "x": -1,
      "y": 3,
      "z": -1,
      "name": "Brick"
    },
    {
      "x": -1,
      "y": 4,
      "z": -1,
      "name": "Brick"
    },
    {
      "x": -1,
      "y": 5,
      "z": -1,
      "name": "Brick"
    },
    {
      "x": -1,
      "y": 6,
      "z": -1,
      "name": "Brick"
    },
    {
      "x": -1,
      "y": 0,
      "z": 0,
      "name": "Brick"
    },
    {
      "x": -1,
      "y": 1,
      "z": 0,
      "name": "Brick"
    },
    {
      "x": -1,
      "y": 2,
      "z": 0,
      "name": "Brick"
    },
    {
      "x": -1,
      "y": 3,
      "z": 0,
      "name": "Brick"
    },
    {
      "x": -1,
      "y": 4,
      "z": 0,
      "name": "Brick"
    },
    {
      "x": -1,
      "y": 5,
      "z": 0,
      "name": "Brick"
    },
    {
      "x": -1,
      "y": 6,
      "z": 0,
      "name": "Brick"
    },
    {
      "x": -1,
      "y": 0,
      "z": 1,
      "name": "Brick"
    },
    {
      "x": -1,
      "y": 1,
      "z": 1,
      "name": "Brick"
    },
    {
      "x": -1,
      "y": 2,
      "z": 1,
      "name": "Brick"
    },
    {
      "x": -1,
      "y": 3,
      "z": 1,
      "name": "Brick"
    },
    {
      "x": -1,
      "y": 4,
      "z": 1,
      "name": "Brick"
    },
    {
      "x": -1,
      "y": 5,
      "z": 1,
      "name": "Brick"
    },
    {
      "x": -1,
      "y": 6,
      "z": 1,
      "name": "Brick"
    },
    {
      "x": 0,
      "y": 0,
      "z": -1,
      "name": "Brick"
    },
    {
      "x": 0,
      "y": 1,
      "z": -1,
      "name": "Brick"
    },
    {
      "x": 0,
      "y": 2,
      "z": -1,
      "name": "Brick"
    },
    {
      "x": 0,
      "y": 3,
      "z": -1,
      "name": "Brick"
    },
    {
      "x": 0,
      "y": 4,
      "z": -1,
      "name": "Brick"
    },
    {
      "x": 0,
      "y": 5,
      "z": -1,
      "name": "Brick"
    },
    {
      "x": 0,
      "y": 6,
      "z": -1,
      "name": "Brick"
    },
    {
      "x": 0,
      "y": 0,
      "z": 0,
      "name": "Brick"
    },
    {
      "x": 0,
      "y": 1,
      "z": 0,
      "name": "Brick"
    },
    {
      "x": 0,
      "y": 2,
      "z": 0,
      "name": "Brick"
    },
    {
      "x": 0,
      "y": 3,
      "z": 0,
      "name": "Brick"
    },
    {
      "x": 0,
      "y": 4,
      "z": 0,
      "name": "Brick"
    },
    {
      "x": 0,
      "y": 5,
      "z": 0,
      "name": "Brick"
    },
    {
      "x": 0,
      "y": 6,
      "z": 0,
      "name": "Brick"
    },
    {
      "x": 0,
      "y": 0,
      "z": 1,
      "name": "Brick"
    },
    {
      "x": 0,
      "y": 1,
      "z": 1,
      "name": "Brick"
    },
    {
      "x": 0,
      "y": 2,
      "z": 1,
      "name": "Brick"
    },
    {
      "x": 0,
      "y": 3,
      "z": 1,
      "name": "Brick"
    },
    {
      "x": 0,
      "y": 4,
      "z": 1,
      "name": "Brick"
    },
    {
      "x": 0,
      "y": 5,
      "z": 1,
      "name": "Brick"
    },
    {
      "x": 0,
      "y": 6,
      "z": 1,
      "name": "Brick"
    },
    {
      "x": 1,
      "y": 0,
      "z": -1,
      "name": "Brick"
    },
    {
      "x": 1,
      "y": 1,
      "z": -1,
      "name": "Brick"
    },
    {
      "x": 1,
      "y": 2,
      "z": -1,
      "name": "Brick"
    },
    {
      "x": 1,
      "y": 3,
      "z": -1,
      "name": "Brick"
    },
    {
      "x": 1,
      "y": 4,
      "z": -1,
      "name": "Brick"
    },
    {
      "x": 1,
      "y": 5,
      "z": -1,
      "name": "Brick"
    },
    {
      "x": 1,
      "y": 6,
      "z": -1,
      "name": "Brick"
    },
    {
      "x": 1,
      "y": 0,
      "z": 0,
      "name": "Brick"
    },
    {
      "x": 1,
      "y": 1,
      "z": 0,
      "name": "Brick"
    },
    {
      "x": 1,
      "y": 2,
      "z": 0,
      "name": "Brick"
    },
    {
      "x": 1,
      "y": 3,
      "z": 0,
      "name": "Brick"
    },
    {
      "x": 1,
      "y": 4,
      "z": 0,
      "name": "Brick"
    },
    {
      "x": 1,
      "y": 5,
      "z": 0,
      "name": "Brick"
    },
    {
      "x": 1,
      "y": 6,
      "z": 0,
      "name": "Brick"
    },
    {
      "x": 1,
      "y": 0,
      "z": 1,
      "name": "Brick"
    },
    {
      "x": 1,
      "y": 1,
      "z": 1,
      "name": "Brick"
    },
    {
      "x": 1,
      "y": 2,
      "z": 1,
      "name": "Brick"
    },
    {
      "x": 1,
      "y": 3,
      "z": 1,
      "name": "Brick"
    },
    {
      "x": 1,
      "y": 4,
      "z": 1,
      "name": "Brick"
    },
    {
      "x": 1,
      "y": 5,
      "z": 1,
      "name": "Brick"
    },
    {
      "x": 1,
      "y": 6,
      "z": 1,
      "name": "Brick"
    }
  ]
}