{
  "version": 8,
  "blockIdVersion": 11,
  "anchorX": 0,
  "anchorY": 0,
  "anchorZ": 0,
  "blocks": [
    {
      "x": -79,
      "y": 61,
      "z": -6,
      "name": "Zone_Launch",
      "rotation": 2
    },
    {
      "x": -79,
      "y": 62,
      "z": -6,
      "name": "Zone_Launch",
      "rotation": 2
    },
    {
      "x": -79,
      "y": 63,
      "z": -6,
      "name": "Zone_Launch",
      "rotation": 2
    },
    {
      "x": -79,
      "y": 64,
      "z": -6,
      "name": "Zone_Launch",
      "rotation": 3
    },
    {
      "x": -79,
      "y": 61,
      "z": -5,
      "name": "Zone_Launch",
      "rotation": 2
    },
    {
      "x": -79,
      "y": 62,
      "z": -5,
      "name": "Zone_Launch",
      "rotation": 2
    },
    {
      "x": -79,
      "y": 63,
      "z": -5,
      "name": "Zone_Launch",
      "rotation": 2
    },
    {
      "x": -79,
      "y": 64,
      "z": -5,
      "name": "Zone_Launch",
      "rotation": 3
    },
    {
      "x": -79,
      "y": 61,
      "z": -4,
      "name": "Zone_Launch",
      "rotation": 2
    },
    {
      "x": -79,
      "y": 62,
      "z": -4,
      "name": "Zone_Launch",
      "rotation": 2
    },
    {
      "x": -79,
      "y": 63,
      "z": -4,
      "name": "Zone_Launch",
      "rotation": 2
    },
    {
      "x": -79,
      "y": 64,
      "z": -4,
      "name": "Zone_Launch",
      "rotation": 3
    },
    {
      "x": -79,
      "y": 61,
      "z": -3,
      "name": "Zone_Launch",
      "rotation": 2
    },
    {
      "x": -79,
      "y": 62,
      "z": -3,
      "name": "Zone_Launch",
      "rotation": 2
    },
    {
      "x": -79,
      "y": 63,
      "z": -3,
      "name": "Zone_Launch",
      "rotation": 2
    },
    {
      "x": -79,
      "y": 64,
      "z": -3,
      "name": "Zone_Launch",
      "rotation": 3
    },
    {
      "x": -79,
      "y": 61,
      "z": -2,
      "name": "Zone_Launch",
      "rotation": 2
    },
    {
      "x": -79,
      "y": 62,
      "z": -2,
      "name": "Zone_Launch",
      "rotation": 2
    },
    {
      "x": -79,
      "y": 63,
      "z": -2,
      "name": "Zone_Launch",
      "rotation": 2
    },
    {
      "x": -79,
      "y": 64,
      "z": -2,
      "name": "Zone_Launch",
      "rotation": 3
    },
    {
      "x": -79,
      "y": 61,
      "z": -1,
      "name": "Zone_Launch",
      "rotation": 2
    },
    {
      "x": -79,
      "y": 62,
      "z": -1,
      "name": "Zone_Launch",
      "rotation": 2
    },
    {
      "x": -79,
      "y": 63,
      "z": -1,
      "name": "Zone_Launch",
      "rotation": 2
    },
    {
      "x": -79,
      "y": 64,
      "z": -1,
      "name": "Zone_Launch",
      "rotation": 3
    },
    {
      "x": -79,
      "y": 61,
      "z": 0,
      "name": "Zone_Launch",
      "rotation": 2
    },
    {
      "x": -79,
      "y": 62,
      "z": 0,
      "name": "Zone_Launch",
      "rotation": 2
    },
    {
      "x": -79,
      "y": 63,
      "z": 0,
      "name": "Zone_Launch",
      "rotation": 2
    },
    {
      "x": -79,
      "y": 64,
      "z": 0,
      "name": "Zone_Launch",
      "rotation": 3
    },
    {
      "x": -79,
      "y": 61,
      "z": 1,
      "name": "Zone_Launch",
      "rotation": 2
    },
    {
      "x": -79,
      "y": 62,
      "z": 1,
      "name": "Zone_Launch",
      "rotation": 2
    },
    {
      "x": -79,
      "y": 63,
      "z": 1,
      "name": "Zone_Launch",
      "rotation": 2
    },
    {
      "x": -79,
      "y": 64,
      "z": 1,
      "name": "Zone_Launch",
      "rotation": 3
    },
    {
      "x": -79,
      "y": 61,
      "z": 2,
      "name": "Zone_Launch",
      "rotation": 2
    },
    {
      "x": -79,
      "y": 62,
      "z": 2,
      "name": "Zone_Launch",
      "rotation": 2
    },
    {
      "x": -79,
      "y": 63,
      "z": 2,
      "name": "Zone_Launch",
      "rotation": 2
    },
    {
      "x": -79,
      "y": 64,
      "z": 2,
      "name": "Zone_Launch",
      "rotation": 3
    },
    {
      "x": -79,
      "y": 61,
      "z": 3,
      "name": "Zone_Launch",
      "rotation": 2
    },
    {
      "x": -79,
      "y": 62,
      "z": 3,
      "name": "Zone_Launch",
      "rotation": 2
    },
    {
      "x": -79,
      "y": 63,
      "z": 3,
      "name": "Zone_Launch",
      "rotation": 2
    },
    {
      "x": -79,
      "y": 64,
      "z": 3,
      "name": "Zone_Launch",
      "rotation": 3
    },
    {
      "x": -79,
      "y": 61,
      "z": 4,
      "name": "Zone_Launch",
      "rotation": 2
    },
    {
      "x": -79,
      "y": 62,
      "z": 4,
      "name": "Zone_Launch",
      "rotation": 2
    },
    {
      "x": -79,
      "y": 63,
      "z": 4,
      "name": "Zone_Launch",
      "rotation": 2
    },
    {
      "x": -79,
      "y": 64,
      "z": 4,
      "name": "Zone_Launch",
      "rotation": 3
    },
    {
      "x": -79,
      "y": 61,
      "z": 5,
      "name": "Zone_Launch",
      "rotation": 2
    },
    {
      "x": -79,
      "y": 62,
      "z": 5,
      "name": "Zone_Launch",
      "rotation": 2
    },
    {
      "x": -79,
      "y": 63,
      "z": 5,
      "name": "Zone_Launch",
      "rotation": 2
    },
    {
      "x": -79,
      "y": 64,
      "z": 5,
      "name": "Zone_Launch",
      "rotation": 3
    },
    {
      "x": -79,
      "y": 61,
      "z": 6,
      "name": "Zone_Launch",
      "rotation": 2
    },
    {
      "x": -79,
      "y": 62,
      "z": 6,
      "name": "Zone_Launch",
      "rotation": 2
    },
    {
      "x": -79,
      "y": 63,
      "z": 6,
      "name": "Zone_Launch",
      "rotation": 2
    },
    {
      "x": -79,
      "y": 64,
      "z": 6,
      "name": "Zone_Launch",
      "rotation": 3
    },
    {
      "x": -79,
      "y": 61,
      "z": 7,
      "name": "Zone_Launch",
      "rotation": 2
    },
    {
      "x": -79,
      "y": 62,
      "z": 7,
      "name": "Zone_Launch",
      "rotation": 2
    },
    {
      "x": -79,
      "y": 63,
      "z": 7,
      "name": "Zone_Launch",
      "rotation": 2
    },
    {
      "x": -79,
      "y": 64,
      "z": 7,
      "name": "Zone_Launch",
      "rotation": 3
    },
    {
      "x": -79,
      "y": 61,
      "z": 8,
      "name": "Zone_Launch",
      "rotation": 2
    },
    {
      "x": -79,
      "y": 62,
      "z": 8,
      "name": "Zone_Launch",
      "rotation": 2
    },
    {
      "x": -79,
      "y": 63,
      "z": 8,
      "name": "Zone_Launch",
      "rotation": 2
    },
    {
      "x": -79,
      "y": 64,
      "z": 8,
      "name": "Zone_Launch",
      "rotation": 3
    },
    {
      "x": -79,
      "y": 61,
      "z": 9,
      "name": "Zone_Launch",
      "rotation": 2
    },
    {
      "x": -79,
      "y": 62,
      "z": 9,
      "name": "Zone_Launch",
      "rotation": 2
    },
    {
      "x": -79,
      "y": 63,
      "z": 9,
      "name": "Zone_Launch",
      "rotation": 2
    },
    {
      "x": -79,
      "y": 64,
      "z": 9,
      "name": "Zone_Launch",
      "rotation": 3
    },
    {
      "x": -79,
      "y": 61,
      "z": 10,
      "name": "Zone_Launch",
      "rotation": 2
    },
    {
      "x": -79,
      "y": 62,
      "z": 10,
      "name": "Zone_Launch",
      "rotation": 2
    },
    {
      "x": -79,
      "y": 63,
      "z": 10,
      "name": "Zone_Launch",
      "rotation": 2
    },
    {
      "x": -79,
      "y": 64,
      "z": 10,
      "name": "Zone_Launch",
      "rotation": 3
    },
    {
      "x": -79,
      "y": 61,
      "z": 11,
      "name": "Zone_Launch",
      "rotation": 2
    },
    {
      "x": -79,
      "y": 62,
      "z": 11,
      "name": "Zone_Launch",
      "rotation": 2
    },
    {
      "x": -79,
      "y": 63,
      "z": 11,
      "name": "Zone_Launch",
      "rotation": 2
    },
    {
      "x": -79,
      "y": 64,
      "z": 11,
      "name": "Zone_Launch",
      "rotation": 3
    },
    {
      "x": -79,
      "y": 61,
      "z": 12,
      "name": "Zone_Launch",
      "rotation": 2
    },
    {
      "x": -79,
      "y": 62,
      "z": 12,
      "name": "Zone_Launch",
      "rotation": 2
    },
    {
      "x": -79,
      "y": 63,
      "z": 12,
      "name": "Zone_Launch",
      "rotation": 2
    },
    {
      "x": -79,
      "y": 64,
      "z": 12,
      "name": "Zone_Launch",
      "rotation": 3
    },
    {
      "x": -78,
      "y": 61,
      "z": -13,
      "name": "Zone_Launch",
      "rotation": 2
    },
    {
      "x": -78,
      "y": 62,
      "z": -13,
      "name": "Zone_Launch",
      "rotation": 2
    },
    {
      "x": -78,
      "y": 63,
      "z": -13,
      "name": "Zone_Launch",
      "rotation": 2
    },
    {
      "x": -78,
      "y": 64,
      "z": -13,
      "name": "Zone_Launch",
      "rotation": 3
    },
    {
      "x": -78,
      "y": 61,
      "z": -12,
      "name": "Zone_Launch",
      "rotation": 2
    },
    {
      "x": -78,
      "y": 62,
      "z": -12,
      "name": "Zone_Launch",
      "rotation": 2
    },
    {
      "x": -78,
      "y": 63,
      "z": -12,
      "name": "Zone_Launch",
      "rotation": 2
    },
    {
      "x": -78,
      "y": 64,
      "z": -12,
      "name": "Zone_Launch",
      "rotation": 3
    },
    {
      "x": -78,
      "y": 61,
      "z": -11,
      "name": "Zone_Launch",
      "rotation": 2
    },
    {
      "x": -78,
      "y": 62,
      "z": -11,
      "name": "Zone_Launch",
      "rotation": 2
    },
    {
      "x": -78,
      "y": 63,
      "z": -11,
      "name": "Zone_Launch",
      "rotation": 2
    },
    {
      "x": -78,
      "y": 64,
      "z": -11,
      "name": "Zone_Launch",
      "rotation": 3
    },
    {
      "x": -78,
      "y": 61,
      "z": -10,
      "name": "Zone_Launch",
      "rotation": 2
    },
    {
      "x": -78,
      "y": 62,
      "z": -10,
      "name": "Zone_Launch",
      "rotation": 2
    },
    {
      "x": -78,
      "y": 63,
      "z": -10,
      "name": "Zone_Launch",
      "rotation": 2
    },
    {
      "x": -78,
      "y": 64,
      "z": -10,
      "name": "Zone_Launch",
      "rotation": 3
    },
    {
      "x": -78,
      "y": 61,
      "z": -9,
      "name": "Zone_Launch",
      "rotation": 2
    },
    {
      "x": -78,
      "y": 62,
      "z": -9,
      "name": "Zone_Launch",
      "rotation": 2
    },
    {
      "x": -78,
      "y": 63,
      "z": -9,
      "name": "Zone_Launch",
      "rotation": 2
    },
    {
      "x": -78,
      "y": 64,
      "z": -9,
      "name": "Zone_Launch",
      "rotation": 3
    },
    {
      "x": -78,
      "y": 61,
      "z": -8,
      "name": "Zone_Launch",
      "rotation": 2
    },
    {
      "x": -78,
      "y": 62,
      "z": -8,
      "name": "Zone_Launch",
      "rotation": 2
    },
    {
      "x": -78,
      "y": 63,
      "z": -8,
      "name": "Zone_Launch",
      "rotation": 2
    },
    {
      "x": -78,
      "y": 64,
      "z": -8,
      "name": "Zone_Launch",
      "rotation": 3
    },
    {
      "x": -78,
      "y": 61,
      "z": -7,
      "name": "Zone_Launch",
      "rotation": 2
    },
    {
      "x": -78,
      "y": 62,
      "z": -7,
      "name": "Zone_Launch",
      "rotation": 2
    },
    {
      "x": -78,
      "y": 63,
      "z": -7,
      "name": "Zone_Launch",
      "rotation": 2
    },
    {
      "x": -78,
      "y": 64,
      "z": -7,
      "name": "Zone_Launch",
      "rotation": 3
    },
    {
      "x": -78,
      "y": 61,
      "z": -6,
      "name": "Zone_Launch",
      "rotation": 2
    },
    {
      "x": -78,
      "y": 62,
      "z": -6,
      "name": "Zone_Launch",
      "rotation": 2
    },
    {
      "x": -78,
      "y": 63,
      "z": -6,
      "name": "Zone_Launch",
      "rotation": 2
    },
    {
      "x": -78,
      "y": 64,
      "z": -6,
      "name": "Zone_Launch",
      "rotation": 3
    },
    {
      "x": -78,
      "y": 61,
      "z": -5,
      "name": "Zone_Launch",
      "rotation": 2
    },
    {
      "x": -78,
      "y": 62,
      "z": -5,
      "name": "Zone_Launch",
      "rotation": 2
    },
    {
      "x": -78,
      "y": 63,
      "z": -5,
      "name": "Zone_Launch",
      "rotation": 2
    },
    {
      "x": -78,
      "y": 64,
      "z": -5,
      "name": "Zone_Launch",
      "rotation": 1
    },
    {
      "x": -78,
      "y": 61,
      "z": -4,
      "name": "Zone_Launch",
      "rotation": 2
    },
    {
      "x": -78,
      "y": 62,
      "z": -4,
      "name": "Zone_Launch",
      "rotation": 2
    },
    {
      "x": -78,
      "y": 63,
      "z": -4,
      "name": "Zone_Launch",
      "rotation": 2
    },
    {
      "x": -78,
      "y": 64,
      "z": -4,
      "name": "Zone_Launch",
      "rotation": 1
    },
    {
      "x": -78,
      "y": 61,
      "z": -3,
      "name": "Zone_Launch",
      "rotation": 2
    },
    {
      "x": -78,
      "y": 62,
      "z": -3,
      "name": "Zone_Launch",
      "rotation": 2
    },
    {
      "x": -78,
      "y": 63,
      "z": -3,
      "name": "Zone_Launch",
      "rotation": 2
    },
    {
      "x": -78,
      "y": 64,
      "z": -3,
      "name": "Zone_Launch",
      "rotation": 1
    },
    {
      "x": -78,
      "y": 61,
      "z": -2,
      "name": "Zone_Launch",
      "rotation": 2
    },
    {
      "x": -78,
      "y": 62,
      "z": -2,
      "name": "Zone_Launch",
      "rotation": 2
    },
    {
      "x": -78,
      "y": 63,
      "z": -2,
      "name": "Zone_Launch",
      "rotation": 2
    },
    {
      "x": -78,
      "y": 64,
      "z": -2,
      "name": "Zone_Launch",
      "rotation": 1
    },
    {
      "x": -78,
      "y": 61,
      "z": -1,
      "name": "Zone_Launch",
      "rotation": 2
    },
    {
      "x": -78,
      "y": 62,
      "z": -1,
      "name": "Zone_Launch",
      "rotation": 2
    },
    {
      "x": -78,
      "y": 63,
      "z": -1,
      "name": "Zone_Launch",
      "rotation": 2
    },
    {
      "x": -78,
      "y": 64,
      "z": -1,
      "name": "Zone_Launch",
      "rotation": 1
    },
    {
      "x": -78,
      "y": 61,
      "z": 0,
      "name": "Zone_Launch",
      "rotation": 2
    },
    {
      "x": -78,
      "y": 62,
      "z": 0,
      "name": "Zone_Launch",
      "rotation": 2
    },
    {
      "x": -78,
      "y": 63,
      "z": 0,
      "name": "Zone_Launch",
      "rotation": 2
    },
    {
      "x": -78,
      "y": 64,
      "z": 0,
      "name": "Zone_Launch",
      "rotation": 1
    },
    {
      "x": -78,
      "y": 61,
      "z": 1,
      "name": "Zone_Launch",
      "rotation": 2
    },
    {
      "x": -78,
      "y": 62,
      "z": 1,
      "name": "Zone_Launch",
      "rotation": 2
    },
    {
      "x": -78,
      "y": 63,
      "z": 1,
      "name": "Zone_Launch",
      "rotation": 2
    },
    {
      "x": -78,
      "y": 64,
      "z": 1,
      "name": "Zone_Launch",
      "rotation": 1
    },
    {
      "x": -78,
      "y": 61,
      "z": 2,
      "name": "Zone_Launch",
      "rotation": 2
    },
    {
      "x": -78,
      "y": 62,
      "z": 2,
      "name": "Zone_Launch",
      "rotation": 2
    },
    {
      "x": -78,
      "y": 63,
      "z": 2,
      "name": "Zone_Launch",
      "rotation": 2
    },
    {
      "x": -78,
      "y": 64,
      "z": 2,
      "name": "Zone_Launch",
      "rotation": 1
    },
    {
      "x": -78,
      "y": 61,
      "z": 3,
      "name": "Zone_Launch",
      "rotation": 2
    },
    {
      "x": -78,
      "y": 62,
      "z": 3,
      "name": "Zone_Launch",
      "rotation": 2
    },
    {
      "x": -78,
      "y": 63,
      "z": 3,
      "name": "Zone_Launch",
      "rotation": 2
    },
    {
      "x": -78,
      "y": 64,
      "z": 3,
      "name": "Zone_Launch",
      "rotation": 1
    },
    {
      "x": -78,
      "y": 61,
      "z": 4,
      "name": "Zone_Launch",
      "rotation": 2
    },
    {
      "x": -78,
      "y": 62,
      "z": 4,
      "name": "Zone_Launch",
      "rotation": 2
    },
    {
      "x": -78,
      "y": 63,
      "z": 4,
      "name": "Zone_Launch",
      "rotation": 2
    },
    {
      "x": -78,
      "y": 64,
      "z": 4,
      "name": "Zone_Launch",
      "rotation": 1
    },
    {
      "x": -78,
      "y": 61,
      "z": 5,
      "name": "Zone_Launch",
      "rotation": 2
    },
    {
      "x": -78,
      "y": 62,
      "z": 5,
      "name": "Zone_Launch",
      "rotation": 2
    },
    {
      "x": -78,
      "y": 63,
      "z": 5,
      "name": "Zone_Launch",
      "rotation": 2
    },
    {
      "x": -78,
      "y": 64,
      "z": 5,
      "name": "Zone_Launch",
      "rotation": 1
    },
    {
      "x": -78,
      "y": 61,
      "z": 6,
      "name": "Zone_Launch",
      "rotation": 2
    },
    {
      "x": -78,
      "y": 62,
      "z": 6,
      "name": "Zone_Launch",
      "rotation": 2
    },
    {
      "x": -78,
      "y": 63,
      "z": 6,
      "name": "Zone_Launch",
      "rotation": 2
    },
    {
      "x": -78,
      "y": 64,
      "z": 6,
      "name": "Zone_Launch",
      "rotation": 1
    },
    {
      "x": -78,
      "y": 61,
      "z": 7,
      "name": "Zone_Launch",
      "rotation": 2
    },
    {
      "x": -78,
      "y": 62,
      "z": 7,
      "name": "Zone_Launch",
      "rotation": 2
    },
    {
      "x": -78,
      "y": 63,
      "z": 7,
      "name": "Zone_Launch",
      "rotation": 2
    },
    {
      "x": -78,
      "y": 64,
      "z": 7,
      "name": "Zone_Launch",
      "rotation": 1
    },
    {
      "x": -78,
      "y": 61,
      "z": 8,
      "name": "Zone_Launch",
      "rotation": 2
    },
    {
      "x": -78,
      "y": 62,
      "z": 8,
      "name": "Zone_Launch",
      "rotation": 2
    },
    {
      "x": -78,
      "y": 63,
      "z": 8,
      "name": "Zone_Launch",
      "rotation": 2
    },
    {
      "x": -78,
      "y": 64,
      "z": 8,
      "name": "Zone_Launch",
      "rotation": 1
    },
    {
      "x": -78,
      "y": 61,
      "z": 9,
      "name": "Zone_Launch",
      "rotation": 2
    },
    {
      "x": -78,
      "y": 62,
      "z": 9,
      "name": "Zone_Launch",
      "rotation": 2
    },
    {
      "x": -78,
      "y": 63,
      "z": 9,
      "name": "Zone_Launch",
      "rotation": 2
    },
    {
      "x": -78,
      "y": 64,
      "z": 9,
      "name": "Zone_Launch",
      "rotation": 1
    },
    {
      "x": -78,
      "y": 61,
      "z": 10,
      "name": "Zone_Launch",
      "rotation": 2
    },
    {
      "x": -78,
      "y": 62,
      "z": 10,
      "name": "Zone_Launch",
      "rotation": 2
    },
    {
      "x": -78,
      "y": 63,
      "z": 10,
      "name": "Zone_Launch",
      "rotation": 2
    },
    {
      "x": -78,
      "y": 64,
      "z": 10,
      "name": "Zone_Launch",
      "rotation": 1
    },
    {
      "x": -78,
      "y": 61,
      "z": 11,
      "name": "Zone_Launch",
      "rotation": 2
    },
    {
      "x": -78,
      "y": 62,
      "z": 11,
      "name": "Zone_Launch",
      "rotation": 2
    },
    {
      "x": -78,
      "y": 63,
      "z": 11,
      "name": "Zone_Launch",
      "rotation": 2
    },
    {
      "x": -78,
      "y": 64,
      "z": 11,
      "name": "Zone_Launch",
      "rotation": 1
    },
    {
      "x": -78,
      "y": 61,
      "z": 12,
      "name": "Zone_Launch",
      "rotation": 2
    },
    {
      "x": -78,
      "y": 62,
      "z": 12,
      "name": "Zone_Launch",
      "rotation": 2
    },
    {
      "x": -78,
      "y": 63,
      "z": 12,
      "name": "Zone_Launch",
      "rotation": 2
    },
    {
      "x": -78,
      "y": 64,
      "z": 12,
      "name": "Zone_Launch",
      "rotation": 3
    },
    {
      "x": -78,
      "y": 61,
      "z": 13,
      "name": "Zone_Launch",
      "rotation": 2
    },
    {
      "x": -78,
      "y": 62,
      "z": 13,
      "name": "Zone_Launch",
      "rotation": 2
    },
    {
      "x": -78,
      "y": 63,
      "z": 13,
      "name": "Zone_Launch",
      "rotation": 2
    },
    {
      "x": -78,
      "y": 64,
      "z": 13,
      "name": "Zone_Launch",
      "rotation": 3
    },
    {
      "x": -78,
      "y": 61,
      "z": 14,
      "name": "Zone_Launch",
      "rotation": 2
    },
    {
      "x": -78,
      "y": 62,
      "z": 14,
      "name": "Zone_Launch",
      "rotation": 2
    },
    {
      "x": -78,
      "y": 63,
      "z": 14,
      "name": "Zone_Launch",
      "rotation": 2
    },
    {
      "x": -78,
      "y": 64,
      "z": 14,
      "name": "Zone_Launch",
      "rotation": 3
    },
    {
      "x": -78,
      "y": 61,
      "z": 15,
      "name": "Zone_Launch",
      "rotation": 2
    },
    {
      "x": -78,
      "y": 62,
      "z": 15,
      "name": "Zone_Launch",
      "rotation": 2
    },
    {
      "x": -78,
      "y": 63,
      "z": 15,
      "name": "Zone_Launch",
      "rotation": 2
    },
    {
      "x": -78,
      "y": 64,
      "z": 15,
      "name": "Zone_Launch",
      "rotation": 3
    },
    {
      "x": -78,
      "y": 61,
      "z": 16,
      "name": "Zone_Launch",
      "rotation": 2
    },
    {
      "x": -78,
      "y": 62,
      "z": 16,
      "name": "Zone_Launch",
      "rotation": 2
    },
    {
      "x": -78,
      "y": 63,
      "z": 16,
      "name": "Zone_Launch",
      "rotation": 2
    },
    {
      "x": -78,
      "y": 64,
      "z": 16,
      "name": "Zone_Launch",
      "rotation": 3
    },
    {
      "x": -78,
      "y": 61,
      "z": 17,
      "name": "Zone_Launch",
      "rotation": 2
    },
    {
      "x": -78,
      "y": 62,
      "z": 17,
      "name": "Zone_Launch",
      "rotation": 2
    },
    {
      "x": -78,
      "y": 63,
      "z": 17,
      "name": "Zone_Launch",
      "rotation": 2
    },
    {
      "x": -78,
      "y": 64,
      "z": 17,
      "name": "Zone_Launch",
      "rotation": 3
    },
    {
      "x": -78,
      "y": 61,
      "z": 18,
      "name": "Zone_Launch",
      "rotation": 2
    },
    {
      "x": -78,
      "y": 62,
      "z": 18,
      "name": "Zone_Launch",
      "rotation": 2
    },
    {
      "x": -78,
      "y": 63,
      "z": 18,
      "name": "Zone_Launch",
      "rotation": 2
    },
    {
      "x": -78,
      "y": 64,
      "z": 18,
      "name": "Zone_Launch",
      "rotation": 3
    },
    {
      "x": -78,
      "y": 61,
      "z": 19,
      "name": "Zone_Launch",
      "rotation": 2
    },
    {
      "x": -78,
      "y": 62,
      "z": 19,
      "name": "Zone_Launch",
      "rotation": 2
    },
    {
      "x": -78,
      "y": 63,
      "z": 19,
      "name": "Zone_Launch",
      "rotation": 2
    },
    {
      "x": -78,
      "y": 64,
      "z": 19,
      "name": "Zone_Launch",
      "rotation": 3
    },
    {
      "x": -77,
      "y": 61,
      "z": -17,
      "name": "Zone_Launch",
      "rotation": 2
    },
    {
      "x": -77,
      "y": 62,
      "z": -17,
      "name": "Zone_Launch",
      "rotation": 2
    },
    {
      "x": -77,
      "y": 63,
      "z": -17,
      "name": "Zone_Launch",
      "rotation": 2
    },
    {
      "x": -77,
      "y": 64,
      "z": -17,
      "name": "Zone_Launch",
      "rotation": 3
    },
    {
      "x": -77,
      "y": 61,
      "z": -16,
      "name": "Zone_Launch",
      "rotation": 2
    },
    {
      "x": -77,
      "y": 62,
      "z": -16,
      "name": "Zone_Launch",
      "rotation": 2
    },
    {
      "x": -77,
      "y": 63,
      "z": -16,
      "name": "Zone_Launch",
      "rotation": 2
    },
    {
      "x": -77,
      "y": 64,
      "z": -16,
      "name": "Zone_Launch",
      "rotation": 3
    },
    {
      "x": -77,
      "y": 61,
      "z": -15,
      "name": "Zone_Launch",
      "rotation": 2
    },
    {
      "x": -77,
      "y": 62,
      "z": -15,
      "name": "Zone_Launch",
      "rotation": 2
    },
    {
      "x": -77,
      "y": 63,
      "z": -15,
      "name": "Zone_Launch",
      "rotation": 2
    },
    {
      "x": -77,
      "y": 64,
      "z": -15,
      "name": "Zone_Launch",
      "rotation": 3
    },
    {
      "x": -77,
      "y": 61,
      "z": -14,
      "name": "Zone_Launch",
      "rotation": 2
    },
    {
      "x": -77,
      "y": 62,
      "z": -14,
      "name": "Zone_Launch",
      "rotation": 2
    },
    {
      "x": -77,
      "y": 63,
      "z": -14,
      "name": "Zone_Launch",
      "rotation": 2
    },
    {
      "x": -77,
      "y": 64,
      "z": -14,
      "name": "Zone_Launch",
      "rotation": 3
    },
    {
      "x": -77,
      "y": 61,
      "z": -13,
      "name": "Zone_Launch",
      "rotation": 2
    },
    {
      "x": -77,
      "y": 62,
      "z": -13,
      "name": "Zone_Launch",
      "rotation": 2
    },
    {
      "x": -77,
      "y": 63,
      "z": -13,
      "name": "Zone_Launch",
      "rotation": 2
    },
    {
      "x": -77,
      "y": 64,
      "z": -13,
      "name": "Zone_Launch",
      "rotation": 3
    },
    {
      "x": -77,
      "y": 61,
      "z": -12,
      "name": "Zone_Launch",
      "rotation": 2
    },
    {
      "x": -77,
      "y": 62,
      "z": -12,
      "name": "Zone_Launch",
      "rotation": 2
    },
    {
      "x": -77,
      "y": 63,
      "z": -12,
      "name": "Zone_Launch",
      "rotation": 2
    },
    {
      "x": -77,
      "y": 64,
      "z": -12,
      "name": "Zone_Launch",
      "rotation": 1
    },
    {
      "x": -77,
      "y": 61,
      "z": -11,
      "name": "Zone_Launch",
      "rotation": 2
    },
    {
      "x": -77,
      "y": 62,
      "z": -11,
      "name": "Zone_Launch",
      "rotation": 2
    },
    {
      "x": -77,
      "y": 63,
      "z": -11,
      "name": "Zone_Launch",
      "rotation": 2
    },
    {
      "x": -77,
      "y": 64,
      "z": -11,
      "name": "Zone_Launch",
      "rotation": 1
    },
    {
      "x": -77,
      "y": 61,
      "z": -10,
      "name": "Zone_Launch",
      "rotation": 2
    },
    {
      "x": -77,
      "y": 62,
      "z": -10,
      "name": "Zone_Launch",
      "rotation": 2
    },
    {
      "x": -77,
      "y": 63,
      "z": -10,
      "name": "Zone_Launch",
      "rotation": 2
    },
    {
      "x": -77,
      "y": 64,
      "z": -10,
      "name": "Zone_Launch",
      "rotation": 1
    },
    {
      "x": -77,
      "y": 61,
      "z": -9,
      "name": "Zone_Launch",
      "rotation": 2
    },
    {
      "x": -77,
      "y": 62,
      "z": -9,
      "name": "Zone_Launch",
      "rotation": 2
    },
    {
      "x": -77,
      "y": 63,
      "z": -9,
      "name": "Zone_Launch",
      "rotation": 2
    },
    {
      "x": -77,
      "y": 64,
      "z": -9,
      "name": "Zone_Launch",
      "rotation": 1
    },
    {
      "x": -77,
      "y": 61,
      "z": -8,
      "name": "Zone_Launch",
      "rotation": 2
    },
    {
      "x": -77,
      "y": 62,
      "z": -8,
      "name": "Zone_Launch",
      "rotation": 2
    },
    {
      "x": -77,
      "y": 63,
      "z": -8,
      "name": "Zone_Launch",
      "rotation": 2
    },
    {
      "x": -77,
      "y": 64,
      "z": -8,
      "name": "Zone_Launch",
      "rotation": 1
    },
    {
      "x": -77,
      "y": 61,
      "z": -7,
      "name": "Zone_Launch",
      "rotation": 2
    },
    {
      "x": -77,
      "y": 62,
      "z": -7,
      "name": "Zone_Launch",
      "rotation": 2
    },
    {
      "x": -77,
      "y": 63,
      "z": -7,
      "name": "Zone_Launch",
      "rotation": 2
    },
    {
      "x": -77,
      "y": 64,
      "z": -7,
      "name": "Zone_Launch",
      "rotation": 1
    },
    {
      "x": -77,
      "y": 61,
      "z": -6,
      "name": "Zone_Launch",
      "rotation": 2
    },
    {
      "x": -77,
      "y": 62,
      "z": -6,
      "name": "Zone_Launch",
      "rotation": 2
    },
    {
      "x": -77,
      "y": 63,
      "z": -6,
      "name": "Zone_Launch",
      "rotation": 2
    },
    {
      "x": -77,
      "y": 64,
      "z": -6,
      "name": "Zone_Launch",
      "rotation": 1
    },
    {
      "x": -77,
      "y": 61,
      "z": -5,
      "name": "Zone_Launch",
      "rotation": 2
    },
    {
      "x": -77,
      "y": 62,
      "z": -5,
      "name": "Zone_Launch",
      "rotation": 2
    },
    {
      "x": -77,
      "y": 63,
      "z": -5,
      "name": "Zone_Launch",
      "rotation": 2
    },
    {
      "x": -77,
      "y": 64,
      "z": -5,
      "name": "Zone_Launch",
      "rotation": 1
    },
    {
      "x": -77,
      "y": 61,
      "z": -4,
      "name": "Zone_Launch",
      "rotation": 2
    },
    {
      "x": -77,
      "y": 62,
      "z": -4,
      "name": "Zone_Launch",
      "rotation": 2
    },
    {
      "x": -77,
      "y": 63,
      "z": -4,
      "name": "Zone_Launch",
      "rotation": 2
    },
    {
      "x": -77,
      "y": 64,
      "z": -4,
      "name": "Zone_Launch",
      "rotation": 1
    },
    {
      "x": -77,
      "y": 61,
      "z": -3,
      "name": "Zone_Launch",
      "rotation": 2
    },
    {
      "x": -77,
      "y": 62,
      "z": -3,
      "name": "Zone_Launch",
      "rotation": 2
    },
    {
      "x": -77,
      "y": 63,
      "z": -3,
      "name": "Zone_Launch",
      "rotation": 2
    },
    {
      "x": -77,
      "y": 64,
      "z": -3,
      "name": "Zone_Launch",
      "rotation": 1
    },
    {
      "x": -77,
      "y": 61,
      "z": -2,
      "name": "Zone_Launch",
      "rotation": 2
    },
    {
      "x": -77,
      "y": 62,
      "z": -2,
      "name": "Zone_Launch",
      "rotation": 2
    },
    {
      "x": -77,
      "y": 63,
      "z": -2,
      "name": "Zone_Launch",
      "rotation": 2
    },
    {
      "x": -77,
      "y": 64,
      "z": -2,
      "name": "Zone_Launch",
      "rotation": 1
    },
    {
      "x": -77,
      "y": 61,
      "z": -1,
      "name": "Zone_Launch",
      "rotation": 2
    },
    {
      "x": -77,
      "y": 62,
      "z": -1,
      "name": "Zone_Launch",
      "rotation": 2
    },
    {
      "x": -77,
      "y": 63,
      "z": -1,
      "name": "Zone_Launch",
      "rotation": 2
    },
    {
      "x": -77,
      "y": 64,
      "z": -1,
      "name": "Zone_Launch",
      "rotation": 1
    },
    {
      "x": -77,
      "y": 61,
      "z": 0,
      "name": "Zone_Launch",
      "rotation": 2
    },
    {
      "x": -77,
      "y": 62,
      "z": 0,
      "name": "Zone_Launch",
      "rotation": 2
    },
    {
      "x": -77,
      "y": 63,
      "z": 0,
      "name": "Zone_Launch",
      "rotation": 2
    },
    {
      "x": -77,
      "y": 64,
      "z": 0,
      "name": "Zone_Launch",
      "rotation": 1
    },
    {
      "x": -77,
      "y": 61,
      "z": 1,
      "name": "Zone_Launch",
      "rotation": 2
    },
    {
      "x": -77,
      "y": 62,
      "z": 1,
      "name": "Zone_Launch",
      "rotation": 2
    },
    {
      "x": -77,
      "y": 63,
      "z": 1,
      "name": "Zone_Launch",
      "rotation": 2
    },
    {
      "x": -77,
      "y": 64,
      "z": 1,
      "name": "Zone_Launch",
      "rotation": 1
    },
    {
      "x": -77,
      "y": 61,
      "z": 2,
      "name": "Zone_Launch",
      "rotation": 2
    },
    {
      "x": -77,
      "y": 62,
      "z": 2,
      "name": "Zone_Launch",
      "rotation": 2
    },
    {
      "x": -77,
      "y": 63,
      "z": 2,
      "name": "Zone_Launch",
      "rotation": 2
    },
    {
      "x": -77,
      "y": 64,
      "z": 2,
      "name": "Zone_Launch",
      "rotation": 1
    },
    {
      "x": -77,
      "y": 61,
      "z": 3,
      "name": "Zone_Launch",
      "rotation": 2
    },
    {
      "x": -77,
      "y": 62,
      "z": 3,
      "name": "Zone_Launch",
      "rotation": 2
    },
    {
      "x": -77,
      "y": 63,
      "z": 3,
      "name": "Zone_Launch",
      "rotation": 2
    },
    {
      "x": -77,
      "y": 64,
      "z": 3,
      "name": "Zone_Launch",
      "rotation": 1
    },
    {
      "x": -77,
      "y": 61,
      "z": 4,
      "name": "Zone_Launch",
      "rotation": 2
    },
    {
      "x": -77,
      "y": 62,
      "z": 4,
      "name": "Zone_Launch",
      "rotation": 2
    },
    {
      "x": -77,
      "y": 63,
      "z": 4,
      "name": "Zone_Launch",
      "rotation": 2
    },
    {
      "x": -77,
      "y": 64,
      "z": 4,
      "name": "Zone_Launch",
      "rotation": 1
    },
    {
      "x": -77,
      "y": 61,
      "z": 5,
      "name": "Zone_Launch",
      "rotation": 2
    },
    {
      "x": -77,
      "y": 62,
      "z": 5,
      "name": "Zone_Launch",
      "rotation": 2
    },
    {
      "x": -77,
      "y": 63,
      "z": 5,
      "name": "Zone_Launch",
      "rotation": 2
    },
    {
      "x": -77,
      "y": 64,
      "z": 5,
      "name": "Zone_Launch",
      "rotation": 1
    },
    {
      "x": -77,
      "y": 61,
      "z": 6,
      "name": "Zone_Launch",
      "rotation": 2
    },
    {
      "x": -77,
      "y": 62,
      "z": 6,
      "name": "Zone_Launch",
      "rotation": 2
    },
    {
      "x": -77,
      "y": 63,
      "z": 6,
      "name": "Zone_Launch",
      "rotation": 2
    },
    {
      "x": -77,
      "y": 64,
      "z": 6,
      "name": "Zone_Launch",
      "rotation": 1
    },
    {
      "x": -77,
      "y": 61,
      "z": 7,
      "name": "Zone_Launch",
      "rotation": 2
    },
    {
      "x": -77,
      "y": 62,
      "z": 7,
      "name": "Zone_Launch",
      "rotation": 2
    },
    {
      "x": -77,
      "y": 63,
      "z": 7,
      "name": "Zone_Launch",
      "rotation": 2
    },
    {
      "x": -77,
      "y": 64,
      "z": 7,
      "name": "Zone_Launch",
      "rotation": 1
    },
    {
      "x": -77,
      "y": 61,
      "z": 8,
      "name": "Zone_Launch",
      "rotation": 2
    },
    {
      "x": -77,
      "y": 62,
      "z": 8,
      "name": "Zone_Launch",
      "rotation": 2
    },
    {
      "x": -77,
      "y": 63,
      "z": 8,
      "name": "Zone_Launch",
      "rotation": 2
    },
    {
      "x": -77,
      "y": 64,
      "z": 8,
      "name": "Zone_Launch",
      "rotation": 1
    },
    {
      "x": -77,
      "y": 61,
      "z": 9,
      "name": "Zone_Launch",
      "rotation": 2
    },
    {
      "x": -77,
      "y": 62,
      "z": 9,
      "name": "Zone_Launch",
      "rotation": 2
    },
    {
      "x": -77,
      "y": 63,
      "z": 9,
      "name": "Zone_Launch",
      "rotation": 2
    },
    {
      "x": -77,
      "y": 64,
      "z": 9,
      "name": "Zone_Launch",
      "rotation": 1
    },
    {
      "x": -77,
      "y": 61,
      "z": 10,
      "name": "Zone_Launch",
      "rotation": 2
    },
    {
      "x": -77,
      "y": 62,
      "z": 10,
      "name": "Zone_Launch",
      "rotation": 2
    },
    {
      "x": -77,
      "y": 63,
      "z": 10,
      "name": "Zone_Launch",
      "rotation": 2
    },
    {
      "x": -77,
      "y": 64,
      "z": 10,
      "name": "Zone_Launch",
      "rotation": 1
    },
    {
      "x": -77,
      "y": 61,
      "z": 11,
      "name": "Zone_Launch",
      "rotation": 2
    },
    {
      "x": -77,
      "y": 62,
      "z": 11,
      "name": "Zone_Launch",
      "rotation": 2
    },
    {
      "x": -77,
      "y": 63,
      "z": 11,
      "name": "Zone_Launch",
      "rotation": 2
    },
    {
      "x": -77,
      "y": 64,
      "z": 11,
      "name": "Zone_Launch",
      "rotation": 1
    },
    {
      "x": -77,
      "y": 61,
      "z": 12,
      "name": "Zone_Launch",
      "rotation": 2
    },
    {
      "x": -77,
      "y": 62,
      "z": 12,
      "name": "Zone_Launch",
      "rotation": 2
    },
    {
      "x": -77,
      "y": 63,
      "z": 12,
      "name": "Zone_Launch",
      "rotation": 2
    },
    {
      "x": -77,
      "y": 64,
      "z": 12,
      "name": "Zone_Launch",
      "rotation": 1
    },
    {
      "x": -77,
      "y": 61,
      "z": 13,
      "name": "Zone_Launch",
      "rotation": 2
    },
    {
      "x": -77,
      "y": 62,
      "z": 13,
      "name": "Zone_Launch",
      "rotation": 2
    },
    {
      "x": -77,
      "y": 63,
      "z": 13,
      "name": "Zone_Launch",
      "rotation": 2
    },
    {
      "x": -77,
      "y": 64,
      "z": 13,
      "name": "Zone_Launch",
      "rotation": 1
    },
    {
      "x": -77,
      "y": 61,
      "z": 14,
      "name": "Zone_Launch",
      "rotation": 2
    },
    {
      "x": -77,
      "y": 62,
      "z": 14,
      "name": "Zone_Launch",
      "rotation": 2
    },
    {
      "x": -77,
      "y": 63,
      "z": 14,
      "name": "Zone_Launch",
      "rotation": 2
    },
    {
      "x": -77,
      "y": 64,
      "z": 14,
      "name": "Zone_Launch",
      "rotation": 1
    },
    {
      "x": -77,
      "y": 61,
      "z": 15,
      "name": "Zone_Launch",
      "rotation": 2
    },
    {
      "x": -77,
      "y": 62,
      "z": 15,
      "name": "Zone_Launch",
      "rotation": 2
    },
    {
      "x": -77,
      "y": 63,
      "z": 15,
      "name": "Zone_Launch",
      "rotation": 2
    },
    {
      "x": -77,
      "y": 64,
      "z": 15,
      "name": "Zone_Launch",
      "rotation": 1
    },
    {
      "x": -77,
      "y": 61,
      "z": 16,
      "name": "Zone_Launch",
      "rotation": 2
    },
    {
      "x": -77,
      "y": 62,
      "z": 16,
      "name": "Zone_Launch",
      "rotation": 2
    },
    {
      "x": -77,
      "y": 63,
      "z": 16,
      "name": "Zone_Launch",
      "rotation": 2
    },
    {
      "x": -77,
      "y": 64,
      "z": 16,
      "name": "Zone_Launch",
      "rotation": 1
    },
    {
      "x": -77,
      "y": 61,
      "z": 17,
      "name": "Zone_Launch",
      "rotation": 2
    },
    {
      "x": -77,
      "y": 62,
      "z": 17,
      "name": "Zone_Launch",
      "rotation": 2
    },
    {
      "x": -77,
      "y": 63,
      "z": 17,
      "name": "Zone_Launch",
      "rotation": 2
    },
    {
      "x": -77,
      "y": 64,
      "z": 17,
      "name": "Zone_Launch",
      "rotation": 1
    },
    {
      "x": -77,
      "y": 61,
      "z": 18,
      "name": "Zone_Launch",
      "rotation": 2
    },
    {
      "x": -77,
      "y": 62,
      "z": 18,
      "name": "Zone_Launch",
      "rotation": 2
    },
    {
      "x": -77,
      "y": 63,
      "z": 18,
      "name": "Zone_Launch",
      "rotation": 2
    },
    {
      "x": -77,
      "y": 64,
      "z": 18,
      "name": "Zone_Launch",
      "rotation": 1
    },
    {
      "x": -77,
      "y": 61,
      "z": 19,
      "name": "Zone_Launch",
      "rotation": 2
    },
    {
      "x": -77,
      "y": 62,
      "z": 19,
      "name": "Zone_Launch",
      "rotation": 2
    },
    {
      "x": -77,
      "y": 63,
      "z": 19,
      "name": "Zone_Launch",
      "rotation": 2
    },
    {
      "x": -77,
      "y": 64,
      "z": 19,
      "name": "Zone_Launch",
      "rotation": 3
    },
    {
      "x": -77,
      "y": 61,
      "z": 20,
      "name": "Zone_Launch",
      "rotation": 2
    },
    {
      "x": -77,
      "y": 62,
      "z": 20,
      "name": "Zone_Launch",
      "rotation": 2
    },
    {
      "x": -77,
      "y": 63,
      "z": 20,
      "name": "Zone_Launch",
      "rotation": 2
    },
    {
      "x": -77,
      "y": 64,
      "z": 20,
      "name": "Zone_Launch",
      "rotation": 3
    },
    {
      "x": -77,
      "y": 61,
      "z": 21,
      "name": "Zone_Launch",
      "rotation": 2
    },
    {
      "x": -77,
      "y": 62,
      "z": 21,
      "name": "Zone_Launch",
      "rotation": 2
    },
    {
      "x": -77,
      "y": 63,
      "z": 21,
      "name": "Zone_Launch",
      "rotation": 2
    },
    {
      "x": -77,
      "y": 64,
      "z": 21,
      "name": "Zone_Launch",
      "rotation": 3
    },
    {
      "x": -77,
      "y": 61,
      "z": 22,
      "name": "Zone_Launch",
      "rotation": 2
    },
    {
      "x": -77,
      "y": 62,
      "z": 22,
      "name": "Zone_Launch",
      "rotation": 2
    },
    {
      "x": -77,
      "y": 63,
      "z": 22,
      "name": "Zone_Launch",
      "rotation": 2
    },
    {
      "x": -77,
      "y": 64,
      "z": 22,
      "name": "Zone_Launch",
      "rotation": 3
    },
    {
      "x": -77,
      "y": 61,
      "z": 23,
      "name": "Zone_Launch",
      "rotation": 2
    },
    {
      "x": -77,
      "y": 62,
      "z": 23,
      "name": "Zone_Launch",
      "rotation": 2
    },
    {
      "x": -77,
      "y": 63,
      "z": 23,
      "name": "Zone_Launch",
      "rotation": 2
    },
    {
      "x": -77,
      "y": 64,
      "z": 23,
      "name": "Zone_Launch",
      "rotation": 3
    },
    {
      "x": -76,
      "y": 61,
      "z": -20,
      "name": "Zone_Launch",
      "rotation": 2
    },
    {
      "x": -76,
      "y": 62,
      "z": -20,
      "name": "Zone_Launch",
      "rotation": 2
    },
    {
      "x": -76,
      "y": 63,
      "z": -20,
      "name": "Zone_Launch",
      "rotation": 2
    },
    {
      "x": -76,
      "y": 64,
      "z": -20,
      "name": "Zone_Launch",
      "rotation": 3
    },
    {
      "x": -76,
      "y": 61,
      "z": -19,
      "name": "Zone_Launch",
      "rotation": 2
    },
    {
      "x": -76,
      "y": 62,
      "z": -19,
      "name": "Zone_Launch",
      "rotation": 2
    },
    {
      "x": -76,
      "y": 63,
      "z": -19,
      "name": "Zone_Launch",
      "rotation": 2
    },
    {
      "x": -76,
      "y": 64,
      "z": -19,
      "name": "Zone_Launch",
      "rotation": 3
    },
    {
      "x": -76,
      "y": 61,
      "z": -18,
      "name": "Zone_Launch",
      "rotation": 2
    },
    {
      "x": -76,
      "y": 62,
      "z": -18,
      "name": "Zone_Launch",
      "rotation": 2
    },
    {
      "x": -76,
      "y": 63,
      "z": -18,
      "name": "Zone_Launch",
      "rotation": 2
    },
    {
      "x": -76,
      "y": 64,
      "z": -18,
      "name": "Zone_Launch",
      "rotation": 3
    },
    {
      "x": -76,
      "y": 61,
      "z": -17,
      "name": "Zone_Launch",
      "rotation": 2
    },
    {
      "x": -76,
      "y": 62,
      "z": -17,
      "name": "Zone_Launch",
      "rotation": 2
    },
    {
      "x": -76,
      "y": 63,
      "z": -17,
      "name": "Zone_Launch",
      "rotation": 2
    },
    {
      "x": -76,
      "y": 64,
      "z": -17,
      "name": "Zone_Launch",
      "rotation": 3
    },
    {
      "x": -76,
      "y": 61,
      "z": -16,
      "name": "Zone_Launch",
      "rotation": 2
    },
    {
      "x": -76,
      "y": 62,
      "z": -16,
      "name": "Zone_Launch",
      "rotation": 2
    },
    {
      "x": -76,
      "y": 63,
      "z": -16,
      "name": "Zone_Launch",
      "rotation": 2
    },
    {
      "x": -76,
      "y": 64,
      "z": -16,
      "name": "Zone_Launch",
      "rotation": 1
    },
    {
      "x": -76,
      "y": 61,
      "z": -15,
      "name": "Zone_Launch",
      "rotation": 2
    },
    {
      "x": -76,
      "y": 62,
      "z": -15,
      "name": "Zone_Launch",
      "rotation": 2
    },
    {
      "x": -76,
      "y": 63,
      "z": -15,
      "name": "Zone_Launch",
      "rotation": 2
    },
    {
      "x": -76,
      "y": 64,
      "z": -15,
      "name": "Zone_Launch",
      "rotation": 1
    },
    {
      "x": -76,
      "y": 61,
      "z": -14,
      "name": "Zone_Launch",
      "rotation": 2
    },
    {
      "x": -76,
      "y": 62,
      "z": -14,
      "name": "Zone_Launch",
      "rotation": 2
    },
    {
      "x": -76,
      "y": 63,
      "z": -14,
      "name": "Zone_Launch",
      "rotation": 2
    },
    {
      "x": -76,
      "y": 64,
      "z": -14,
      "name": "Zone_Launch",
      "rotation": 1
    },
    {
      "x": -76,
      "y": 61,
      "z": -13,
      "name": "Zone_Launch",
      "rotation": 2
    },
    {
      "x": -76,
      "y": 62,
      "z": -13,
      "name": "Zone_Launch",
      "rotation": 2
    },
    {
      "x": -76,
      "y": 63,
      "z": -13,
      "name": "Zone_Launch",
      "rotation": 2
    },
    {
      "x": -76,
      "y": 64,
      "z": -13,
      "name": "Zone_Launch",
      "rotation": 1
    },
    {
      "x": -76,
      "y": 61,
      "z": -12,
      "name": "Zone_Launch",
      "rotation": 2
    },
    {
      "x": -76,
      "y": 62,
      "z": -12,
      "name": "Zone_Launch",
      "rotation": 2
    },
    {
      "x": -76,
      "y": 63,
      "z": -12,
      "name": "Zone_Launch",
      "rotation": 2
    },
    {
      "x": -76,
      "y": 64,
      "z": -12,
      "name": "Zone_Launch",
      "rotation": 1
    },
    {
      "x": -76,
      "y": 61,
      "z": -11,
      "name": "Zone_Launch",
      "rotation": 2
    },
    {
      "x": -76,
      "y": 62,
      "z": -11,
      "name": "Zone_Launch",
      "rotation": 2
    },
    {
      "x": -76,
      "y": 63,
      "z": -11,
      "name": "Zone_Launch",
      "rotation": 2
    },
    {
      "x": -76,
      "y": 64,
      "z": -11,
      "name": "Zone_Launch",
      "rotation": 1
    },
    {
      "x": -76,
      "y": 61,
      "z": -10,
      "name": "Zone_Launch",
      "rotation": 2
    },
    {
      "x": -76,
      "y": 62,
      "z": -10,
      "name": "Zone_Launch",
      "rotation": 2
    },
    {
      "x": -76,
      "y": 63,
      "z": -10,
      "name": "Zone_Launch",
      "rotation": 2
    },
    {
      "x": -76,
      "y": 64,
      "z": -10,
      "name": "Zone_Launch",
      "rotation": 1
    },
    {
      "x": -76,
      "y": 61,
      "z": -9,
      "name": "Zone_Launch",
      "rotation": 2
    },
    {
      "x": -76,
      "y": 62,
      "z": -9,
      "name": "Zone_Launch",
      "rotation": 2
    },
    {
      "x": -76,
      "y": 63,
      "z": -9,
      "name": "Zone_Launch",
      "rotation": 2
    },
    {
      "x": -76,
      "y": 64,
      "z": -9,
      "name": "Zone_Launch",
      "rotation": 1
    },
    {
      "x": -76,
      "y": 61,
      "z": -8,
      "name": "Zone_Launch",
      "rotation": 2
    },
    {
      "x": -76,
      "y": 62,
      "z": -8,
      "name": "Zone_Launch",
      "rotation": 2
    },
    {
      "x": -76,
      "y": 63,
      "z": -8,
      "name": "Zone_Launch",
      "rotation": 2
    },
    {
      "x": -76,
      "y": 64,
      "z": -8,
      "name": "Zone_Launch",
      "rotation": 1
    },
    {
      "x": -76,
      "y": 61,
      "z": -7,
      "name": "Zone_Launch",
      "rotation": 2
    },
    {
      "x": -76,
      "y": 62,
      "z": -7,
      "name": "Zone_Launch",
      "rotation": 2
    },
    {
      "x": -76,
      "y": 63,
      "z": -7,
      "name": "Zone_Launch",
      "rotation": 2
    },
    {
      "x": -76,
      "y": 64,
      "z": -7,
      "name": "Zone_Launch",
      "rotation": 1
    },
    {
      "x": -76,
      "y": 61,
      "z": -6,
      "name": "Zone_Launch",
      "rotation": 2
    },
    {
      "x": -76,
      "y": 62,
      "z": -6,
      "name": "Zone_Launch",
      "rotation": 2
    },
    {
      "x": -76,
      "y": 63,
      "z": -6,
      "name": "Zone_Launch",
      "rotation": 2
    },
    {
      "x": -76,
      "y": 64,
      "z": -6,
      "name": "Zone_Launch",
      "rotation": 1
    },
    {
      "x": -76,
      "y": 61,
      "z": -5,
      "name": "Zone_Launch",
      "rotation": 2
    },
    {
      "x": -76,
      "y": 62,
      "z": -5,
      "name": "Zone_Launch",
      "rotation": 2
    },
    {
      "x": -76,
      "y": 63,
      "z": -5,
      "name": "Zone_Launch",
      "rotation": 2
    },
    {
      "x": -76,
      "y": 61,
      "z": -4,
      "name": "Zone_Launch",
      "rotation": 2
    },
    {
      "x": -76,
      "y": 62,
      "z": -4,
      "name": "Zone_Launch",
      "rotation": 2
    },
    {
      "x": -76,
      "y": 63,
      "z": -4,
      "name": "Zone_Launch",
      "rotation": 2
    },
    {
      "x": -76,
      "y": 61,
      "z": -3,
      "name": "Zone_Launch",
      "rotation": 2
    },
    {
      "x": -76,
      "y": 62,
      "z": -3,
      "name": "Zone_Launch",
      "rotation": 2
    },
    {
      "x": -76,
      "y": 63,
      "z": -3,
      "name": "Zone_Launch",
      "rotation": 2
    },
    {
      "x": -76,
      "y": 61,
      "z": -2,
      "name": "Zone_Launch",
      "rotation": 2
    },
    {
      "x": -76,
      "y": 62,
      "z": -2,
      "name": "Zone_Launch",
      "rotation": 2
    },
    {
      "x": -76,
      "y": 63,
      "z": -2,
      "name": "Zone_Launch",
      "rotation": 2
    },
    {
      "x": -76,
      "y": 61,
      "z": -1,
      "name": "Zone_Launch",
      "rotation": 2
    },
    {
      "x": -76,
      "y": 62,
      "z": -1,
      "name": "Zone_Launch",
      "rotation": 2
    },
    {
      "x": -76,
      "y": 63,
      "z": -1,
      "name": "Zone_Launch",
      "rotation": 2
    },
    {
      "x": -76,
      "y": 61,
      "z": 0,
      "name": "Zone_Launch",
      "rotation": 2
    },
    {
      "x": -76,
      "y": 62,
      "z": 0,
      "name": "Zone_Launch",
      "rotation": 2
    },
    {
      "x": -76,
      "y": 63,
      "z": 0,
      "name": "Zone_Launch",
      "rotation": 2
    },
    {
      "x": -76,
      "y": 61,
      "z": 1,
      "name": "Zone_Launch",
      "rotation": 2
    },
    {
      "x": -76,
      "y": 62,
      "z": 1,
      "name": "Zone_Launch",
      "rotation": 2
    },
    {
      "x": -76,
      "y": 63,
      "z": 1,
      "name": "Zone_Launch",
      "rotation": 2
    },
    {
      "x": -76,
      "y": 61,
      "z": 2,
      "name": "Zone_Launch",
      "rotation": 2
    },
    {
      "x": -76,
      "y": 62,
      "z": 2,
      "name": "Zone_Launch",
      "rotation": 2
    },
    {
      "x": -76,
      "y": 63,
      "z": 2,
      "name": "Zone_Launch",
      "rotation": 2
    },
    {
      "x": -76,
      "y": 61,
      "z": 3,
      "name": "Zone_Launch",
      "rotation": 2
    },
    {
      "x": -76,
      "y": 62,
      "z": 3,
      "name": "Zone_Launch",
      "rotation": 2
    },
    {
      "x": -76,
      "y": 63,
      "z": 3,
      "name": "Zone_Launch",
      "rotation": 2
    },
    {
      "x": -76,
      "y": 61,
      "z": 4,
      "name": "Zone_Launch",
      "rotation": 2
    },
    {
      "x": -76,
      "y": 62,
      "z": 4,
      "name": "Zone_Launch",
      "rotation": 2
    },
    {
      "x": -76,
      "y": 63,
      "z": 4,
      "name": "Zone_Launch",
      "rotation": 2
    },
    {
      "x": -76,
      "y": 61,
      "z": 5,
      "name": "Zone_Launch",
      "rotation": 2
    },
    {
      "x": -76,
      "y": 62,
      "z": 5,
      "name": "Zone_Launch",
      "rotation": 2
    },
    {
      "x": -76,
      "y": 63,
      "z": 5,
      "name": "Zone_Launch",
      "rotation": 2
    },
    {
      "x": -76,
      "y": 61,
      "z": 6,
      "name": "Zone_Launch",
      "rotation": 2
    },
    {
      "x": -76,
      "y": 62,
      "z": 6,
      "name": "Zone_Launch",
      "rotation": 2
    },
    {
      "x": -76,
      "y": 63,
      "z": 6,
      "name": "Zone_Launch",
      "rotation": 2
    },
    {
      "x": -76,
      "y": 61,
      "z": 7,
      "name": "Zone_Launch",
      "rotation": 2
    },
    {
      "x": -76,
      "y": 62,
      "z": 7,
      "name": "Zone_Launch",
      "rotation": 2
    },
    {
      "x": -76,
      "y": 63,
      "z": 7,
      "name": "Zone_Launch",
      "rotation": 2
    },
    {
      "x": -76,
      "y": 61,
      "z": 8,
      "name": "Zone_Launch",
      "rotation": 2
    },
    {
      "x": -76,
      "y": 62,
      "z": 8,
      "name": "Zone_Launch",
      "rotation": 2
    },
    {
      "x": -76,
      "y": 63,
      "z": 8,
      "name": "Zone_Launch",
      "rotation": 2
    },
    {
      "x": -76,
      "y": 61,
      "z": 9,
      "name": "Zone_Launch",
      "rotation": 2
    },
    {
      "x": -76,
      "y": 62,
      "z": 9,
      "name": "Zone_Launch",
      "rotation": 2
    },
    {
      "x": -76,
      "y": 63,
      "z": 9,
      "name": "Zone_Launch",
      "rotation": 2
    },
    {
      "x": -76,
      "y": 61,
      "z": 10,
      "name": "Zone_Launch",
      "rotation": 2
    },
    {
      "x": -76,
      "y": 62,
      "z": 10,
      "name": "Zone_Launch",
      "rotation": 2
    },
    {
      "x": -76,
      "y": 63,
      "z": 10,
      "name": "Zone_Launch",
      "rotation": 2
    },
    {
      "x": -76,
      "y": 61,
      "z": 11,
      "name": "Zone_Launch",
      "rotation": 2
    },
    {
      "x": -76,
      "y": 62,
      "z": 11,
      "name": "Zone_Launch",
      "rotation": 2
    },
    {
      "x": -76,
      "y": 63,
      "z": 11,
      "name": "Zone_Launch",
      "rotation": 2
    },
    {
      "x": -76,
      "y": 61,
      "z": 12,
      "name": "Zone_Launch",
      "rotation": 2
    },
    {
      "x": -76,
      "y": 62,
      "z": 12,
      "name": "Zone_Launch",
      "rotation": 2
    },
    {
      "x": -76,
      "y": 63,
      "z": 12,
      "name": "Zone_Launch",
      "rotation": 2
    },
    {
      "x": -76,
      "y": 64,
      "z": 12,
      "name": "Zone_Launch",
      "rotation": 1
    },
    {
      "x": -76,
      "y": 61,
      "z": 13,
      "name": "Zone_Launch",
      "rotation": 2
    },
    {
      "x": -76,
      "y": 62,
      "z": 13,
      "name": "Zone_Launch",
      "rotation": 2
    },
    {
      "x": -76,
      "y": 63,
      "z": 13,
      "name": "Zone_Launch",
      "rotation": 2
    },
    {
      "x": -76,
      "y": 64,
      "z": 13,
      "name": "Zone_Launch",
      "rotation": 1
    },
    {
      "x": -76,
      "y": 61,
      "z": 14,
      "name": "Zone_Launch",
      "rotation": 2
    },
    {
      "x": -76,
      "y": 62,
      "z": 14,
      "name": "Zone_Launch",
      "rotation": 2
    },
    {
      "x": -76,
      "y": 63,
      "z": 14,
      "name": "Zone_Launch",
      "rotation": 2
    },
    {
      "x": -76,
      "y": 64,
      "z": 14,
      "name": "Zone_Launch",
      "rotation": 1
    },
    {
      "x": -76,
      "y": 61,
      "z": 15,
      "name": "Zone_Launch",
      "rotation": 2
    },
    {
      "x": -76,
      "y": 62,
      "z": 15,
      "name": "Zone_Launch",
      "rotation": 2
    },
    {
      "x": -76,
      "y": 63,
      "z": 15,
      "name": "Zone_Launch",
      "rotation": 2
    },
    {
      "x": -76,
      "y": 64,
      "z": 15,
      "name": "Zone_Launch",
      "rotation": 1
    },
    {
      "x": -76,
      "y": 61,
      "z": 16,
      "name": "Zone_Launch",
      "rotation": 2
    },
    {
      "x": -76,
      "y": 62,
      "z": 16,
      "name": "Zone_Launch",
      "rotation": 2
    },
    {
      "x": -76,
      "y": 63,
      "z": 16,
      "name": "Zone_Launch",
      "rotation": 2
    },
    {
      "x": -76,
      "y": 64,
      "z": 16,
      "name": "Zone_Launch",
      "rotation": 1
    },
    {
      "x": -76,
      "y": 61,
      "z": 17,
      "name": "Zone_Launch",
      "rotation": 2
    },
    {
      "x": -76,
      "y": 62,
      "z": 17,
      "name": "Zone_Launch",
      "rotation": 2
    },
    {
      "x": -76,
      "y": 63,
      "z": 17,
      "name": "Zone_Launch",
      "rotation": 2
    },
    {
      "x": -76,
      "y": 64,
      "z": 17,
      "name": "Zone_Launch",
      "rotation": 1
    },
    {
      "x": -76,
      "y": 61,
      "z": 18,
      "name": "Zone_Launch",
      "rotation": 2
    },
    {
      "x": -76,
      "y": 62,
      "z": 18,
      "name": "Zone_Launch",
      "rotation": 2
    },
    {
      "x": -76,
      "y": 63,
      "z": 18,
      "name": "Zone_Launch",
      "rotation": 2
    },
    {
      "x": -76,
      "y": 64,
      "z": 18,
      "name": "Zone_Launch",
      "rotation": 1
    },
    {
      "x": -76,
      "y": 61,
      "z": 19,
      "name": "Zone_Launch",
      "rotation": 2
    },
    {
      "x": -76,
      "y": 62,
      "z": 19,
      "name": "Zone_Launch",
      "rotation": 2
    },
    {
      "x": -76,
      "y": 63,
      "z": 19,
      "name": "Zone_Launch",
      "rotation": 2
    },
    {
      "x": -76,
      "y": 64,
      "z": 19,
      "name": "Zone_Launch",
      "rotation": 1
    },
    {
      "x": -76,
      "y": 61,
      "z": 20,
      "name": "Zone_Launch",
      "rotation": 2
    },
    {
      "x": -76,
      "y": 62,
      "z": 20,
      "name": "Zone_Launch",
      "rotation": 2
    },
    {
      "x": -76,
      "y": 63,
      "z": 20,
      "name": "Zone_Launch",
      "rotation": 2
    },
    {
      "x": -76,
      "y": 64,
      "z": 20,
      "name": "Zone_Launch",
      "rotation": 1
    },
    {
      "x": -76,
      "y": 61,
      "z": 21,
      "name": "Zone_Launch",
      "rotation": 2
    },
    {
      "x": -76,
      "y": 62,
      "z": 21,
      "name": "Zone_Launch",
      "rotation": 2
    },
    {
      "x": -76,
      "y": 63,
      "z": 21,
      "name": "Zone_Launch",
      "rotation": 2
    },
    {
      "x": -76,
      "y": 64,
      "z": 21,
      "name": "Zone_Launch",
      "rotation": 1
    },
    {
      "x": -76,
      "y": 61,
      "z": 22,
      "name": "Zone_Launch",
      "rotation": 2
    },
    {
      "x": -76,
      "y": 62,
      "z": 22,
      "name": "Zone_Launch",
      "rotation": 2
    },
    {
      "x": -76,
      "y": 63,
      "z": 22,
      "name": "Zone_Launch",
      "rotation": 2
    },
    {
      "x": -76,
      "y": 64,
      "z": 22,
      "name": "Zone_Launch",
      "rotation": 1
    },
    {
      "x": -76,
      "y": 61,
      "z": 23,
      "name": "Zone_Launch",
      "rotation": 2
    },
    {
      "x": -76,
      "y": 62,
      "z": 23,
      "name": "Zone_Launch",
      "rotation": 2
    },
    {
      "x": -76,
      "y": 63,
      "z": 23,
      "name": "Zone_Launch",
      "rotation": 2
    },
    {
      "x": -76,
      "y": 64,
      "z": 23,
      "name": "Zone_Launch",
      "rotation": 3
    },
    {
      "x": -76,
      "y": 61,
      "z": 24,
      "name": "Zone_Launch",
      "rotation": 2
    },
    {
      "x": -76,
      "y": 62,
      "z": 24,
      "name": "Zone_Launch",
      "rotation": 2
    },
    {
      "x": -76,
      "y": 63,
      "z": 24,
      "name": "Zone_Launch",
      "rotation": 2
    },
    {
      "x": -76,
      "y": 64,
      "z": 24,
      "name": "Zone_Launch",
      "rotation": 3
    },
    {
      "x": -76,
      "y": 61,
      "z": 25,
      "name": "Zone_Launch",
      "rotation": 2
    },
    {
      "x": -76,
      "y": 62,
      "z": 25,
      "name": "Zone_Launch",
      "rotation": 2
    },
    {
      "x": -76,
      "y": 63,
      "z": 25,
      "name": "Zone_Launch",
      "rotation": 2
    },
    {
      "x": -76,
      "y": 64,
      "z": 25,
      "name": "Zone_Launch",
      "rotation": 3
    },
    {
      "x": -76,
      "y": 61,
      "z": 26,
      "name": "Zone_Launch",
      "rotation": 2
    },
    {
      "x": -76,
      "y": 62,
      "z": 26,
      "name": "Zone_Launch",
      "rotation": 2
    },
    {
      "x": -76,
      "y": 63,
      "z": 26,
      "name": "Zone_Launch",
      "rotation": 2
    },
    {
      "x": -76,
      "y": 64,
      "z": 26,
      "name": "Zone_Launch",
      "rotation": 3
    },
    {
      "x": -75,
      "y": 61,
      "z": -24,
      "name": "Zone_Launch",
      "rotation": 2
    },
    {
      "x": -75,
      "y": 62,
      "z": -24,
      "name": "Zone_Launch",
      "rotation": 2
    },
    {
      "x": -75,
      "y": 63,
      "z": -24,
      "name": "Zone_Launch",
      "rotation": 2
    },
    {
      "x": -75,
      "y": 64,
      "z": -24,
      "name": "Zone_Launch",
      "rotation": 3
    },
    {
      "x": -75,
      "y": 61,
      "z": -23,
      "name": "Zone_Launch",
      "rotation": 2
    },
    {
      "x": -75,
      "y": 62,
      "z": -23,
      "name": "Zone_Launch",
      "rotation": 2
    },
    {
      "x": -75,
      "y": 63,
      "z": -23,
      "name": "Zone_Launch",
      "rotation": 2
    },
    {
      "x": -75,
      "y": 64,
      "z": -23,
      "name": "Zone_Launch",
      "rotation": 3
    },
    {
      "x": -75,
      "y": 61,
      "z": -22,
      "name": "Zone_Launch",
      "rotation": 2
    },
    {
      "x": -75,
      "y": 62,
      "z": -22,
      "name": "Zone_Launch",
      "rotation": 2
    },
    {
      "x": -75,
      "y": 63,
      "z": -22,
      "name": "Zone_Launch",
      "rotation": 2
    },
    {
      "x": -75,
      "y": 64,
      "z": -22,
      "name": "Zone_Launch",
      "rotation": 3
    },
    {
      "x": -75,
      "y": 61,
      "z": -21,
      "name": "Zone_Launch",
      "rotation": 2
    },
    {
      "x": -75,
      "y": 62,
      "z": -21,
      "name": "Zone_Launch",
      "rotation": 2
    },
    {
      "x": -75,
      "y": 63,
      "z": -21,
      "name": "Zone_Launch",
      "rotation": 2
    },
    {
      "x": -75,
      "y": 64,
      "z": -21,
      "name": "Zone_Launch",
      "rotation": 3
    },
    {
      "x": -75,
      "y": 61,
      "z": -20,
      "name": "Zone_Launch",
      "rotation": 2
    },
    {
      "x": -75,
      "y": 62,
      "z": -20,
      "name": "Zone_Launch",
      "rotation": 2
    },
    {
      "x": -75,
      "y": 63,
      "z": -20,
      "name": "Zone_Launch",
      "rotation": 2
    },
    {
      "x": -75,
      "y": 64,
      "z": -20,
      "name": "Zone_Launch",
      "rotation": 1
    },
    {
      "x": -75,
      "y": 61,
      "z": -19,
      "name": "Zone_Launch",
      "rotation": 2
    },
    {
      "x": -75,
      "y": 62,
      "z": -19,
      "name": "Zone_Launch",
      "rotation": 2
    },
    {
      "x": -75,
      "y": 63,
      "z": -19,
      "name": "Zone_Launch",
      "rotation": 2
    },
    {
      "x": -75,
      "y": 64,
      "z": -19,
      "name": "Zone_Launch",
      "rotation": 1
    },
    {
      "x": -75,
      "y": 61,
      "z": -18,
      "name": "Zone_Launch",
      "rotation": 2
    },
    {
      "x": -75,
      "y": 62,
      "z": -18,
      "name": "Zone_Launch",
      "rotation": 2
    },
    {
      "x": -75,
      "y": 63,
      "z": -18,
      "name": "Zone_Launch",
      "rotation": 2
    },
    {
      "x": -75,
      "y": 64,
      "z": -18,
      "name": "Zone_Launch",
      "rotation": 1
    },
    {
      "x": -75,
      "y": 61,
      "z": -17,
      "name": "Zone_Launch",
      "rotation": 2
    },
    {
      "x": -75,
      "y": 62,
      "z": -17,
      "name": "Zone_Launch",
      "rotation": 2
    },
    {
      "x": -75,
      "y": 63,
      "z": -17,
      "name": "Zone_Launch",
      "rotation": 2
    },
    {
      "x": -75,
      "y": 64,
      "z": -17,
      "name": "Zone_Launch",
      "rotation": 1
    },
    {
      "x": -75,
      "y": 61,
      "z": -16,
      "name": "Zone_Launch",
      "rotation": 2
    },
    {
      "x": -75,
      "y": 62,
      "z": -16,
      "name": "Zone_Launch",
      "rotation": 2
    },
    {
      "x": -75,
      "y": 63,
      "z": -16,
      "name": "Zone_Launch",
      "rotation": 2
    },
    {
      "x": -75,
      "y": 64,
      "z": -16,
      "name": "Zone_Launch",
      "rotation": 1
    },
    {
      "x": -75,
      "y": 61,
      "z": -15,
      "name": "Zone_Launch",
      "rotation": 2
    },
    {
      "x": -75,
      "y": 62,
      "z": -15,
      "name": "Zone_Launch",
      "rotation": 2
    },
    {
      "x": -75,
      "y": 63,
      "z": -15,
      "name": "Zone_Launch",
      "rotation": 2
    },
    {
      "x": -75,
      "y": 64,
      "z": -15,
      "name": "Zone_Launch",
      "rotation": 1
    },
    {
      "x": -75,
      "y": 61,
      "z": -14,
      "name": "Zone_Launch",
      "rotation": 2
    },
    {
      "x": -75,
      "y": 62,
      "z": -14,
      "name": "Zone_Launch",
      "rotation": 2
    },
    {
      "x": -75,
      "y": 63,
      "z": -14,
      "name": "Zone_Launch",
      "rotation": 2
    },
    {
      "x": -75,
      "y": 64,
      "z": -14,
      "name": "Zone_Launch",
      "rotation": 1
    },
    {
      "x": -75,
      "y": 61,
      "z": -13,
      "name": "Zone_Launch",
      "rotation": 2
    },
    {
      "x": -75,
      "y": 62,
      "z": -13,
      "name": "Zone_Launch",
      "rotation": 2
    },
    {
      "x": -75,
      "y": 63,
      "z": -13,
      "name": "Zone_Launch",
      "rotation": 2
    },
    {
      "x": -75,
      "y": 64,
      "z": -13,
      "name": "Zone_Launch",
      "rotation": 1
    },
    {
      "x": -75,
      "y": 61,
      "z": -12,
      "name": "Zone_Launch",
      "rotation": 2
    },
    {
      "x": -75,
      "y": 62,
      "z": -12,
      "name": "Zone_Launch",
      "rotation": 2
    },
    {
      "x": -75,
      "y": 63,
      "z": -12,
      "name": "Zone_Launch",
      "rotation": 2
    },
    {
      "x": -75,
      "y": 61,
      "z": -11,
      "name": "Zone_Launch",
      "rotation": 2
    },
    {
      "x": -75,
      "y": 62,
      "z": -11,
      "name": "Zone_Launch",
      "rotation": 2
    },
    {
      "x": -75,
      "y": 63,
      "z": -11,
      "name": "Zone_Launch",
      "rotation": 2
    },
    {
      "x": -75,
      "y": 61,
      "z": -10,
      "name": "Zone_Launch",
      "rotation": 2
    },
    {
      "x": -75,
      "y": 62,
      "z": -10,
      "name": "Zone_Launch",
      "rotation": 2
    },
    {
      "x": -75,
      "y": 63,
      "z": -10,
      "name": "Zone_Launch",
      "rotation": 2
    },
    {
      "x": -75,
      "y": 61,
      "z": -9,
      "name": "Zone_Launch",
      "rotation": 2
    },
    {
      "x": -75,
      "y": 62,
      "z": -9,
      "name": "Zone_Launch",
      "rotation": 2
    },
    {
      "x": -75,
      "y": 63,
      "z": -9,
      "name": "Zone_Launch",
      "rotation": 2
    },
    {
      "x": -75,
      "y": 61,
      "z": -8,
      "name": "Zone_Launch",
      "rotation": 2
    },
    {
      "x": -75,
      "y": 62,
      "z": -8,
      "name": "Zone_Launch",
      "rotation": 2
    },
    {
      "x": -75,
      "y": 63,
      "z": -8,
      "name": "Zone_Launch",
      "rotation": 2
    },
    {
      "x": -75,
      "y": 61,
      "z": -7,
      "name": "Zone_Launch",
      "rotation": 2
    },
    {
      "x": -75,
      "y": 62,
      "z": -7,
      "name": "Zone_Launch",
      "rotation": 2
    },
    {
      "x": -75,
      "y": 63,
      "z": -7,
      "name": "Zone_Launch",
      "rotation": 2
    },
    {
      "x": -75,
      "y": 61,
      "z": -6,
      "name": "Zone_Launch",
      "rotation": 2
    },
    {
      "x": -75,
      "y": 62,
      "z": -6,
      "name": "Zone_Launch",
      "rotation": 2
    },
    {
      "x": -75,
      "y": 63,
      "z": -6,
      "name": "Zone_Launch",
      "rotation": 2
    },
    {
      "x": -75,
      "y": 61,
      "z": -5,
      "name": "Zone_Launch",
      "rotation": 2
    },
    {
      "x": -75,
      "y": 62,
      "z": -5,
      "name": "Zone_Launch",
      "rotation": 2
    },
    {
      "x": -75,
      "y": 63,
      "z": -5,
      "name": "Zone_Launch",
      "rotation": 2
    },
    {
      "x": -75,
      "y": 61,
      "z": -4,
      "name": "Zone_Launch",
      "rotation": 2
    },
    {
      "x": -75,
      "y": 62,
      "z": -4,
      "name": "Zone_Launch",
      "rotation": 2
    },
    {
      "x": -75,
      "y": 63,
      "z": -4,
      "name": "Zone_Launch",
      "rotation": 2
    },
    {
      "x": -75,
      "y": 61,
      "z": -3,
      "name": "Zone_Launch",
      "rotation": 2
    },
    {
      "x": -75,
      "y": 62,
      "z": -3,
      "name": "Zone_Launch",
      "rotation": 2
    },
    {
      "x": -75,
      "y": 63,
      "z": -3,
      "name": "Zone_Launch",
      "rotation": 2
    },
    {
      "x": -75,
      "y": 61,
      "z": -2,
      "name": "Zone_Launch",
      "rotation": 2
    },
    {
      "x": -75,
      "y": 62,
      "z": -2,
      "name": "Zone_Launch",
      "rotation": 2
    },
    {
      "x": -75,
      "y": 63,
      "z": -2,
      "name": "Zone_Launch",
      "rotation": 2
    },
    {
      "x": -75,
      "y": 61,
      "z": -1,
      "name": "Zone_Launch",
      "rotation": 2
    },
    {
      "x": -75,
      "y": 62,
      "z": -1,
      "name": "Zone_Launch",
      "rotation": 2
    },
    {
      "x": -75,
      "y": 63,
      "z": -1,
      "name": "Zone_Launch",
      "rotation": 2
    },
    {
      "x": -75,
      "y": 61,
      "z": 0,
      "name": "Zone_Launch",
      "rotation": 2
    },
    {
      "x": -75,
      "y": 62,
      "z": 0,
      "name": "Zone_Launch",
      "rotation": 2
    },
    {
      "x": -75,
      "y": 63,
      "z": 0,
      "name": "Zone_Launch",
      "rotation": 2
    },
    {
      "x": -75,
      "y": 61,
      "z": 1,
      "name": "Zone_Launch",
      "rotation": 2
    },
    {
      "x": -75,
      "y": 62,
      "z": 1,
      "name": "Zone_Launch",
      "rotation": 2
    },
    {
      "x": -75,
      "y": 63,
      "z": 1,
      "name": "Zone_Launch",
      "rotation": 2
    },
    {
      "x": -75,
      "y": 61,
      "z": 2,
      "name": "Zone_Launch",
      "rotation": 2
    },
    {
      "x": -75,
      "y": 62,
      "z": 2,
      "name": "Zone_Launch",
      "rotation": 2
    },
    {
      "x": -75,
      "y": 63,
      "z": 2,
      "name": "Zone_Launch",
      "rotation": 2
    },
    {
      "x": -75,
      "y": 61,
      "z": 3,
      "name": "Zone_Launch",
      "rotation": 2
    },
    {
      "x": -75,
      "y": 62,
      "z": 3,
      "name": "Zone_Launch",
      "rotation": 2
    },
    {
      "x": -75,
      "y": 63,
      "z": 3,
      "name": "Zone_Launch",
      "rotation": 2
    },
    {
      "x": -75,
      "y": 61,
      "z": 4,
      "name": "Zone_Launch",
      "rotation": 2
    },
    {
      "x": -75,
      "y": 62,
      "z": 4,
      "name": "Zone_Launch",
      "rotation": 2
    },
    {
      "x": -75,
      "y": 63,
      "z": 4,
      "name": "Zone_Launch",
      "rotation": 2
    },
    {
      "x": -75,
      "y": 61,
      "z": 5,
      "name": "Zone_Launch",
      "rotation": 2
    },
    {
      "x": -75,
      "y": 62,
      "z": 5,
      "name": "Zone_Launch",
      "rotation": 2
    },
    {
      "x": -75,
      "y": 63,
      "z": 5,
      "name": "Zone_Launch",
      "rotation": 2
    },
    {
      "x": -75,
      "y": 61,
      "z": 6,
      "name": "Zone_Launch",
      "rotation": 2
    },
    {
      "x": -75,
      "y": 62,
      "z": 6,
      "name": "Zone_Launch",
      "rotation": 2
    },
    {
      "x": -75,
      "y": 63,
      "z": 6,
      "name": "Zone_Launch",
      "rotation": 2
    },
    {
      "x": -75,
      "y": 61,
      "z": 7,
      "name": "Zone_Launch",
      "rotation": 2
    },
    {
      "x": -75,
      "y": 62,
      "z": 7,
      "name": "Zone_Launch",
      "rotation": 2
    },
    {
      "x": -75,
      "y": 63,
      "z": 7,
      "name": "Zone_Launch",
      "rotation": 2
    },
    {
      "x": -75,
      "y": 61,
      "z": 8,
      "name": "Zone_Launch",
      "rotation": 2
    },
    {
      "x": -75,
      "y": 62,
      "z": 8,
      "name": "Zone_Launch",
      "rotation": 2
    },
    {
      "x": -75,
      "y": 63,
      "z": 8,
      "name": "Zone_Launch",
      "rotation": 2
    },
    {
      "x": -75,
      "y": 61,
      "z": 9,
      "name": "Zone_Launch",
      "rotation": 2
    },
    {
      "x": -75,
      "y": 62,
      "z": 9,
      "name": "Zone_Launch",
      "rotation": 2
    },
    {
      "x": -75,
      "y": 63,
      "z": 9,
      "name": "Zone_Launch",
      "rotation": 2
    },
    {
      "x": -75,
      "y": 61,
      "z": 10,
      "name": "Zone_Launch",
      "rotation": 2
    },
    {
      "x": -75,
      "y": 62,
      "z": 10,
      "name": "Zone_Launch",
      "rotation": 2
    },
    {
      "x": -75,
      "y": 63,
      "z": 10,
      "name": "Zone_Launch",
      "rotation": 2
    },
    {
      "x": -75,
      "y": 61,
      "z": 11,
      "name": "Zone_Launch",
      "rotation": 2
    },
    {
      "x": -75,
      "y": 62,
      "z": 11,
      "name": "Zone_Launch",
      "rotation": 2
    },
    {
      "x": -75,
      "y": 63,
      "z": 11,
      "name": "Zone_Launch",
      "rotation": 2
    },
    {
      "x": -75,
      "y": 61,
      "z": 12,
      "name": "Zone_Launch",
      "rotation": 2
    },
    {
      "x": -75,
      "y": 62,
      "z": 12,
      "name": "Zone_Launch",
      "rotation": 2
    },
    {
      "x": -75,
      "y": 63,
      "z": 12,
      "name": "Zone_Launch",
      "rotation": 2
    },
    {
      "x": -75,
      "y": 61,
      "z": 13,
      "name": "Zone_Launch",
      "rotation": 2
    },
    {
      "x": -75,
      "y": 62,
      "z": 13,
      "name": "Zone_Launch",
      "rotation": 2
    },
    {
      "x": -75,
      "y": 63,
      "z": 13,
      "name": "Zone_Launch",
      "rotation": 2
    },
    {
      "x": -75,
      "y": 61,
      "z": 14,
      "name": "Zone_Launch",
      "rotation": 2
    },
    {
      "x": -75,
      "y": 62,
      "z": 14,
      "name": "Zone_Launch",
      "rotation": 2
    },
    {
      "x": -75,
      "y": 63,
      "z": 14,
      "name": "Zone_Launch",
      "rotation": 2
    },
    {
      "x": -75,
      "y": 61,
      "z": 15,
      "name": "Zone_Launch",
      "rotation": 2
    },
    {
      "x": -75,
      "y": 62,
      "z": 15,
      "name": "Zone_Launch",
      "rotation": 2
    },
    {
      "x": -75,
      "y": 63,
      "z": 15,
      "name": "Zone_Launch",
      "rotation": 2
    },
    {
      "x": -75,
      "y": 61,
      "z": 16,
      "name": "Zone_Launch",
      "rotation": 2
    },
    {
      "x": -75,
      "y": 62,
      "z": 16,
      "name": "Zone_Launch",
      "rotation": 2
    },
    {
      "x": -75,
      "y": 63,
      "z": 16,
      "name": "Zone_Launch",
      "rotation": 2
    },
    {
      "x": -75,
      "y": 61,
      "z": 17,
      "name": "Zone_Launch",
      "rotation": 2
    },
    {
      "x": -75,
      "y": 62,
      "z": 17,
      "name": "Zone_Launch",
      "rotation": 2
    },
    {
      "x": -75,
      "y": 63,
      "z": 17,
      "name": "Zone_Launch",
      "rotation": 2
    },
    {
      "x": -75,
      "y": 61,
      "z": 18,
      "name": "Zone_Launch",
      "rotation": 2
    },
    {
      "x": -75,
      "y": 62,
      "z": 18,
      "name": "Zone_Launch",
      "rotation": 2
    },
    {
      "x": -75,
      "y": 63,
      "z": 18,
      "name": "Zone_Launch",
      "rotation": 2
    },
    {
      "x": -75,
      "y": 61,
      "z": 19,
      "name": "Zone_Launch",
      "rotation": 2
    },
    {
      "x": -75,
      "y": 62,
      "z": 19,
      "name": "Zone_Launch",
      "rotation": 2
    },
    {
      "x": -75,
      "y": 63,
      "z": 19,
      "name": "Zone_Launch",
      "rotation": 2
    },
    {
      "x": -75,
      "y": 64,
      "z": 19,
      "name": "Zone_Launch",
      "rotation": 1
    },
    {
      "x": -75,
      "y": 61,
      "z": 20,
      "name": "Zone_Launch",
      "rotation": 2
    },
    {
      "x": -75,
      "y": 62,
      "z": 20,
      "name": "Zone_Launch",
      "rotation": 2
    },
    {
      "x": -75,
      "y": 63,
      "z": 20,
      "name": "Zone_Launch",
      "rotation": 2
    },
    {
      "x": -75,
      "y": 64,
      "z": 20,
      "name": "Zone_Launch",
      "rotation": 1
    },
    {
      "x": -75,
      "y": 61,
      "z": 21,
      "name": "Zone_Launch",
      "rotation": 2
    },
    {
      "x": -75,
      "y": 62,
      "z": 21,
      "name": "Zone_Launch",
      "rotation": 2
    },
    {
      "x": -75,
      "y": 63,
      "z": 21,
      "name": "Zone_Launch",
      "rotation": 2
    },
    {
      "x": -75,
      "y": 64,
      "z": 21,
      "name": "Zone_Launch",
      "rotation": 1
    },
    {
      "x": -75,
      "y": 61,
      "z": 22,
      "name": "Zone_Launch",
      "rotation": 2
    },
    {
      "x": -75,
      "y": 62,
      "z": 22,
      "name": "Zone_Launch",
      "rotation": 2
    },
    {
      "x": -75,
      "y": 63,
      "z": 22,
      "name": "Zone_Launch",
      "rotation": 2
    },
    {
      "x": -75,
      "y": 64,
      "z": 22,
      "name": "Zone_Launch",
      "rotation": 1
    },
    {
      "x": -75,
      "y": 61,
      "z": 23,
      "name": "Zone_Launch",
      "rotation": 2
    },
    {
      "x": -75,
      "y": 62,
      "z": 23,
      "name": "Zone_Launch",
      "rotation": 2
    },
    {
      "x": -75,
      "y": 63,
      "z": 23,
      "name": "Zone_Launch",
      "rotation": 2
    },
    {
      "x": -75,
      "y": 64,
      "z": 23,
      "name": "Zone_Launch",
      "rotation": 1
    },
    {
      "x": -75,
      "y": 61,
      "z": 24,
      "name": "Zone_Launch",
      "rotation": 2
    },
    {
      "x": -75,
      "y": 62,
      "z": 24,
      "name": "Zone_Launch",
      "rotation": 2
    },
    {
      "x": -75,
      "y": 63,
      "z": 24,
      "name": "Zone_Launch",
      "rotation": 2
    },
    {
      "x": -75,
      "y": 64,
      "z": 24,
      "name": "Zone_Launch",
      "rotation": 1
    },
    {
      "x": -75,
      "y": 61,
      "z": 25,
      "name": "Zone_Launch",
      "rotation": 2
    },
    {
      "x": -75,
      "y": 62,
      "z": 25,
      "name": "Zone_Launch",
      "rotation": 2
    },
    {
      "x": -75,
      "y": 63,
      "z": 25,
      "name": "Zone_Launch",
      "rotation": 2
    },
    {
      "x": -75,
      "y": 64,
      "z": 25,
      "name": "Zone_Launch",
      "rotation": 1
    },
    {
      "x": -75,
      "y": 61,
      "z": 26,
      "name": "Zone_Launch",
      "rotation": 2
    },
    {
      "x": -75,
      "y": 62,
      "z": 26,
      "name": "Zone_Launch",
      "rotation": 2
    },
    {
      "x": -75,
      "y": 63,
      "z": 26,
      "name": "Zone_Launch",
      "rotation": 2
    },
    {
      "x": -75,
      "y": 64,
      "z": 26,
      "name": "Zone_Launch",
      "rotation": 1
    },
    {
      "x": -75,
      "y": 61,
      "z": 27,
      "name": "Zone_Launch",
      "rotation": 2
    },
    {
      "x": -75,
      "y": 62,
      "z": 27,
      "name": "Zone_Launch",
      "rotation": 2
    },
    {
      "x": -75,
      "y": 63,
      "z": 27,
      "name": "Zone_Launch",
      "rotation": 2
    },
    {
      "x": -75,
      "y": 64,
      "z": 27,
      "name": "Zone_Launch",
      "rotation": 3
    },
    {
      "x": -75,
      "y": 61,
      "z": 28,
      "name": "Zone_Launch",
      "rotation": 2
    },
    {
      "x": -75,
      "y": 62,
      "z": 28,
      "name": "Zone_Launch",
      "rotation": 2
    },
    {
      "x": -75,
      "y": 63,
      "z": 28,
      "name": "Zone_Launch",
      "rotation": 2
    },
    {
      "x": -75,
      "y": 64,
      "z": 28,
      "name": "Zone_Launch",
      "rotation": 3
    },
    {
      "x": -75,
      "y": 61,
      "z": 29,
      "name": "Zone_Launch",
      "rotation": 2
    },
    {
      "x": -75,
      "y": 62,
      "z": 29,
      "name": "Zone_Launch",
      "rotation": 2
    },
    {
      "x": -75,
      "y": 63,
      "z": 29,
      "name": "Zone_Launch",
      "rotation": 2
    },
    {
      "x": -75,
      "y": 64,
      "z": 29,
      "name": "Zone_Launch",
      "rotation": 3
    },
    {
      "x": -75,
      "y": 61,
      "z": 30,
      "name": "Zone_Launch",
      "rotation": 2
    },
    {
      "x": -75,
      "y": 62,
      "z": 30,
      "name": "Zone_Launch",
      "rotation": 2
    },
    {
      "x": -75,
      "y": 63,
      "z": 30,
      "name": "Zone_Launch",
      "rotation": 2
    },
    {
      "x": -75,
      "y": 64,
      "z": 30,
      "name": "Zone_Launch",
      "rotation": 3
    },
    {
      "x": -74,
      "y": 61,
      "z": -26,
      "name": "Zone_Launch",
      "rotation": 2
    },
    {
      "x": -74,
      "y": 62,
      "z": -26,
      "name": "Zone_Launch",
      "rotation": 2
    },
    {
      "x": -74,
      "y": 63,
      "z": -26,
      "name": "Zone_Launch",
      "rotation": 2
    },
    {
      "x": -74,
      "y": 64,
      "z": -26,
      "name": "Zone_Launch",
      "rotation": 3
    },
    {
      "x": -74,
      "y": 61,
      "z": -25,
      "name": "Zone_Launch",
      "rotation": 2
    },
    {
      "x": -74,
      "y": 62,
      "z": -25,
      "name": "Zone_Launch",
      "rotation": 2
    },
    {
      "x": -74,
      "y": 63,
      "z": -25,
      "name": "Zone_Launch",
      "rotation": 2
    },
    {
      "x": -74,
      "y": 64,
      "z": -25,
      "name": "Zone_Launch",
      "rotation": 3
    },
    {
      "x": -74,
      "y": 61,
      "z": -24,
      "name": "Zone_Launch",
      "rotation": 2
    },
    {
      "x": -74,
      "y": 62,
      "z": -24,
      "name": "Zone_Launch",
      "rotation": 2
    },
    {
      "x": -74,
      "y": 63,
      "z": -24,
      "name": "Zone_Launch",
      "rotation": 2
    },
    {
      "x": -74,
      "y": 64,
      "z": -24,
      "name": "Zone_Launch",
      "rotation": 3
    },
    {
      "x": -74,
      "y": 61,
      "z": -23,
      "name": "Zone_Launch",
      "rotation": 2
    },
    {
      "x": -74,
      "y": 62,
      "z": -23,
      "name": "Zone_Launch",
      "rotation": 2
    },
    {
      "x": -74,
      "y": 63,
      "z": -23,
      "name": "Zone_Launch",
      "rotation": 2
    },
    {
      "x": -74,
      "y": 64,
      "z": -23,
      "name": "Zone_Launch",
      "rotation": 1
    },
    {
      "x": -74,
      "y": 61,
      "z": -22,
      "name": "Zone_Launch",
      "rotation": 2
    },
    {
      "x": -74,
      "y": 62,
      "z": -22,
      "name": "Zone_Launch",
      "rotation": 2
    },
    {
      "x": -74,
      "y": 63,
      "z": -22,
      "name": "Zone_Launch",
      "rotation": 2
    },
    {
      "x": -74,
      "y": 64,
      "z": -22,
      "name": "Zone_Launch",
      "rotation": 1
    },
    {
      "x": -74,
      "y": 61,
      "z": -21,
      "name": "Zone_Launch",
      "rotation": 2
    },
    {
      "x": -74,
      "y": 62,
      "z": -21,
      "name": "Zone_Launch",
      "rotation": 2
    },
    {
      "x": -74,
      "y": 63,
      "z": -21,
      "name": "Zone_Launch",
      "rotation": 2
    },
    {
      "x": -74,
      "y": 64,
      "z": -21,
      "name": "Zone_Launch",
      "rotation": 1
    },
    {
      "x": -74,
      "y": 61,
      "z": -20,
      "name": "Zone_Launch",
      "rotation": 2
    },
    {
      "x": -74,
      "y": 62,
      "z": -20,
      "name": "Zone_Launch",
      "rotation": 2
    },
    {
      "x": -74,
      "y": 63,
      "z": -20,
      "name": "Zone_Launch",
      "rotation": 2
    },
    {
      "x": -74,
      "y": 64,
      "z": -20,
      "name": "Zone_Launch",
      "rotation": 1
    },
    {
      "x": -74,
      "y": 61,
      "z": -19,
      "name": "Zone_Launch",
      "rotation": 2
    },
    {
      "x": -74,
      "y": 62,
      "z": -19,
      "name": "Zone_Launch",
      "rotation": 2
    },
    {
      "x": -74,
      "y": 63,
      "z": -19,
      "name": "Zone_Launch",
      "rotation": 2
    },
    {
      "x": -74,
      "y": 64,
      "z": -19,
      "name": "Zone_Launch",
      "rotation": 1
    },
    {
      "x": -74,
      "y": 61,
      "z": -18,
      "name": "Zone_Launch",
      "rotation": 2
    },
    {
      "x": -74,
      "y": 62,
      "z": -18,
      "name": "Zone_Launch",
      "rotation": 2
    },
    {
      "x": -74,
      "y": 63,
      "z": -18,
      "name": "Zone_Launch",
      "rotation": 2
    },
    {
      "x": -74,
      "y": 64,
      "z": -18,
      "name": "Zone_Launch",
      "rotation": 1
    },
    {
      "x": -74,
      "y": 61,
      "z": -17,
      "name": "Zone_Launch",
      "rotation": 2
    },
    {
      "x": -74,
      "y": 62,
      "z": -17,
      "name": "Zone_Launch",
      "rotation": 2
    },
    {
      "x": -74,
      "y": 63,
      "z": -17,
      "name": "Zone_Launch",
      "rotation": 2
    },
    {
      "x": -74,
      "y": 64,
      "z": -17,
      "name": "Zone_Launch",
      "rotation": 1
    },
    {
      "x": -74,
      "y": 61,
      "z": -16,
      "name": "Zone_Launch",
      "rotation": 2
    },
    {
      "x": -74,
      "y": 62,
      "z": -16,
      "name": "Zone_Launch",
      "rotation": 2
    },
    {
      "x": -74,
      "y": 63,
      "z": -16,
      "name": "Zone_Launch",
      "rotation": 2
    },
    {
      "x": -74,
      "y": 61,
      "z": -15,
      "name": "Zone_Launch",
      "rotation": 2
    },
    {
      "x": -74,
      "y": 62,
      "z": -15,
      "name": "Zone_Launch",
      "rotation": 2
    },
    {
      "x": -74,
      "y": 63,
      "z": -15,
      "name": "Zone_Launch",
      "rotation": 2
    },
    {
      "x": -74,
      "y": 61,
      "z": -14,
      "name": "Zone_Launch",
      "rotation": 2
    },
    {
      "x": -74,
      "y": 62,
      "z": -14,
      "name": "Zone_Launch",
      "rotation": 2
    },
    {
      "x": -74,
      "y": 63,
      "z": -14,
      "name": "Zone_Launch",
      "rotation": 2
    },
    {
      "x": -74,
      "y": 61,
      "z": -13,
      "name": "Zone_Launch",
      "rotation": 2
    },
    {
      "x": -74,
      "y": 62,
      "z": -13,
      "name": "Zone_Launch",
      "rotation": 2
    },
    {
      "x": -74,
      "y": 63,
      "z": -13,
      "name": "Zone_Launch",
      "rotation": 2
    },
    {
      "x": -74,
      "y": 61,
      "z": -12,
      "name": "Zone_Launch",
      "rotation": 2
    },
    {
      "x": -74,
      "y": 62,
      "z": -12,
      "name": "Zone_Launch",
      "rotation": 2
    },
    {
      "x": -74,
      "y": 63,
      "z": -12,
      "name": "Zone_Launch",
      "rotation": 2
    },
    {
      "x": -74,
      "y": 61,
      "z": -11,
      "name": "Zone_Launch",
      "rotation": 2
    },
    {
      "x": -74,
      "y": 62,
      "z": -11,
      "name": "Zone_Launch",
      "rotation": 2
    },
    {
      "x": -74,
      "y": 63,
      "z": -11,
      "name": "Zone_Launch",
      "rotation": 2
    },
    {
      "x": -74,
      "y": 61,
      "z": -10,
      "name": "Zone_Launch",
      "rotation": 2
    },
    {
      "x": -74,
      "y": 62,
      "z": -10,
      "name": "Zone_Launch",
      "rotation": 2
    },
    {
      "x": -74,
      "y": 63,
      "z": -10,
      "name": "Zone_Launch",
      "rotation": 2
    },
    {
      "x": -74,
      "y": 61,
      "z": -9,
      "name": "Zone_Launch",
      "rotation": 2
    },
    {
      "x": -74,
      "y": 62,
      "z": -9,
      "name": "Zone_Launch",
      "rotation": 2
    },
    {
      "x": -74,
      "y": 63,
      "z": -9,
      "name": "Zone_Launch",
      "rotation": 2
    },
    {
      "x": -74,
      "y": 61,
      "z": -8,
      "name": "Zone_Launch",
      "rotation": 2
    },
    {
      "x": -74,
      "y": 62,
      "z": -8,
      "name": "Zone_Launch",
      "rotation": 2
    },
    {
      "x": -74,
      "y": 63,
      "z": -8,
      "name": "Zone_Launch",
      "rotation": 2
    },
    {
      "x": -74,
      "y": 61,
      "z": -7,
      "name": "Zone_Launch",
      "rotation": 2
    },
    {
      "x": -74,
      "y": 62,
      "z": -7,
      "name": "Zone_Launch",
      "rotation": 2
    },
    {
      "x": -74,
      "y": 63,
      "z": -7,
      "name": "Zone_Launch",
      "rotation": 2
    },
    {
      "x": -74,
      "y": 61,
      "z": -6,
      "name": "Zone_Launch",
      "rotation": 2
    },
    {
      "x": -74,
      "y": 62,
      "z": -6,
      "name": "Zone_Launch",
      "rotation": 2
    },
    {
      "x": -74,
      "y": 63,
      "z": -6,
      "name": "Zone_Launch",
      "rotation": 2
    },
    {
      "x": -74,
      "y": 61,
      "z": -5,
      "name": "Zone_Launch",
      "rotation": 2
    },
    {
      "x": -74,
      "y": 62,
      "z": -5,
      "name": "Zone_Launch",
      "rotation": 2
    },
    {
      "x": -74,
      "y": 63,
      "z": -5,
      "name": "Zone_Launch",
      "rotation": 2
    },
    {
      "x": -74,
      "y": 61,
      "z": -4,
      "name": "Zone_Launch",
      "rotation": 2
    },
    {
      "x": -74,
      "y": 62,
      "z": -4,
      "name": "Zone_Launch",
      "rotation": 2
    },
    {
      "x": -74,
      "y": 63,
      "z": -4,
      "name": "Zone_Launch",
      "rotation": 2
    },
    {
      "x": -74,
      "y": 61,
      "z": -3,
      "name": "Zone_Launch",
      "rotation": 2
    },
    {
      "x": -74,
      "y": 62,
      "z": -3,
      "name": "Zone_Launch",
      "rotation": 2
    },
    {
      "x": -74,
      "y": 63,
      "z": -3,
      "name": "Zone_Launch",
      "rotation": 2
    },
    {
      "x": -74,
      "y": 61,
      "z": -2,
      "name": "Zone_Launch",
      "rotation": 2
    },
    {
      "x": -74,
      "y": 62,
      "z": -2,
      "name": "Zone_Launch",
      "rotation": 2
    },
    {
      "x": -74,
      "y": 63,
      "z": -2,
      "name": "Zone_Launch",
      "rotation": 2
    },
    {
      "x": -74,
      "y": 61,
      "z": -1,
      "name": "Zone_Launch",
      "rotation": 2
    },
    {
      "x": -74,
      "y": 62,
      "z": -1,
      "name": "Zone_Launch",
      "rotation": 2
    },
    {
      "x": -74,
      "y": 63,
      "z": -1,
      "name": "Zone_Launch",
      "rotation": 2
    },
    {
      "x": -74,
      "y": 61,
      "z": 0,
      "name": "Zone_Launch",
      "rotation": 2
    },
    {
      "x": -74,
      "y": 62,
      "z": 0,
      "name": "Zone_Launch",
      "rotation": 2
    },
    {
      "x": -74,
      "y": 63,
      "z": 0,
      "name": "Zone_Launch",
      "rotation": 2
    },
    {
      "x": -74,
      "y": 61,
      "z": 1,
      "name": "Zone_Launch",
      "rotation": 2
    },
    {
      "x": -74,
      "y": 62,
      "z": 1,
      "name": "Zone_Launch",
      "rotation": 2
    },
    {
      "x": -74,
      "y": 63,
      "z": 1,
      "name": "Zone_Launch",
      "rotation": 2
    },
    {
      "x": -74,
      "y": 61,
      "z": 2,
      "name": "Zone_Launch",
      "rotation": 2
    },
    {
      "x": -74,
      "y": 62,
      "z": 2,
      "name": "Zone_Launch",
      "rotation": 2
    },
    {
      "x": -74,
      "y": 63,
      "z": 2,
      "name": "Zone_Launch",
      "rotation": 2
    },
    {
      "x": -74,
      "y": 64,
      "z": 2,
      "name": "Neon_Red"
    },
    {
      "x": -74,
      "y": 61,
      "z": 3,
      "name": "Zone_Launch",
      "rotation": 2
    },
    {
      "x": -74,
      "y": 62,
      "z": 3,
      "name": "Zone_Launch",
      "rotation": 2
    },
    {
      "x": -74,
      "y": 63,
      "z": 3,
      "name": "Zone_Launch",
      "rotation": 2
    },
    {
      "x": -74,
      "y": 64,
      "z": 3,
      "name": "Neon_Red",
      "rotation": 10
    },
    {
      "x": -74,
      "y": 61,
      "z": 4,
      "name": "Zone_Launch",
      "rotation": 2
    },
    {
      "x": -74,
      "y": 62,
      "z": 4,
      "name": "Zone_Launch",
      "rotation": 2
    },
    {
      "x": -74,
      "y": 63,
      "z": 4,
      "name": "Zone_Launch",
      "rotation": 2
    },
    {
      "x": -74,
      "y": 64,
      "z": 4,
      "name": "Neon_Red"
    },
    {
      "x": -74,
      "y": 61,
      "z": 5,
      "name": "Zone_Launch",
      "rotation": 2
    },
    {
      "x": -74,
      "y": 62,
      "z": 5,
      "name": "Zone_Launch",
      "rotation": 2
    },
    {
      "x": -74,
      "y": 63,
      "z": 5,
      "name": "Zone_Launch",
      "rotation": 2
    },
    {
      "x": -74,
      "y": 61,
      "z": 6,
      "name": "Zone_Launch",
      "rotation": 2
    },
    {
      "x": -74,
      "y": 62,
      "z": 6,
      "name": "Zone_Launch",
      "rotation": 2
    },
    {
      "x": -74,
      "y": 63,
      "z": 6,
      "name": "Zone_Launch",
      "rotation": 2
    },
    {
      "x": -74,
      "y": 61,
      "z": 7,
      "name": "Zone_Launch",
      "rotation": 2
    },
    {
      "x": -74,
      "y": 62,
      "z": 7,
      "name": "Zone_Launch",
      "rotation": 2
    },
    {
      "x": -74,
      "y": 63,
      "z": 7,
      "name": "Zone_Launch",
      "rotation": 2
    },
    {
      "x": -74,
      "y": 61,
      "z": 8,
      "name": "Zone_Launch",
      "rotation": 2
    },
    {
      "x": -74,
      "y": 62,
      "z": 8,
      "name": "Zone_Launch",
      "rotation": 2
    },
    {
      "x": -74,
      "y": 63,
      "z": 8,
      "name": "Zone_Launch",
      "rotation": 2
    },
    {
      "x": -74,
      "y": 61,
      "z": 9,
      "name": "Zone_Launch",
      "rotation": 2
    },
    {
      "x": -74,
      "y": 62,
      "z": 9,
      "name": "Zone_Launch",
      "rotation": 2
    },
    {
      "x": -74,
      "y": 63,
      "z": 9,
      "name": "Zone_Launch",
      "rotation": 2
    },
    {
      "x": -74,
      "y": 61,
      "z": 10,
      "name": "Zone_Launch",
      "rotation": 2
    },
    {
      "x": -74,
      "y": 62,
      "z": 10,
      "name": "Zone_Launch",
      "rotation": 2
    },
    {
      "x": -74,
      "y": 63,
      "z": 10,
      "name": "Zone_Launch",
      "rotation": 2
    },
    {
      "x": -74,
      "y": 61,
      "z": 11,
      "name": "Zone_Launch",
      "rotation": 2
    },
    {
      "x": -74,
      "y": 62,
      "z": 11,
      "name": "Zone_Launch",
      "rotation": 2
    },
    {
      "x": -74,
      "y": 63,
      "z": 11,
      "name": "Zone_Launch",
      "rotation": 2
    },
    {
      "x": -74,
      "y": 61,
      "z": 12,
      "name": "Zone_Launch",
      "rotation": 2
    },
    {
      "x": -74,
      "y": 62,
      "z": 12,
      "name": "Zone_Launch",
      "rotation": 2
    },
    {
      "x": -74,
      "y": 63,
      "z": 12,
      "name": "Zone_Launch",
      "rotation": 2
    },
    {
      "x": -74,
      "y": 61,
      "z": 13,
      "name": "Zone_Launch",
      "rotation": 2
    },
    {
      "x": -74,
      "y": 62,
      "z": 13,
      "name": "Zone_Launch",
      "rotation": 2
    },
    {
      "x": -74,
      "y": 63,
      "z": 13,
      "name": "Zone_Launch",
      "rotation": 2
    },
    {
      "x": -74,
      "y": 61,
      "z": 14,
      "name": "Zone_Launch",
      "rotation": 2
    },
    {
      "x": -74,
      "y": 62,
      "z": 14,
      "name": "Zone_Launch",
      "rotation": 2
    },
    {
      "x": -74,
      "y": 63,
      "z": 14,
      "name": "Zone_Launch",
      "rotation": 2
    },
    {
      "x": -74,
      "y": 61,
      "z": 15,
      "name": "Zone_Launch",
      "rotation": 2
    },
    {
      "x": -74,
      "y": 62,
      "z": 15,
      "name": "Zone_Launch",
      "rotation": 2
    },
    {
      "x": -74,
      "y": 63,
      "z": 15,
      "name": "Zone_Launch",
      "rotation": 2
    },
    {
      "x": -74,
      "y": 61,
      "z": 16,
      "name": "Zone_Launch",
      "rotation": 2
    },
    {
      "x": -74,
      "y": 62,
      "z": 16,
      "name": "Zone_Launch",
      "rotation": 2
    },
    {
      "x": -74,
      "y": 63,
      "z": 16,
      "name": "Zone_Launch",
      "rotation": 2
    },
    {
      "x": -74,
      "y": 61,
      "z": 17,
      "name": "Zone_Launch",
      "rotation": 2
    },
    {
      "x": -74,
      "y": 62,
      "z": 17,
      "name": "Zone_Launch",
      "rotation": 2
    },
    {
      "x": -74,
      "y": 63,
      "z": 17,
      "name": "Zone_Launch",
      "rotation": 2
    },
    {
      "x": -74,
      "y": 61,
      "z": 18,
      "name": "Zone_Launch",
      "rotation": 2
    },
    {
      "x": -74,
      "y": 62,
      "z": 18,
      "name": "Zone_Launch",
      "rotation": 2
    },
    {
      "x": -74,
      "y": 63,
      "z": 18,
      "name": "Zone_Launch",
      "rotation": 2
    },
    {
      "x": -74,
      "y": 61,
      "z": 19,
      "name": "Zone_Launch",
      "rotation": 2
    },
    {
      "x": -74,
      "y": 62,
      "z": 19,
      "name": "Zone_Launch",
      "rotation": 2
    },
    {
      "x": -74,
      "y": 63,
      "z": 19,
      "name": "Zone_Launch",
      "rotation": 2
    },
    {
      "x": -74,
      "y": 61,
      "z": 20,
      "name": "Zone_Launch",
      "rotation": 2
    },
    {
      "x": -74,
      "y": 62,
      "z": 20,
      "name": "Zone_Launch",
      "rotation": 2
    },
    {
      "x": -74,
      "y": 63,
      "z": 20,
      "name": "Zone_Launch",
      "rotation": 2
    },
    {
      "x": -74,
      "y": 61,
      "z": 21,
      "name": "Zone_Launch",
      "rotation": 2
    },
    {
      "x": -74,
      "y": 62,
      "z": 21,
      "name": "Zone_Launch",
      "rotation": 2
    },
    {
      "x": -74,
      "y": 63,
      "z": 21,
      "name": "Zone_Launch",
      "rotation": 2
    },
    {
      "x": -74,
      "y": 61,
      "z": 22,
      "name": "Zone_Launch",
      "rotation": 2
    },
    {
      "x": -74,
      "y": 62,
      "z": 22,
      "name": "Zone_Launch",
      "rotation": 2
    },
    {
      "x": -74,
      "y": 63,
      "z": 22,
      "name": "Zone_Launch",
      "rotation": 2
    },
    {
      "x": -74,
      "y": 61,
      "z": 23,
      "name": "Zone_Launch",
      "rotation": 2
    },
    {
      "x": -74,
      "y": 62,
      "z": 23,
      "name": "Zone_Launch",
      "rotation": 2
    },
    {
      "x": -74,
      "y": 63,
      "z": 23,
      "name": "Zone_Launch",
      "rotation": 2
    },
    {
      "x": -74,
      "y": 64,
      "z": 23,
      "name": "Zone_Launch",
      "rotation": 1
    },
    {
      "x": -74,
      "y": 61,
      "z": 24,
      "name": "Zone_Launch",
      "rotation": 2
    },
    {
      "x": -74,
      "y": 62,
      "z": 24,
      "name": "Zone_Launch",
      "rotation": 2
    },
    {
      "x": -74,
      "y": 63,
      "z": 24,
      "name": "Zone_Launch",
      "rotation": 2
    },
    {
      "x": -74,
      "y": 64,
      "z": 24,
      "name": "Zone_Launch",
      "rotation": 1
    },
    {
      "x": -74,
      "y": 61,
      "z": 25,
      "name": "Zone_Launch",
      "rotation": 2
    },
    {
      "x": -74,
      "y": 62,
      "z": 25,
      "name": "Zone_Launch",
      "rotation": 2
    },
    {
      "x": -74,
      "y": 63,
      "z": 25,
      "name": "Zone_Launch",
      "rotation": 2
    },
    {
      "x": -74,
      "y": 64,
      "z": 25,
      "name": "Zone_Launch",
      "rotation": 1
    },
    {
      "x": -74,
      "y": 61,
      "z": 26,
      "name": "Zone_Launch",
      "rotation": 2
    },
    {
      "x": -74,
      "y": 62,
      "z": 26,
      "name": "Zone_Launch",
      "rotation": 2
    },
    {
      "x": -74,
      "y": 63,
      "z": 26,
      "name": "Zone_Launch",
      "rotation": 2
    },
    {
      "x": -74,
      "y": 64,
      "z": 26,
      "name": "Zone_Launch",
      "rotation": 1
    },
    {
      "x": -74,
      "y": 61,
      "z": 27,
      "name": "Zone_Launch",
      "rotation": 2
    },
    {
      "x": -74,
      "y": 62,
      "z": 27,
      "name": "Zone_Launch",
      "rotation": 2
    },
    {
      "x": -74,
      "y": 63,
      "z": 27,
      "name": "Zone_Launch",
      "rotation": 2
    },
    {
      "x": -74,
      "y": 64,
      "z": 27,
      "name": "Zone_Launch",
      "rotation": 1
    },
    {
      "x": -74,
      "y": 61,
      "z": 28,
      "name": "Zone_Launch",
      "rotation": 2
    },
    {
      "x": -74,
      "y": 62,
      "z": 28,
      "name": "Zone_Launch",
      "rotation": 2
    },
    {
      "x": -74,
      "y": 63,
      "z": 28,
      "name": "Zone_Launch",
      "rotation": 2
    },
    {
      "x": -74,
      "y": 64,
      "z": 28,
      "name": "Zone_Launch",
      "rotation": 1
    },
    {
      "x": -74,
      "y": 61,
      "z": 29,
      "name": "Zone_Launch",
      "rotation": 2
    },
    {
      "x": -74,
      "y": 62,
      "z": 29,
      "name": "Zone_Launch",
      "rotation": 2
    },
    {
      "x": -74,
      "y": 63,
      "z": 29,
      "name": "Zone_Launch",
      "rotation": 2
    },
    {
      "x": -74,
      "y": 64,
      "z": 29,
      "name": "Zone_Launch",
      "rotation": 1
    },
    {
      "x": -74,
      "y": 61,
      "z": 30,
      "name": "Zone_Launch",
      "rotation": 2
    },
    {
      "x": -74,
      "y": 62,
      "z": 30,
      "name": "Zone_Launch",
      "rotation": 2
    },
    {
      "x": -74,
      "y": 63,
      "z": 30,
      "name": "Zone_Launch",
      "rotation": 2
    },
    {
      "x": -74,
      "y": 64,
      "z": 30,
      "name": "Zone_Launch",
      "rotation": 3
    },
    {
      "x": -74,
      "y": 61,
      "z": 31,
      "name": "Zone_Launch",
      "rotation": 2
    },
    {
      "x": -74,
      "y": 62,
