{
  "version": 8,
  "blockIdVersion": 11,
  "anchorX": 0,
  "anchorY": 0,
  "anchorZ": 0,
  "blocks": [
    {
      "x": -5,
      "y": 0,
      "z": -3,
      "name": "Block_White"
    },
    {
      "x": -5,
      "y": 1,
      "z": -3,
      "name": "Stair_White",
      "rotation": 3
    },
    {
      "x": -5,
      "y": 2,
      "z": -3,
      "name": "Zone_Empty"
    },
    {
      "x": -5,
      "y": 3,
      "z": -3,
      "name": "Zone_Empty"
    },
    {
      "x": -5,
      "y": 4,
      "z": -3,
      "name": "Zone_Empty"
    },
    {
      "x": -5,
      "y": 5,
      "z": -3,
      "name": "Zone_Empty"
    },
    {
      "x": -5,
      "y": 6,
      "z": -3,
      "name": "Zone_Empty"
    },
    {
      "x": -5,
      "y": 7,
      "z": -3,
      "name": "Zone_Empty"
    },
    {
      "x": -5,
      "y": 8,
      "z": -3,
      "name": "Zone_Empty"
    },
    {
      "x": -5,
      "y": 0,
      "z": -2,
      "name": "Stair_White",
      "rotation": 3
    },
    {
      "x": -5,
      "y": 1,
      "z": -2,
      "name": "Zone_Empty"
    },
    {
      "x": -5,
      "y": 2,
      "z": -2,
      "name": "Zone_Empty"
    },
    {
      "x": -5,
      "y": 3,
      "z": -2,
      "name": "Zone_Empty"
    },
    {
      "x": -5,
      "y": 4,
      "z": -2,
      "name": "Zone_Empty"
    },
    {
      "x": -5,
      "y": 5,
      "z": -2,
      "name": "Zone_Empty"
    },
    {
      "x": -5,
      "y": 6,
      "z": -2,
      "name": "Zone_Empty"
    },
    {
      "x": -5,
      "y": 7,
      "z": -2,
      "name": "Zone_Empty"
    },
    {
      "x": -5,
      "y": 8,
      "z": -2,
      "name": "Zone_Empty"
    },
    {
      "x": -5,
      "y": 0,
      "z": -1,
      "name": "Stair_White",
      "rotation": 3
    },
    {
      "x": -5,
      "y": 1,
      "z": -1,
      "name": "Zone_Empty"
    },
    {
      "x": -5,
      "y": 2,
      "z": -1,
      "name": "Zone_Empty"
    },
    {
      "x": -5,
      "y": 3,
      "z": -1,
      "name": "Zone_Empty"
    },
    {
      "x": -5,
      "y": 4,
      "z": -1,
      "name": "Zone_Empty"
    },
    {
      "x": -5,
      "y": 5,
      "z": -1,
      "name": "Zone_Empty"
    },
    {
      "x": -5,
      "y": 6,
      "z": -1,
      "name": "Zone_Empty"
    },
    {
      "x": -5,
      "y": 7,
      "z": -1,
      "name": "Zone_Empty"
    },
    {
      "x": -5,
      "y": 8,
      "z": -1,
      "name": "Zone_Empty"
    },
    {
      "x": -5,
      "y": 0,
      "z": 0,
      "name": "Stair_White",
      "rotation": 3
    },
    {
      "x": -5,
      "y": 1,
      "z": 0,
      "name": "Zone_Empty"
    },
    {
      "x": -5,
      "y": 2,
      "z": 0,
      "name": "Zone_Empty"
    },
    {
      "x": -5,
      "y": 3,
      "z": 0,
      "name": "Zone_Empty"
    },
    {
      "x": -5,
      "y": 4,
      "z": 0,
      "name": "Zone_Empty"
    },
    {
      "x": -5,
      "y": 5,
      "z": 0,
      "name": "Zone_Empty"
    },
    {
      "x": -5,
      "y": 6,
      "z": 0,
      "name": "Zone_Empty"
    },
    {
      "x": -5,
      "y": 7,
      "z": 0,
      "name": "Zone_Empty"
    },
    {
      "x": -5,
      "y": 8,
      "z": 0,
      "name": "Zone_Empty"
    },
    {
      "x": -5,
      "y": 0,
      "z": 1,
      "name": "Stair_White",
      "rotation": 3
    },
    {
      "x": -5,
      "y": 1,
      "z": 1,
      "name": "Zone_Empty"
    },
    {
      "x": -5,
      "y": 2,
      "z": 1,
      "name": "Zone_Empty"
    },
    {
      "x": -5,
      "y": 3,
      "z": 1,
      "name": "Zone_Empty"
    },
    {
      "x": -5,
      "y": 4,
      "z": 1,
      "name": "Zone_Empty"
    },
    {
      "x": -5,
      "y": 5,
      "z": 1,
      "name": "Zone_Empty"
    },
    {
      "x": -5,
      "y": 6,
      "z": 1,
      "name": "Zone_Empty"
    },
    {
      "x": -5,
      "y": 7,
      "z": 1,
      "name": "Zone_Empty"
    },
    {
      "x": -5,
      "y": 8,
      "z": 1,
      "name": "Zone_Empty"
    },
    {
      "x": -5,
      "y": 0,
      "z": 2,
      "name": "Stair_White",
      "rotation": 3
    },
    {
      "x": -5,
      "y": 1,
      "z": 2,
      "name": "Zone_Empty"
    },
    {
      "x": -5,
      "y": 2,
      "z": 2,
      "name": "Zone_Empty"
    },
    {
      "x": -5,
      "y": 3,
      "z": 2,
      "name": "Zone_Empty"
    },
    {
      "x": -5,
      "y": 4,
      "z": 2,
      "name": "Zone_Empty"
    },
    {
      "x": -5,
      "y": 5,
      "z": 2,
      "name": "Zone_Empty"
    },
    {
      "x": -5,
      "y": 6,
      "z": 2,
      "name": "Zone_Empty"
    },
    {
      "x": -5,
      "y": 7,
      "z": 2,
      "name": "Zone_Empty"
    },
    {
      "x": -5,
      "y": 8,
      "z": 2,
      "name": "Zone_Empty"
    },
    {
      "x": -5,
      "y": 0,
      "z": 3,
      "name": "Block_White"
    },
    {
      "x": -5,
      "y": 1,
      "z": 3,
      "name": "Stair_White",
      "rotation": 3
    },
    {
      "x": -5,
      "y": 2,
      "z": 3,
      "name": "Zone_Empty"
    },
    {
      "x": -5,
      "y": 3,
      "z": 3,
      "name": "Zone_Empty"
    },
    {
      "x": -5,
      "y": 4,
      "z": 3,
      "name": "Zone_Empty"
    },
    {
      "x": -5,
      "y": 5,
      "z": 3,
      "name": "Zone_Empty"
    },
    {
      "x": -5,
      "y": 6,
      "z": 3,
      "name": "Zone_Empty"
    },
    {
      "x": -5,
      "y": 7,
      "z": 3,
      "name": "Zone_Empty"
    },
    {
      "x": -5,
      "y": 8,
      "z": 3,
      "name": "Zone_Empty"
    },
    {
      "x": -4,
      "y": 0,
      "z": -3,
      "name": "Block_White"
    },
    {
      "x": -4,
      "y": 1,
      "z": -3,
      "name": "Block_White"
    },
    {
      "x": -4,
      "y": 2,
      "z": -3,
      "name": "Zone_Empty"
    },
    {
      "x": -4,
      "y": 3,
      "z": -3,
      "name": "Zone_Empty"
    },
    {
      "x": -4,
      "y": 4,
      "z": -3,
      "name": "Zone_Empty"
    },
    {
      "x": -4,
      "y": 5,
      "z": -3,
      "name": "Zone_Empty"
    },
    {
      "x": -4,
      "y": 6,
      "z": -3,
      "name": "Zone_Empty"
    },
    {
      "x": -4,
      "y": 7,
      "z": -3,
      "name": "Zone_Empty"
    },
    {
      "x": -4,
      "y": 8,
      "z": -3,
      "name": "Zone_Empty"
    },
    {
      "x": -4,
      "y": 0,
      "z": -2,
      "name": "Block_White"
    },
    {
      "x": -4,
      "y": 1,
      "z": -2,
      "name": "Stair_White",
      "rotation": 3
    },
    {
      "x": -4,
      "y": 2,
      "z": -2,
      "name": "Zone_Empty"
    },
    {
      "x": -4,
      "y": 3,
      "z": -2,
      "name": "Zone_Empty"
    },
    {
      "x": -4,
      "y": 4,
      "z": -2,
      "name": "Zone_Empty"
    },
    {
      "x": -4,
      "y": 5,
      "z": -2,
      "name": "Zone_Empty"
    },
    {
      "x": -4,
      "y": 6,
      "z": -2,
      "name": "Zone_Empty"
    },
    {
      "x": -4,
      "y": 7,
      "z": -2,
      "name": "Zone_Empty"
    },
    {
      "x": -4,
      "y": 8,
      "z": -2,
      "name": "Zone_Empty"
    },
    {
      "x": -4,
      "y": 0,
      "z": -1,
      "name": "Block_White"
    },
    {
      "x": -4,
      "y": 1,
      "z": -1,
      "name": "Stair_White",
      "rotation": 3
    },
    {
      "x": -4,
      "y": 2,
      "z": -1,
      "name": "Zone_Empty"
    },
    {
      "x": -4,
      "y": 3,
      "z": -1,
      "name": "Zone_Empty"
    },
    {
      "x": -4,
      "y": 4,
      "z": -1,
      "name": "Zone_Empty"
    },
    {
      "x": -4,
      "y": 5,
      "z": -1,
      "name": "Zone_Empty"
    },
    {
      "x": -4,
      "y": 6,
      "z": -1,
      "name": "Zone_Empty"
    },
    {
      "x": -4,
      "y": 7,
      "z": -1,
      "name": "Zone_Empty"
    },
    {
      "x": -4,
      "y": 8,
      "z": -1,
      "name": "Zone_Empty"
    },
    {
      "x": -4,
      "y": 0,
      "z": 0,
      "name": "Block_White"
    },
    {
      "x": -4,
      "y": 1,
      "z": 0,
      "name": "Stair_White",
      "rotation": 3
    },
    {
      "x": -4,
      "y": 2,
      "z": 0,
      "name": "Zone_Empty"
    },
    {
      "x": -4,
      "y": 3,
      "z": 0,
      "name": "Zone_Empty"
    },
    {
      "x": -4,
      "y": 4,
      "z": 0,
      "name": "Zone_Empty"
    },
    {
      "x": -4,
      "y": 5,
      "z": 0,
      "name": "Zone_Empty"
    },
    {
      "x": -4,
      "y": 6,
      "z": 0,
      "name": "Zone_Empty"
    },
    {
      "x": -4,
      "y": 7,
      "z": 0,
      "name": "Zone_Empty"
    },
    {
      "x": -4,
      "y": 8,
      "z": 0,
      "name": "Zone_Empty"
    },
    {
      "x": -4,
      "y": 0,
      "z": 1,
      "name": "Block_White"
    },
    {
      "x": -4,
      "y": 1,
      "z": 1,
      "name": "Stair_White",
      "rotation": 3
    },
    {
      "x": -4,
      "y": 2,
      "z": 1,
      "name": "Zone_Empty"
    },
    {
      "x": -4,
      "y": 3,
      "z": 1,
      "name": "Zone_Empty"
    },
    {
      "x": -4,
      "y": 4,
      "z": 1,
      "name": "Zone_Empty"
    },
    {
      "x": -4,
      "y": 5,
      "z": 1,
      "name": "Zone_Empty"
    },
    {
      "x": -4,
      "y": 6,
      "z": 1,
      "name": "Zone_Empty"
    },
    {
      "x": -4,
      "y": 7,
      "z": 1,
      "name": "Zone_Empty"
    },
    {
      "x": -4,
      "y": 8,
      "z": 1,
      "name": "Zone_Empty"
    },
    {
      "x": -4,
      "y": 0,
      "z": 2,
      "name": "Block_White"
    },
    {
      "x": -4,
      "y": 1,
      "z": 2,
      "name": "Stair_White",
      "rotation": 3
    },
    {
      "x": -4,
      "y": 2,
      "z": 2,
      "name": "Zone_Empty"
    },
    {
      "x": -4,
      "y": 3,
      "z": 2,
      "name": "Zone_Empty"
    },
    {
      "x": -4,
      "y": 4,
      "z": 2,
      "name": "Zone_Empty"
    },
    {
      "x": -4,
      "y": 5,
      "z": 2,
      "name": "Zone_Empty"
    },
    {
      "x": -4,
      "y": 6,
      "z": 2,
      "name": "Zone_Empty"
    },
    {
      "x": -4,
      "y": 7,
      "z": 2,
      "name": "Zone_Empty"
    },
    {
      "x": -4,
      "y": 8,
      "z": 2,
      "name": "Zone_Empty"
    },
    {
      "x": -4,
      "y": 0,
      "z": 3,
      "name": "Block_White"
    },
    {
      "x": -4,
      "y": 1,
      "z": 3,
      "name": "Block_White"
    },
    {
      "x": -4,
      "y": 2,
      "z": 3,
      "name": "Zone_Empty"
    },
    {
      "x": -4,
      "y": 3,
      "z": 3,
      "name": "Zone_Empty"
    },
    {
      "x": -4,
      "y": 4,
      "z": 3,
      "name": "Zone_Empty"
    },
    {
      "x": -4,
      "y": 5,
      "z": 3,
      "name": "Zone_Empty"
    },
    {
      "x": -4,
      "y": 6,
      "z": 3,
      "name": "Zone_Empty"
    },
    {
      "x": -4,
      "y": 7,
      "z": 3,
      "name": "Zone_Empty"
    },
    {
      "x": -4,
      "y": 8,
      "z": 3,
      "name": "Zone_Empty"
    },
    {
      "x": -3,
      "y": 0,
      "z": -5,
      "name": "Block_White"
    },
    {
      "x": -3,
      "y": 1,
      "z": -5,
      "name": "Stair_White",
      "rotation": 2
    },
    {
      "x": -3,
      "y": 2,
      "z": -5,
      "name": "Zone_Empty"
    },
    {
      "x": -3,
      "y": 3,
      "z": -5,
      "name": "Zone_Empty"
    },
    {
      "x": -3,
      "y": 4,
      "z": -5,
      "name": "Zone_Empty"
    },
    {
      "x": -3,
      "y": 5,
      "z": -5,
      "name": "Zone_Empty"
    },
    {
      "x": -3,
      "y": 6,
      "z": -5,
      "name": "Zone_Empty"
    },
    {
      "x": -3,
      "y": 7,
      "z": -5,
      "name": "Zone_Empty"
    },
    {
      "x": -3,
      "y": 8,
      "z": -5,
      "name": "Zone_Empty"
    },
    {
      "x": -3,
      "y": 0,
      "z": -4,
      "name": "Block_White"
    },
    {
      "x": -3,
      "y": 1,
      "z": -4,
      "name": "Block_White"
    },
    {
      "x": -3,
      "y": 2,
      "z": -4,
      "name": "Zone_Empty"
    },
    {
      "x": -3,
      "y": 3,
      "z": -4,
      "name": "Zone_Empty"
    },
    {
      "x": -3,
      "y": 4,
      "z": -4,
      "name": "Zone_Empty"
    },
    {
      "x": -3,
      "y": 5,
      "z": -4,
      "name": "Zone_Empty"
    },
    {
      "x": -3,
      "y": 6,
      "z": -4,
      "name": "Zone_Empty"
    },
    {
      "x": -3,
      "y": 7,
      "z": -4,
      "name": "Zone_Empty"
    },
    {
      "x": -3,
      "y": 8,
      "z": -4,
      "name": "Zone_Empty"
    },
    {
      "x": -3,
      "y": 0,
      "z": -3,
      "name": "Block_White"
    },
    {
      "x": -3,
      "y": 1,
      "z": -3,
      "name": "Block_White"
    },
    {
      "x": -3,
      "y": 2,
      "z": -3,
      "name": "Zone_Empty"
    },
    {
      "x": -3,
      "y": 3,
      "z": -3,
      "name": "Zone_Empty"
    },
    {
      "x": -3,
      "y": 4,
      "z": -3,
      "name": "Zone_Empty"
    },
    {
      "x": -3,
      "y": 5,
      "z": -3,
      "name": "Zone_Empty"
    },
    {
      "x": -3,
      "y": 6,
      "z": -3,
      "name": "Zone_Empty"
    },
    {
      "x": -3,
      "y": 7,
      "z": -3,
      "name": "Zone_Empty"
    },
    {
      "x": -3,
      "y": 8,
      "z": -3,
      "name": "Zone_Empty"
    },
    {
      "x": -3,
      "y": 0,
      "z": -2,
      "name": "Block_White"
    },
    {
      "x": -3,
      "y": 1,
      "z": -2,
      "name": "Block_White"
    },
    {
      "x": -3,
      "y": 2,
      "z": -2,
      "name": "Zone_Empty"
    },
    {
      "x": -3,
      "y": 3,
      "z": -2,
      "name": "Zone_Empty"
    },
    {
      "x": -3,
      "y": 4,
      "z": -2,
      "name": "Zone_Empty"
    },
    {
      "x": -3,
      "y": 5,
      "z": -2,
      "name": "Zone_Empty"
    },
    {
      "x": -3,
      "y": 6,
      "z": -2,
      "name": "Zone_Empty"
    },
    {
      "x": -3,
      "y": 7,
      "z": -2,
      "name": "Zone_Empty"
    },
    {
      "x": -3,
      "y": 8,
      "z": -2,
      "name": "Zone_Empty"
    },
    {
      "x": -3,
      "y": 0,
      "z": -1,
      "name": "Block_White"
    },
    {
      "x": -3,
      "y": 1,
      "z": -1,
      "name": "Block_White"
    },
    {
      "x": -3,
      "y": 2,
      "z": -1,
      "name": "Zone_Empty"
    },
    {
      "x": -3,
      "y": 3,
      "z": -1,
      "name": "Zone_Empty"
    },
    {
      "x": -3,
      "y": 4,
      "z": -1,
      "name": "Zone_Empty"
    },
    {
      "x": -3,
      "y": 5,
      "z": -1,
      "name": "Zone_Empty"
    },
    {
      "x": -3,
      "y": 6,
      "z": -1,
      "name": "Zone_Empty"
    },
    {
      "x": -3,
      "y": 7,
      "z": -1,
      "name": "Zone_Empty"
    },
    {
      "x": -3,
      "y": 8,
      "z": -1,
      "name": "Zone_Empty"
    },
    {
      "x": -3,
      "y": 0,
      "z": 0,
      "name": "Block_White"
    },
    {
      "x": -3,
      "y": 1,
      "z": 0,
      "name": "Neon_Red"
    },
    {
      "x": -3,
      "y": 2,
      "z": 0,
      "name": "Zone_Empty"
    },
    {
      "x": -3,
      "y": 3,
      "z": 0,
      "name": "Zone_Empty"
    },
    {
      "x": -3,
      "y": 4,
      "z": 0,
      "name": "Zone_Empty"
    },
    {
      "x": -3,
      "y": 5,
      "z": 0,
      "name": "Zone_Empty"
    },
    {
      "x": -3,
      "y": 6,
      "z": 0,
      "name": "Zone_Empty"
    },
    {
      "x": -3,
      "y": 7,
      "z": 0,
      "name": "Zone_Empty"
    },
    {
      "x": -3,
      "y": 8,
      "z": 0,
      "name": "Zone_Empty"
    },
    {
      "x": -3,
      "y": 0,
      "z": 1,
      "name": "Block_White"
    },
    {
      "x": -3,
      "y": 1,
      "z": 1,
      "name": "Block_White"
    },
    {
      "x": -3,
      "y": 2,
      "z": 1,
      "name": "Zone_Empty"
    },
    {
      "x": -3,
      "y": 3,
      "z": 1,
      "name": "Zone_Empty"
    },
    {
      "x": -3,
      "y": 4,
      "z": 1,
      "name": "Zone_Empty"
    },
    {
      "x": -3,
      "y": 5,
      "z": 1,
      "name": "Zone_Empty"
    },
    {
      "x": -3,
      "y": 6,
      "z": 1,
      "name": "Zone_Empty"
    },
    {
      "x": -3,
      "y": 7,
      "z": 1,
      "name": "Zone_Empty"
    },
    {
      "x": -3,
      "y": 8,
      "z": 1,
      "name": "Zone_Empty"
    },
    {
      "x": -3,
      "y": 0,
      "z": 2,
      "name": "Block_White"
    },
    {
      "x": -3,
      "y": 1,
      "z": 2,
      "name": "Block_White"
    },
    {
      "x": -3,
      "y": 2,
      "z": 2,
      "name": "Zone_Empty"
    },
    {
      "x": -3,
      "y": 3,
      "z": 2,
      "name": "Zone_Empty"
    },
    {
      "x": -3,
      "y": 4,
      "z": 2,
      "name": "Zone_Empty"
    },
    {
      "x": -3,
      "y": 5,
      "z": 2,
      "name": "Zone_Empty"
    },
    {
      "x": -3,
      "y": 6,
      "z": 2,
      "name": "Zone_Empty"
    },
    {
      "x": -3,
      "y": 7,
      "z": 2,
      "name": "Zone_Empty"
    },
    {
      "x": -3,
      "y": 8,
      "z": 2,
      "name": "Zone_Empty"
    },
    {
      "x": -3,
      "y": 0,
      "z": 3,
      "name": "Block_White"
    },
    {
      "x": -3,
      "y": 1,
      "z": 3,
      "name": "Block_White"
    },
    {
      "x": -3,
      "y": 2,
      "z": 3,
      "name": "Zone_Empty"
    },
    {
      "x": -3,
      "y": 3,
      "z": 3,
      "name": "Zone_Empty"
    },
    {
      "x": -3,
      "y": 4,
      "z": 3,
      "name": "Zone_Empty"
    },
    {
      "x": -3,
      "y": 5,
      "z": 3,
      "name": "Zone_Empty"
    },
    {
      "x": -3,
      "y": 6,
      "z": 3,
      "name": "Zone_Empty"
    },
    {
      "x": -3,
      "y": 7,
      "z": 3,
      "name": "Zone_Empty"
    },
    {
      "x": -3,
      "y": 8,
      "z": 3,
      "name": "Zone_Empty"
    },
    {
      "x": -3,
      "y": 0,
      "z": 4,
      "name": "Block_White"
    },
    {
      "x": -3,
      "y": 1,
      "z": 4,
      "name": "Block_White"
    },
    {
      "x": -3,
      "y": 2,
      "z": 4,
      "name": "Zone_Empty"
    },
    {
      "x": -3,
      "y": 3,
      "z": 4,
      "name": "Zone_Empty"
    },
    {
      "x": -3,
      "y": 4,
      "z": 4,
      "name": "Zone_Empty"
    },
    {
      "x": -3,
      "y": 5,
      "z": 4,
      "name": "Zone_Empty"
    },
    {
      "x": -3,
      "y": 6,
      "z": 4,
      "name": "Zone_Empty"
    },
    {
      "x": -3,
      "y": 7,
      "z": 4,
      "name": "Zone_Empty"
    },
    {
      "x": -3,
      "y": 8,
      "z": 4,
      "name": "Zone_Empty"
    },
    {
      "x": -3,
      "y": 0,
      "z": 5,
      "name": "Block_White"
    },
    {
      "x": -3,
      "y": 1,
      "z": 5,
      "name": "Stair_White"
    },
    {
      "x": -3,
      "y": 2,
      "z": 5,
      "name": "Zone_Empty"
    },
    {
      "x": -3,
      "y": 3,
      "z": 5,
      "name": "Zone_Empty"
    },
    {
      "x": -3,
      "y": 4,
      "z": 5,
      "name": "Zone_Empty"
    },
    {
      "x": -3,
      "y": 5,
      "z": 5,
      "name": "Zone_Empty"
    },
    {
      "x": -3,
      "y": 6,
      "z": 5,
      "name": "Zone_Empty"
    },
    {
      "x": -3,
      "y": 7,
      "z": 5,
      "name": "Zone_Empty"
    },
    {
      "x": -3,
      "y": 8,
      "z": 5,
      "name": "Zone_Empty"
    },
    {
      "x": -2,
      "y": 0,
      "z": -5,
      "name": "Stair_White",
      "rotation": 2
    },
    {
      "x": -2,
      "y": 1,
      "z": -5,
      "name": "Zone_Empty"
    },
    {
      "x": -2,
      "y": 2,
      "z": -5,
      "name": "Zone_Empty"
    },
    {
      "x": -2,
      "y": 3,
      "z": -5,
      "name": "Zone_Empty"
    },
    {
      "x": -2,
      "y": 4,
      "z": -5,
      "name": "Zone_Empty"
    },
    {
      "x": -2,
      "y": 5,
      "z": -5,
      "name": "Zone_Empty"
    },
    {
      "x": -2,
      "y": 6,
      "z": -5,
      "name": "Zone_Empty"
    },
    {
      "x": -2,
      "y": 7,
      "z": -5,
      "name": "Zone_Empty"
    },
    {
      "x": -2,
      "y": 8,
      "z": -5,
      "name": "Zone_Empty"
    },
    {
      "x": -2,
      "y": 0,
      "z": -4,
      "name": "Block_White"
    },
    {
      "x": -2,
      "y": 1,
      "z": -4,
      "name": "Stair_White",
      "rotation": 2
    },
    {
      "x": -2,
      "y": 2,
      "z": -4,
      "name": "Zone_Empty"
    },
    {
      "x": -2,
      "y": 3,
      "z": -4,
      "name": "Zone_Empty"
    },
    {
      "x": -2,
      "y": 4,
      "z": -4,
      "name": "Zone_Empty"
    },
    {
      "x": -2,
      "y": 5,
      "z": -4,
      "name": "Zone_Empty"
    },
    {
      "x": -2,
      "y": 6,
      "z": -4,
      "name": "Zone_Empty"
    },
    {
      "x": -2,
      "y": 7,
      "z": -4,
      "name": "Zone_Empty"
    },
    {
      "x": -2,
      "y": 8,
      "z": -4,
      "name": "Zone_Empty"
    },
    {
      "x": -2,
      "y": 0,
      "z": -3,
      "name": "Block_White"
    },
    {
      "x": -2,
      "y": 1,
      "z": -3,
      "name": "Block_White"
    },
    {
      "x": -2,
      "y": 2,
      "z": -3,
      "name": "Zone_Empty"
    },
    {
      "x": -2,
      "y": 3,
      "z": -3,
      "name": "Zone_Empty"
    },
    {
      "x": -2,
      "y": 4,
      "z": -3,
      "name": "Zone_Empty"
    },
    {
      "x": -2,
      "y": 5,
      "z": -3,
      "name": "Zone_Empty"
    },
    {
      "x": -2,
      "y": 6,
      "z": -3,
      "name": "Zone_Empty"
    },
    {
      "x": -2,
      "y": 7,
      "z": -3,
      "name": "Zone_Empty"
    },
    {
      "x": -2,
      "y": 8,
      "z": -3,
      "name": "Zone_Empty"
    },
    {
      "x": -2,
      "y": 0,
      "z": -2,
      "name": "Block_White"
    },
    {
      "x": -2,
      "y": 1,
      "z": -2,
      "name": "Neon_Orange"
    },
    {
      "x": -2,
      "y": 2,
      "z": -2,
      "name": "Zone_Empty"
    },
    {
      "x": -2,
      "y": 3,
      "z": -2,
      "name": "Zone_Empty"
    },
    {
      "x": -2,
      "y": 4,
      "z": -2,
      "name": "Zone_Empty"
    },
    {
      "x": -2,
      "y": 5,
      "z": -2,
      "name": "Zone_Empty"
    },
    {
      "x": -2,
      "y": 6,
      "z": -2,
      "name": "Zone_Empty"
    },
    {
      "x": -2,
      "y": 7,
      "z": -2,
      "name": "Zone_Empty"
    },
    {
      "x": -2,
      "y": 8,
      "z": -2,
      "name": "Zone_Empty"
    },
    {
      "x": -2,
      "y": 0,
      "z": -1,
      "name": "Block_White"
    },
    {
      "x": -2,
      "y": 1,
      "z": -1,
      "name": "Block_White"
    },
    {
      "x": -2,
      "y": 2,
      "z": -1,
      "name": "Zone_Empty"
    },
    {
      "x": -2,
      "y": 3,
      "z": -1,
      "name": "Zone_Empty"
    },
    {
      "x": -2,
      "y": 4,
      "z": -1,
      "name": "Zone_Empty"
    },
    {
      "x": -2,
      "y": 5,
      "z": -1,
      "name": "Zone_Empty"
    },
    {
      "x": -2,
      "y": 6,
      "z": -1,
      "name": "Zone_Empty"
    },
    {
      "x": -2,
      "y": 7,
      "z": -1,
      "name": "Zone_Empty"
    },
    {
      "x": -2,
      "y": 8,
      "z": -1,
      "name": "Zone_Empty"
    },
    {
      "x": -2,
      "y": 0,
      "z": 0,
      "name": "Block_White"
    },
    {
      "x": -2,
      "y": 1,
      "z": 0,
      "name": "Block_White"
    },
    {
      "x": -2,
      "y": 2,
      "z": 0,
      "name": "Zone_Empty"
    },
    {
      "x": -2,
      "y": 3,
      "z": 0,
      "name": "Zone_Empty"
    },
    {
      "x": -2,
      "y": 4,
      "z": 0,
      "name": "Zone_Empty"
    },
    {
      "x": -2,
      "y": 5,
      "z": 0,
      "name": "Zone_Empty"
    },
    {
      "x": -2,
      "y": 6,
      "z": 0,
      "name": "Zone_Empty"
    },
    {
      "x": -2,
      "y": 7,
      "z": 0,
      "name": "Zone_Empty"
    },
    {
      "x": -2,
      "y": 8,
      "z": 0,
      "name": "Zone_Empty"
    },
    {
      "x": -2,
      "y": 0,
      "z": 1,
      "name": "Block_White"
    },
    {
      "x": -2,
      "y": 1,
      "z": 1,
      "name": "Block_White"
    },
    {
      "x": -2,
      "y": 2,
      "z": 1,
      "name": "Zone_Empty"
    },
    {
      "x": -2,
      "y": 3,
      "z": 1,
      "name": "Zone_Empty"
    },
    {
      "x": -2,
      "y": 4,
      "z": 1,
      "name": "Zone_Empty"
    },
    {
      "x": -2,
      "y": 5,
      "z": 1,
      "name": "Zone_Empty"
    },
    {
      "x": -2,
      "y": 6,
      "z": 1,
      "name": "Zone_Empty"
    },
    {
      "x": -2,
      "y": 7,
      "z": 1,
      "name": "Zone_Empty"
    },
    {
      "x": -2,
      "y": 8,
      "z": 1,
      "name": "Zone_Empty"
    },
    {
      "x": -2,
      "y": 0,
      "z": 2,
      "name": "Block_White"
    },
    {
      "x": -2,
      "y": 1,
      "z": 2,
      "name": "Neon_Pink"
    },
    {
      "x": -2,
      "y": 2,
      "z": 2,
      "name": "Zone_Empty"
    },
    {
      "x": -2,
      "y": 3,
      "z": 2,
      "name": "Zone_Empty"
    },
    {
      "x": -2,
      "y": 4,
      "z": 2,
      "name": "Zone_Empty"
    },
    {
      "x": -2,
      "y": 5,
      "z": 2,
      "name": "Zone_Empty"
    },
    {
      "x": -2,
      "y": 6,
      "z": 2,
      "name": "Zone_Empty"
    },
    {
      "x": -2,
      "y": 7,
      "z": 2,
      "name": "Zone_Empty"
    },
    {
      "x": -2,
      "y": 8,
      "z": 2,
      "name": "Zone_Empty"
    },
    {
      "x": -2,
      "y": 0,
      "z": 3,
      "name": "Block_White"
    },
    {
      "x": -2,
      "y": 1,
      "z": 3,
      "name": "Block_White"
    },
    {
      "x": -2,
      "y": 2,
      "z": 3,
      "name": "Zone_Empty"
    },
    {
      "x": -2,
      "y": 3,
      "z": 3,
      "name": "Zone_Empty"
    },
    {
      "x": -2,
      "y": 4,
      "z": 3,
      "name": "Zone_Empty"
    },
    {
      "x": -2,
      "y": 5,
      "z": 3,
      "name": "Zone_Empty"
    },
    {
      "x": -2,
      "y": 6,
      "z": 3,
      "name": "Zone_Empty"
    },
    {
      "x": -2,
      "y": 7,
      "z": 3,
      "name": "Zone_Empty"
    },
    {
      "x": -2,
      "y": 8,
      "z": 3,
      "name": "Zone_Empty"
    },
    {
      "x": -2,
      "y": 0,
      "z": 4,
      "name": "Block_White"
    },
    {
      "x": -2,
      "y": 1,
      "z": 4,
      "name": "Stair_White"
    },
    {
      "x": -2,
      "y": 2,
      "z": 4,
      "name": "Zone_Empty"
    },
    {
      "x": -2,
      "y": 3,
      "z": 4,
      "name": "Zone_Empty"
    },
    {
      "x": -2,
      "y": 4,
      "z": 4,
      "name": "Zone_Empty"
    },
    {
      "x": -2,
      "y": 5,
      "z": 4,
      "name": "Zone_Empty"
    },
    {
      "x": -2,
      "y": 6,
      "z": 4,
      "name": "Zone_Empty"
    },
    {
      "x": -2,
      "y": 7,
      "z": 4,
      "name": "Zone_Empty"
    },
    {
      "x": -2,
      "y": 8,
      "z": 4,
      "name": "Zone_Empty"
    },
    {
      "x": -2,
      "y": 0,
      "z": 5,
      "name": "Stair_White"
    },
    {
      "x": -2,
      "y": 1,
      "z": 5,
      "name": "Zone_Empty"
    },
    {
      "x": -2,
      "y": 2,
      "z": 5,
      "name": "Zone_Empty"
    },
    {
      "x": -2,
      "y": 3,
      "z": 5,
      "name": "Zone_Empty"
    },
    {
      "x": -2,
      "y": 4,
      "z": 5,
      "name": "Zone_Empty"
    },
    {
      "x": -2,
      "y": 5,
      "z": 5,
      "name": "Zone_Empty"
    },
    {
      "x": -2,
      "y": 6,
      "z": 5,
      "name": "Zone_Empty"
    },
    {
      "x": -2,
      "y": 7,
      "z": 5,
      "name": "Zone_Empty"
    },
    {
      "x": -2,
      "y": 8,
      "z": 5,
      "name": "Zone_Empty"
    },
    {
      "x": -1,
      "y": 0,
      "z": -5,
      "name": "Stair_White",
      "rotation": 2
    },
    {
      "x": -1,
      "y": 1,
      "z": -5,
      "name": "Zone_Empty"
    },
    {
      "x": -1,
      "y": 2,
      "z": -5,
      "name": "Zone_Empty"
    },
    {
      "x": -1,
      "y": 3,
      "z": -5,
      "name": "Zone_Empty"
    },
    {
      "x": -1,
      "y": 4,
      "z": -5,
      "name": "Zone_Empty"
    },
    {
      "x": -1,
      "y": 5,
      "z": -5,
      "name": "Zone_Empty"
    },
    {
      "x": -1,
      "y": 6,
      "z": -5,
      "name": "Zone_Empty"
    },
    {
      "x": -1,
      "y": 7,
      "z": -5,
      "name": "Zone_Empty"
    },
    {
      "x": -1,
      "y": 8,
      "z": -5,
      "name": "Zone_Empty"
    },
    {
      "x": -1,
      "y": 0,
      "z": -4,
      "name": "Block_White"
    },
    {
      "x": -1,
      "y": 1,
      "z": -4,
      "name": "Stair_White",
      "rotation": 2
    },
    {
      "x": -1,
      "y": 2,
      "z": -4,
      "name": "Zone_Empty"
    },
    {
      "x": -1,
      "y": 3,
      "z": -4,
      "name": "Zone_Empty"
    },
    {
      "x": -1,
      "y": 4,
      "z": -4,
      "name": "Zone_Empty"
    },
    {
      "x": -1,
      "y": 5,
      "z": -4,
      "name": "Zone_Empty"
    },
    {
      "x": -1,
      "y": 6,
      "z": -4,
      "name": "Zone_Empty"
    },
    {
      "x": -1,
      "y": 7,
      "z": -4,
      "name": "Zone_Empty"
    },
    {
      "x": -1,
      "y": 8,
      "z": -4,
      "name": "Zone_Empty"
    },
    {
      "x": -1,
      "y": 0,
      "z": -3,
      "name": "Block_White"
    },
    {
      "x": -1,
      "y": 1,
      "z": -3,
      "name": "Block_White"
    },
    {
      "x": -1,
      "y": 2,
      "z": -3,
      "name": "Zone_Empty"
    },
    {
      "x": -1,
      "y": 3,
      "z": -3,
      "name": "Zone_Empty"
    },
    {
      "x": -1,
      "y": 4,
      "z": -3,
      "name": "Zone_Empty"
    },
    {
      "x": -1,
      "y": 5,
      "z": -3,
      "name": "Zone_Empty"
    },
    {
      "x": -1,
      "y": 6,
      "z": -3,
      "name": "Zone_Empty"
    },
    {
      "x": -1,
      "y": 7,
      "z": -3,
      "name": "Zone_Empty"
    },
    {
      "x": -1,
      "y": 8,
      "z": -3,
      "name": "Zone_Empty"
    },
    {
      "x": -1,
      "y": 0,
      "z": -2,
      "name": "Block_White"
    },
    {
      "x": -1,
      "y": 1,
      "z": -2,
      "name": "Block_White"
    },
    {
      "x": -1,
      "y": 2,
      "z": -2,
      "name": "Zone_Empty"
    },
    {
      "x": -1,
      "y": 3,
      "z": -2,
      "name": "Zone_Empty"
    },
    {
      "x": -1,
      "y": 4,
      "z": -2,
      "name": "Zone_Empty"
    },
    {
      "x": -1,
      "y": 5,
      "z": -2,
      "name": "Zone_Empty"
    },
    {
      "x": -1,
      "y": 6,
      "z": -2,
      "name": "Zone_Empty"
    },
    {
      "x": -1,
      "y": 7,
      "z": -2,
      "name": "Zone_Empty"
    },
    {
      "x": -1,
      "y": 8,
      "z": -2,
      "name": "Zone_Empty"
    },
    {
      "x": -1,
      "y": 0,
      "z": -1,
      "name": "Block_White"
    },
    {
      "x": -1,
      "y": 1,
      "z": -1,
      "name": "Block_White"
    },
    {
      "x": -1,
      "y": 2,
      "z": -1,
      "name": "Zone_Empty"
    },
    {
      "x": -1,
      "y": 3,
      "z": -1,
      "name": "Zone_Empty"
    },
    {
      "x": -1,
      "y": 4,
      "z": -1,
      "name": "Zone_Empty"
    },
    {
      "x": -1,
      "y": 5,
      "z": -1,
      "name": "Zone_Empty"
    },
    {
      "x": -1,
      "y": 6,
      "z": -1,
      "name": "Zone_Empty"
    },
    {
      "x": -1,
      "y": 7,
      "z": -1,
      "name": "Zone_Empty"
    },
    {
      "x": -1,
      "y": 8,
      "z": -1,
      "name": "Zone_Empty"
    },
    {
      "x": -1,
      "y": 0,
      "z": 0,
      "name": "Block_White"
    },
    {
      "x": -1,
      "y": 1,
      "z": 0,
      "name": "Block_White"
    },
    {
      "x": -1,
      "y": 2,
      "z": 0,
      "name": "Zone_Empty"
    },
    {
      "x": -1,
      "y": 3,
      "z": 0,
      "name": "Zone_Empty"
    },
    {
      "x": -1,
      "y": 4,
      "z": 0,
      "name": "Zone_Empty"
    },
    {
      "x": -1,
      "y": 5,
      "z": 0,
      "name": "Zone_Empty"
    },
    {
      "x": -1,
      "y": 6,
      "z": 0,
      "name": "Zone_Empty"
    },
    {
      "x": -1,
      "y": 7,
      "z": 0,
      "name": "Zone_Empty"
    },
    {
      "x": -1,
      "y": 8,
      "z": 0,
      "name": "Zone_Empty"
    },
    {
      "x": -1,
      "y": 0,
      "z": 1,
      "name": "Block_White"
    },
    {
      "x": -1,
      "y": 1,
      "z": 1,
      "name": "Block_White"
    },
    {
      "x": -1,
      "y": 2,
      "z": 1,
      "name": "Zone_Empty"
    },
    {
      "x": -1,
      "y": 3,
      "z": 1,
      "name": "Zone_Empty"
    },
    {
      "x": -1,
      "y": 4,
      "z": 1,
      "name": "Zone_Empty"
    },
    {
      "x": -1,
      "y": 5,
      "z": 1,
      "name": "Zone_Empty"
    },
    {
      "x": -1,
      "y": 6,
      "z": 1,
      "name": "Zone_Empty"
    },
    {
      "x": -1,
      "y": 7,
      "z": 1,
      "name": "Zone_Empty"
    },
    {
      "x": -1,
      "y": 8,
      "z": 1,
      "name": "Zone_Empty"
    },
    {
      "x": -1,
      "y": 0,
      "z": 2,
      "name": "Block_White"
    },
    {
      "x": -1,
      "y": 1,
      "z": 2,
      "name": "Block_White"
    },
    {
      "x": -1,
      "y": 2,
      "z": 2,
      "name": "Zone_Empty"
    },
    {
      "x": -1,
      "y": 3,
      "z": 2,
      "name": "Zone_Empty"
    },
    {
      "x": -1,
      "y": 4,
      "z": 2,
      "name": "Zone_Empty"
    },
    {
      "x": -1,
      "y": 5,
      "z": 2,
      "name": "Zone_Empty"
    },
    {
      "x": -1,
      "y": 6,
      "z": 2,
      "name": "Zone_Empty"
    },
    {
      "x": -1,
      "y": 7,
      "z": 2,
      "name": "Zone_Empty"
    },
    {
      "x": -1,
      "y": 8,
      "z": 2,
      "name": "Zone_Empty"
    },
    {
      "x": -1,
      "y": 0,
      "z": 3,
      "name": "Block_White"
    },
    {
      "x": -1,
      "y": 1,
      "z": 3,
      "name": "Block_White"
    },
    {
      "x": -1,
      "y": 2,
      "z": 3,
      "name": "Zone_Empty"
    },
    {
      "x": -1,
      "y": 3,
      "z": 3,
      "name": "Zone_Empty"
    },
    {
      "x": -1,
      "y": 4,
      "z": 3,
      "name": "Zone_Empty"
    },
    {
      "x": -1,
      "y": 5,
      "z": 3,
      "name": "Zone_Empty"
    },
    {
      "x": -1,
      "y": 6,
      "z": 3,
      "name": "Zone_Empty"
    },
    {
      "x": -1,
      "y": 7,
      "z": 3,
      "name": "Zone_Empty"
    },
    {
      "x": -1,
      "y": 8,
      "z": 3,
      "name": "Zone_Empty"
    },
    {
      "x": -1,
      "y": 0,
      "z": 4,
      "name": "Block_White"
    },
    {
      "x": -1,
      "y": 1,
      "z": 4,
      "name": "Stair_White"
    },
    {
      "x": -1,
      "y": 2,
      "z": 4,
      "name": "Zone_Empty"
    },
    {
      "x": -1,
      "y": 3,
      "z": 4,
      "name": "Zone_Empty"
    },
    {
      "x": -1,
      "y": 4,
      "z": 4,
      "name": "Zone_Empty"
    },
    {
      "x": -1,
      "y": 5,
      "z": 4,
      "name": "Zone_Empty"
    },
    {
      "x": -1,
      "y": 6,
      "z": 4,
      "name": "Zone_Empty"
    },
    {
      "x": -1,
      "y": 7,
      "z": 4,
      "name": "Zone_Empty"
    },
    {
      "x": -1,
      "y": 8,
      "z": 4,
      "name": "Zone_Empty"
    },
    {
      "x": -1,
      "y": 0,
      "z": 5,
      "name": "Stair_White"
    },
    {
      "x": -1,
      "y": 1,
      "z": 5,
      "name": "Zone_Empty"
    },
    {
      "x": -1,
      "y": 2,
      "z": 5,
      "name": "Zone_Empty"
    },
    {
      "x": -1,
      "y": 3,
      "z": 5,
      "name": "Zone_Empty"
    },
    {
      "x": -1,
      "y": 4,
      "z": 5,
      "name": "Zone_Empty"
    },
    {
      "x": -1,
      "y": 5,
      "z": 5,
      "name": "Zone_Empty"
    },
    {
      "x": -1,
      "y": 6,
      "z": 5,
      "name": "Zone_Empty"
    },
    {
      "x": -1,
      "y": 7,
      "z": 5,
      "name": "Zone_Empty"
    },
    {
      "x": -1,
      "y": 8,
      "z": 5,
      "name": "Zone_Empty"
    },
    {
      "x": 0,
      "y": 0,
      "z": -5,
      "name": "Stair_White",
      "rotation": 2
    },
    {
      "x": 0,
      "y": 1,
      "z": -5,
      "name": "Zone_Empty"
    },
    {
      "x": 0,
      "y": 2,
      "z": -5,
      "name": "Zone_Empty"
    },
    {
      "x": 0,
      "y": 3,
      "z": -5,
      "name": "Zone_Empty"
    },
    {
      "x": 0,
      "y": 4,
      "z": -5,
      "name": "Zone_Empty"
    },
    {
      "x": 0,
      "y": 5,
      "z": -5,
      "name": "Zone_Empty"
    },
    {
      "x": 0,
      "y": 6,
      "z": -5,
      "name": "Zone_Empty"
    },
    {
      "x": 0,
      "y": 7,
      "z": -5,
      "name": "Zone_Empty"
    },
    {
      "x": 0,
      "y": 8,
      "z": -5,
      "name": "Zone_Empty"
    },
    {
      "x": 0,
      "y": 0,
      "z": -4,
      "name": "Block_White"
    },
    {
      "x": 0,
      "y": 1,
      "z": -4,
      "name": "Stair_White",
      "rotation": 2
    },
    {
      "x": 0,
      "y": 2,
      "z": -4,
      "name": "Zone_Empty"
    },
    {
      "x": 0,
      "y": 3,
      "z": -4,
      "name": "Zone_Empty"
    },
    {
      "x": 0,
      "y": 4,
      "z": -4,
      "name": "Zone_Empty"
    },
    {
      "x": 0,
      "y": 5,
      "z": -4,
      "name": "Zone_Empty"
    },
    {
      "x": 0,
      "y": 6,
      "z": -4,
      "name": "Zone_Empty"
    },
    {
      "x": 0,
      "y": 7,
      "z": -4,
      "name": "Zone_Empty"
    },
    {
      "x": 0,
      "y": 8,
      "z": -4,
      "name": "Zone_Empty"
    },
    {
      "x": 0,
      "y": 0,
      "z": -3,
      "name": "Block_White"
    },
    {
      "x": 0,
      "y": 1,
      "z": -3,
      "name": "Neon_Yellow"
    },
    {
      "x": 0,
      "y": 2,
      "z": -3,
      "name": "Zone_Empty"
    },
    {
      "x": 0,
      "y": 3,
      "z": -3,
      "name": "Zone_Empty"
    },
    {
      "x": 0,
      "y": 4,
      "z": -3,
      "name": "Zone_Empty"
    },
    {
      "x": 0,
      "y": 5,
      "z": -3,
      "name": "Zone_Empty"
    },
    {
      "x": 0,
      "y": 6,
      "z": -3,
      "name": "Zone_Empty"
    },
    {
      "x": 0,
      "y": 7,
      "z": -3,
      "name": "Zone_Empty"
    },
    {
      "x": 0,
      "y": 8,
      "z": -3,
      "name": "Zone_Empty"
    },
    {
      "x": 0,
      "y": 0,
      "z": -2,
      "name": "Block_White"
    },
    {
      "x": 0,
      "y": 1,
      "z": -2,
      "name": "Block_White"
    },
    {
      "x": 0,
      "y": 2,
      "z": -2,
      "name": "Zone_Empty"
    },
    {
      "x": 0,
      "y": 3,
      "z": -2,
      "name": "Zone_Empty"
    },
    {
      "x": 0,
      "y": 4,
      "z": -2,
      "name": "Zone_Empty"
    },
    {
      "x": 0,
      "y": 5,
      "z": -2,
      "name": "Zone_Empty"
    },
    {
      "x": 0,
      "y": 6,
      "z": -2,
      "name": "Zone_Empty"
    },
    {
      "x": 0,
      "y": 7,
      "z": -2,
      "name": "Zone_Empty"
    },
    {
      "x": 0,
      "y": 8,
      "z": -2,
      "name": "Zone_Empty"
    },
    {
      "x": 0,
      "y": 0,
      "z": -1,
      "name": "Block_White"
    },
    {
      "x": 0,
      "y": 1,
      "z": -1,
      "name": "Block_White"
    },
    {
      "x": 0,
      "y": 2,
      "z": -1,
      "name": "Zone_Empty"
    },
    {
      "x": 0,
      "y": 3,
      "z": -1,
      "name": "Zone_Empty"
    },
    {
      "x": 0,
      "y": 4,
      "z": -1,
      "name": "Zone_Empty"
    },
    {
      "x": 0,
      "y": 5,
      "z": -1,
      "name": "Zone_Empty"
    },
    {
      "x": 0,
      "y": 6,
      "z": -1,
      "name": "Zone_Empty"
    },
    {
      "x": 0,
      "y": 7,
      "z": -1,
      "name": "Zone_Empty"
    },
    {
      "x": 0,
      "y": 8,
      "z": -1,
      "name": "Zone_Empty"
    },
    {
      "x": 0,
      "y": 0,
      "z": 0,
      "name": "Block_White"
    },
    {
      "x": 0,
      "y": 1,
      "z": 0,
      "name": "Extraction_Active"
    },
    {
      "x": 0,
      "y": 2,
      "z": 0,
      "name": "Zone_Empty"
    },
    {
      "x": 0,
      "y": 3,
      "z": 0,
      "name": "Zone_Empty"
    },
    {
      "x": 0,
      "y": 4,
      "z": 0,
      "name": "Zone_Empty"
    },
    {
      "x": 0,
      "y": 5,
      "z": 0,
      "name": "Zone_Empty"
    },
    {
      "x": 0,
      "y": 6,
      "z": 0,
      "name": "Zone_Empty"
    },
    {
      "x": 0,
      "y": 7,
      "z": 0,
      "name": "Zone_Empty"
    },
    {
      "x": 0,
      "y": 8,
      "z": 0,
      "name": "Zone_Empty"
    },
    {
      "x": 0,
      "y": 0,
      "z": 1,
      "name": "Block_White"
    },
    {
      "x": 0,
      "y": 1,
      "z": 1,
      "name": "Block_White"
    },
    {
      "x": 0,
      "y": 2,
      "z": 1,
      "name": "Zone_Empty"
    },
    {
      "x": 0,
      "y": 3,
      "z": 1,
      "name": "Zone_Empty"
    },
    {
      "x": 0,
      "y": 4,
      "z": 1,
      "name": "Zone_Empty"
    },
    {
      "x": 0,
      "y": 5,
      "z": 1,
      "name": "Zone_Empty"
    },
    {
      "x": 0,
      "y": 6,
      "z": 1,
      "name": "Zone_Empty"
    },
    {
      "x": 0,
      "y": 7,
      "z": 1,
      "name": "Zone_Empty"
    },
    {
      "x": 0,
      "y": 8,
      "z": 1,
      "name": "Zone_Empty"
    },
    {
      "x": 0,
      "y": 0,
      "z": 2,
      "name": "Block_White"
    },
    {
      "x": 0,
      "y": 1,
      "z": 2,
      "name": "Block_White"
    },
    {
      "x": 0,
      "y": 2,
      "z": 2,
      "name": "Zone_Empty"
    },
    {
      "x": 0,
      "y": 3,
      "z": 2,
      "name": "Zone_Empty"
    },
    {
      "x": 0,
      "y": 4,
      "z": 2,
      "name": "Zone_Empty"
    },
    {
      "x": 0,
      "y": 5,
      "z": 2,
      "name": "Zone_Empty"
    },
    {
      "x": 0,
      "y": 6,
      "z": 2,
      "name": "Zone_Empty"
    },
    {
      "x": 0,
      "y": 7,
      "z": 2,
      "name": "Zone_Empty"
    },
    {
      "x": 0,
      "y": 8,
      "z": 2,
      "name": "Zone_Empty"
    },
    {
      "x": 0,
      "y": 0,
      "z": 3,
      "name": "Block_White"
    },
    {
      "x": 0,
      "y": 1,
      "z": 3,
      "name": "Neon_Purple"
    },
    {
      "x": 0,
      "y": 2,
      "z": 3,
      "name": "Zone_Empty"
    },
    {
      "x": 0,
      "y": 3,
      "z": 3,
      "name": "Zone_Empty"
    },
    {
      "x": 0,
      "y": 4,
      "z": 3,
      "name": "Zone_Empty"
    },
    {
      "x": 0,
      "y": 5,
      "z": 3,
      "name": "Zone_Empty"
    },
    {
      "x": 0,
      "y": 6,
      "z": 3,
      "name": "Zone_Empty"
    },
    {
      "x": 0,
      "y": 7,
      "z": 3,
      "name": "Zone_Empty"
    },
    {
      "x": 0,
      "y": 8,
      "z": 3,
      "name": "Zone_Empty"
    },
    {
      "x": 0,
      "y": 0,
      "z": 4,
      "name": "Block_White"
    },
    {
      "x": 0,
      "y": 1,
      "z": 4,
      "name": "Stair_White"
    },
    {
      "x": 0,
      "y": 2,
      "z": 4,
      "name": "Zone_Empty"
    },
    {
      "x": 0,
      "y": 3,
      "z": 4,
      "name": "Zone_Empty"
    },
    {
      "x": 0,
      "y": 4,
      "z": 4,
      "name": "Zone_Empty"
    },
    {
      "x": 0,
      "y": 5,
      "z": 4,
      "name": "Zone_Empty"
    },
    {
      "x": 0,
      "y": 6,
      "z": 4,
      "name": "Zone_Empty"
    },
    {
      "x": 0,
      "y": 7,
      "z": 4,
      "name": "Zone_Empty"
    },
    {
      "x": 0,
      "y": 8,
      "z": 4,
      "name": "Zone_Empty"
    },
    {
      "x": 0,
      "y": 0,
      "z": 5,
      "name": "Stair_White"
    },
    {
      "x": 0,
      "y": 1,
      "z": 5,
      "name": "Zone_Empty"
    },
    {
      "x": 0,
      "y": 2,
      "z": 5,
      "name": "Zone_Empty"
    },
    {
      "x": 0,
      "y": 3,
      "z": 5,
      "name": "Zone_Empty"
    },
    {
      "x": 0,
      "y": 4,
      "z": 5,
      "name": "Zone_Empty"
    },
    {
      "x": 0,
      "y": 5,
      "z": 5,
      "name": "Zone_Empty"
    },
    {
      "x": 0,
      "y": 6,
      "z": 5,
      "name": "Zone_Empty"
    },
    {
      "x": 0,
      "y": 7,
      "z": 5,
      "name": "Zone_Empty"
    },
    {
      "x": 0,
      "y": 8,
      "z": 5,
      "name": "Zone_Empty"
    },
    {
      "x": 1,
      "y": 0,
      "z": -5,
      "name": "Stair_White",
      "rotation": 2
    },
    {
      "x": 1,
      "y": 1,
      "z": -5,
      "name": "Zone_Empty"
    },
    {
      "x": 1,
      "y": 2,
      "z": -5,
      "name": "Zone_Empty"
    },
    {
      "x": 1,
      "y": 3,
      "z": -5,
      "name": "Zone_Empty"
    },
    {
      "x": 1,
      "y": 4,
      "z": -5,
      "name": "Zone_Empty"
    },
    {
      "x": 1,
      "y": 5,
      "z": -5,
      "name": "Zone_Empty"
    },
    {
      "x": 1,
      "y": 6,
      "z": -5,
      "name": "Zone_Empty"
    },
    {
      "x": 1,
      "y": 7,
      "z": -5,
      "name": "Zone_Empty"
    },
    {
      "x": 1,
      "y": 8,
      "z": -5,
      "name": "Zone_Empty"
    },
    {
      "x": 1,
      "y": 0,
      "z": -4,
      "name": "Block_White"
    },
    {
      "x": 1,
      "y": 1,
      "z": -4,
      "name": "Stair_White",
      "rotation": 2
    },
    {
      "x": 1,
      "y": 2,
      "z": -4,
      "name": "Zone_Empty"
    },
    {
      "x": 1,
      "y": 3,
      "z": -4,
      "name": "Zone_Empty"
    },
    {
      "x": 1,
      "y": 4,
      "z": -4,
      "name": "Zone_Empty"
    },
    {
      "x": 1,
      "y": 5,
      "z": -4,
      "name": "Zone_Empty"
    },
    {
      "x": 1,
      "y": 6,
      "z": -4,
      "name": "Zone_Empty"
    },
    {
      "x": 1,
      "y": 7,
      "z": -4,
      "name": "Zone_Empty"
    },
    {
      "x": 1,
      "y": 8,
      "z": -4,
      "name": "Zone_Empty"
    },
    {
      "x": 1,
      "y": 0,
      "z": -3,
      "name": "Block_White"
    },
    {
      "x": 1,
      "y": 1,
      "z": -3,
      "name": "Block_White"
    },
    {
      "x": 1,
      "y": 2,
      "z": -3,
      "name": "Zone_Empty"
    },
    {
      "x": 1,
      "y": 3,
      "z": -3,
      "name": "Zone_Empty"
    },
    {
      "x": 1,
      "y": 4,
      "z": -3,
      "name": "Zone_Empty"
    },
    {
      "x": 1,
      "y": 5,
      "z": -3,
      "name": "Zone_Empty"
    },
    {
      "x": 1,
      "y": 6,
      "z": -3,
      "name": "Zone_Empty"
    },
    {
      "x": 1,
      "y": 7,
      "z": -3,
      "name": "Zone_Empty"
    },
    {
      "x": 1,
      "y": 8,
      "z": -3,
      "name": "Zone_Empty"
    },
    {
      "x": 1,
      "y": 0,
      "z": -2,
      "name": "Block_White"
    },
    {
      "x": 1,
      "y": 1,
      "z": -2,
      "name": "Block_White"
    },
    {
      "x": 1,
      "y": 2,
      "z": -2,
      "name": "Zone_Empty"
    },
    {
      "x": 1,
      "y": 3,
      "z": -2,
      "name": "Zone_Empty"
    },
    {
      "x": 1,
      "y": 4,
      "z": -2,
      "name": "Zone_Empty"
    },
    {
      "x": 1,
      "y": 5,
      "z": -2,
      "name": "Zone_Empty"
    },
    {
      "x": 1,
      "y": 6,
      "z": -2,
      "name": "Zone_Empty"
    },
    {
      "x": 1,
      "y": 7,
      "z": -2,
      "name": "Zone_Empty"
    },
    {
      "x": 1,
      "y": 8,
      "z": -2,
      "name": "Zone_Empty"
    },
    {
      "x": 1,
      "y": 0,
      "z": -1,
      "name": "Block_White"
    },
    {
      "x": 1,
      "y": 1,
      "z": -1,
      "name": "Block_White"
    },
    {
      "x": 1,
      "y": 2,
      "z": -1,
      "name": "Zone_Empty"
    },
    {
      "x": 1,
      "y": 3,
      "z": -1,
      "name": "Zone_Empty"
    },
    {
      "x": 1,
      "y": 4,
      "z": -1,
      "name": "Zone_Empty"
    },
    {
      "x": 1,
      "y": 5,
      "z": -1,
      "name": "Zone_Empty"
    },
    {
      "x": 1,
      "y": 6,
      "z": -1,
      "name": "Zone_Empty"
    },
    {
      "x": 1,
      "y": 7,
      "z": -1,
      "name": "Zone_Empty"
    },
    {
      "x": 1,
      "y": 8,
      "z": -1,
      "name": "Zone_Empty"
    },
    {
      "x": 1,
      "y": 0,
      "z": 0,
      "name": "Block_White"
    },
    {
      "x": 1,
      "y": 1,
      "z": 0,
      "name": "Block_White"
    },
    {
      "x": 1,
      "y": 2,
      "z": 0,
      "name": "Zone_Empty"
    },
    {
      "x": 1,
      "y": 3,
      "z": 0,
      "name": "Zone_Empty"
    },
    {
      "x": 1,
      "y": 4,
      "z": 0,
      "name": "Zone_Empty"
    },
    {
      "x": 1,
      "y": 5,
      "z": 0,
      "name": "Zone_Empty"
    },
    {
      "x": 1,
      "y": 6,
      "z": 0,
      "name": "Zone_Empty"
    },
    {
      "x": 1,
      "y": 7,
      "z": 0,
      "name": "Zone_Empty"
    },
    {
      "x": 1,
      "y": 8,
      "z": 0,
      "name": "Zone_Empty"
    },
    {
      "x": 1,
      "y": 0,
      "z": 1,
      "name": "Block_White"
    },
    {
      "x": 1,
      "y": 1,
      "z": 1,
      "name": "Block_White"
    },
    {
      "x": 1,
      "y": 2,
      "z": 1,
      "name": "Zone_Empty"
    },
    {
      "x": 1,
      "y": 3,
      "z": 1,
      "name": "Zone_Empty"
    },
    {
      "x": 1,
      "y": 4,
      "z": 1,
      "name": "Zone_Empty"
    },
    {
      "x": 1,
      "y": 5,
      "z": 1,
      "name": "Zone_Empty"
    },
    {
      "x": 1,
      "y": 6,
      "z": 1,
      "name": "Zone_Empty"
    },
    {
      "x": 1,
      "y": 7,
      "z": 1,
      "name": "Zone_Empty"
    },
    {
      "x": 1,
      "y": 8,
      "z": 1,
      "name": "Zone_Empty"
    },
    {
      "x": 1,
      "y": 0,
      "z": 2,
      "name": "Block_White"
    },
    {
      "x": 1,
      "y": 1,
      "z": 2,
      "name": "Block_White"
    },
    {
      "x": 1,
      "y": 2,
      "z": 2,
      "name": "Zone_Empty"
    },
    {
      "x": 1,
      "y": 3,
      "z": 2,
      "name": "Zone_Empty"
    },
    {
      "x": 1,
      "y": 4,
      "z": 2,
      "name": "Zone_Empty"
    },
    {
      "x": 1,
      "y": 5,
      "z": 2,
      "name": "Zone_Empty"
    },
    {
      "x": 1,
      "y": 6,
      "z": 2,
      "name": "Zone_Empty"
    },
    {
      "x": 1,
      "y": 7,
      "z": 2,
      "name": "Zone_Empty"
    },
    {
      "x": 1,
      "y": 8,
      "z": 2,
      "name": "Zone_Empty"
    },
    {
      "x": 1,
      "y": 0,
      "z": 3,
      "name": "Block_White"
    },
    {
      "x": 1,
      "y": 1,
      "z": 3,
      "name": "Block_White"
    },
    {
      "x": 1,
      "y": 2,
      "z": 3,
      "name": "Zone_Empty"
    },
    {
      "x": 1,
      "y": 3,
      "z": 3,
      "name": "Zone_Empty"
    },
    {
      "x": 1,
      "y": 4,
      "z": 3,
      "name": "Zone_Empty"
    },
    {
      "x": 1,
      "y": 5,
      "z": 3,
      "name": "Zone_Empty"
    },
    {
      "x": 1,
      "y": 6,
      "z": 3,
      "name": "Zone_Empty"
    },
    {
      "x": 1,
      "y": 7,
      "z": 3,
      "name": "Zone_Empty"
    },
    {
      "x": 1,
      "y": 8,
      "z": 3,
      "name": "Zone_Empty"
    },
    {
      "x": 1,
      "y": 0,
      "z": 4,
      "name": "Block_White"
    },
    {
      "x": 1,
      "y": 1,
      "z": 4,
      "name": "Stair_White"
    },
    {
      "x": 1,
      "y": 2,
      "z": 4,
      "name": "Zone_Empty"
    },
    {
      "x": 1,
      "y": 3,
      "z": 4,
      "name": "Zone_Empty"
    },
    {
      "x": 1,
      "y": 4,
      "z": 4,
      "name": "Zone_Empty"
    },
    {
      "x": 1,
      "y": 5,
      "z": 4,
      "name": "Zone_Empty"
    },
    {
      "x": 1,
      "y": 6,
      "z": 4,
      "name": "Zone_Empty"
    },
    {
      "x": 1,
      "y": 7,
      "z": 4,
      "name": "Zone_Empty"
    },
    {
      "x": 1,
      "y": 8,
      "z": 4,
      "name": "Zone_Empty"
    },
    {
      "x": 1,
      "y": 0,
      "z": 5,
      "name": "Stair_White"
    },
    {
      "x": 1,
      "y": 1,
      "z": 5,
      "name": "Zone_Empty"
    },
    {
      "x": 1,
      "y": 2,
      "z": 5,
      "name": "Zone_Empty"
    },
    {
      "x": 1,
      "y": 3,
      "z": 5,
      "name": "Zone_Empty"
    },
    {
      "x": 1,
      "y": 4,
      "z": 5,
      "name": "Zone_Empty"
    },
    {
      "x": 1,
      "y": 5,
      "z": 5,
      "name": "Zone_Empty"
    },
    {
      "x": 1,
      "y": 6,
      "z": 5,
      "name": "Zone_Empty"
    },
    {
      "x": 1,
      "y": 7,
      "z": 5,
      "name": "Zone_Empty"
    },
    {
      "x": 1,
      "y": 8,
      "z": 5,
      "name": "Zone_Empty"
    },
    {
      "x": 2,
      "y": 0,
      "z": -5,
      "name": "Stair_White",
      "rotation": 2
    },
    {
      "x": 2,
      "y": 1,
      "z": -5,
      "name": "Zone_Empty"
    },
    {
      "x": 2,
      "y": 2,
      "z": -5,
      "name": "Zone_Empty"
    },
    {
      "x": 2,
      "y": 3,
      "z": -5,
      "name": "Zone_Empty"
    },
    {
      "x": 2,
      "y": 4,
      "z": -5,
      "name": "Zone_Empty"
    },
    {
      "x": 2,
      "y": 5,
      "z": -5,
      "name": "Zone_Empty"
    },
    {
      "x": 2,
      "y": 6,
      "z": -5,
      "name": "Zone_Empty"
    },
    {
      "x": 2,
      "y": 7,
      "z": -5,
      "name": "Zone_Empty"
    },
    {
      "x": 2,
      "y": 8,
      "z": -5,
      "name": "Zone_Empty"
    },
    {
      "x": 2,
      "y": 0,
      "z": -4,
      "name": "Block_White"
    },
    {
      "x": 2,
      "y": 1,
      "z": -4,
      "name": "Stair_White",
      "rotation": 2
    },
    {
      "x": 2,
      "y": 2,
      "z": -4,
      "name": "Zone_Empty"
    },
    {
      "x": 2,
      "y": 3,
      "z": -4,
      "name": "Zone_Empty"
    },
    {
      "x": 2,
      "y": 4,
      "z": -4,
      "name": "Zone_Empty"
    },
    {
      "x": 2,
      "y": 5,
      "z": -4,
      "name": "Zone_Empty"
    },
    {
      "x": 2,
      "y": 6,
      "z": -4,
      "name": "Zone_Empty"
    },
    {
      "x": 2,
      "y": 7,
      "z": -4,
      "name": "Zone_Empty"
    },
    {
      "x": 2,
      "y": 8,
      "z": -4,
      "name": "Zone_Empty"
    },
    {
      "x": 2,
      "y": 0,
      "z": -3,
      "name": "Block_White"
    },
    {
      "x": 2,
      "y": 1,
      "z": -3,
      "name": "Block_White"
    },
    {
      "x": 2,
      "y": 2,
      "z": -3,
      "name": "Zone_Empty"
    },
    {
      "x": 2,
      "y": 3,
      "z": -3,
      "name": "Zone_Empty"
    },
    {
      "x": 2,
      "y": 4,
      "z": -3,
      "name": "Zone_Empty"
    },
    {
      "x": 2,
      "y": 5,
      "z": -3,
      "name": "Zone_Empty"
    },
    {
      "x": 2,
      "y": 6,
      "z": -3,
      "name": "Zone_Empty"
    },
    {
      "x": 2,
      "y": 7,
      "z": -3,
      "name": "Zone_Empty"
    },
    {
      "x": 2,
      "y": 8,
      "z": -3,
      "name": "Zone_Empty"
    },
    {
      "x": 2,
      "y": 0,
      "z": -2,
      "name": "Block_White"
    },
    {
      "x": 2,
      "y": 1,
      "z": -2,
      "name": "Neon_Green"
    },
    {
      "x": 2,
      "y": 2,
      "z": -2,
      "name": "Zone_Empty"
    },
    {
      "x": 2,
      "y": 3,
      "z": -2,
      "name": "Zone_Empty"
    },
    {
      "x": 2,
      "y": 4,
      "z": -2,
      "name": "Zone_Empty"
    },
    {
      "x": 2,
      "y": 5,
      "z": -2,
      "name": "Zone_Empty"
    },
    {
      "x": 2,
      "y": 6,
      "z": -2,
      "name": "Zone_Empty"
    },
    {
      "x": 2,
      "y": 7,
      "z": -2,
      "name": "Zone_Empty"
    },
    {
      "x": 2,
      "y": 8,
      "z": -2,
      "name": "Zone_Empty"
    },
    {
      "x": 2,
      "y": 0,
      "z": -1,
      "name": "Block_White"
    },
    {
      "x": 2,
      "y": 1,
      "z": -1,
      "name": "Block_White"
    },
    {
      "x": 2,
      "y": 2,
      "z": -1,
      "name": "Zone_Empty"
    },
    {
      "x": 2,
      "y": 3,
      "z": -1,
      "name": "Zone_Empty"
    },
    {
      "x": 2,
      "y": 4,
      "z": -1,
      "name": "Zone_Empty"
    },
    {
      "x": 2,
      "y": 5,
      "z": -1,
      "name": "Zone_Empty"
    },
    {
      "x": 2,
      "y": 6,
      "z": -1,
      "name": "Zone_Empty"
    },
    {
      "x": 2,
      "y": 7,
      "z": -1,
      "name": "Zone_Empty"
    },
    {
      "x": 2,
      "y": 8,
      "z": -1,
      "name": "Zone_Empty"
    },
    {
      "x": 2,
      "y": 0,
      "z": 0,
      "name": "Block_White"
    },
    {
      "x": 2,
      "y": 1,
      "z": 0,
      "name": "Block_White"
    },
    {
      "x": 2,
      "y": 2,
      "z": 0,
      "name": "Zone_Empty"
    },
    {
      "x": 2,
      "y": 3,
      "z": 0,
      "name": "Zone_Empty"
    },
    {
      "x": 2,
      "y": 4,
      "z": 0,
      "name": "Zone_Empty"
    },
    {
      "x": 2,
      "y": 5,
      "z": 0,
      "name": "Zone_Empty"
    },
    {
      "x": 2,
      "y": 6,
      "z": 0,
      "name": "Zone_Empty"
    },
    {
      "x": 2,
      "y": 7,
      "z": 0,
      "name": "Zone_Empty"
    },
    {
      "x": 2,
      "y": 8,
      "z": 0,
      "name": "Zone_Empty"
    },
    {
      "x": 2,
      "y": 0,
      "z": 1,
      "name": "Block_White"
    },
    {
      "x": 2,
      "y": 1,
      "z": 1,
      "name": "Block_White"
    },
    {
      "x": 2,
      "y": 2,
      "z": 1,
      "name": "Zone_Empty"
    },
    {
      "x": 2,
      "y": 3,
      "z": 1,
      "name": "Zone_Empty"
    },
    {
      "x": 2,
      "y": 4,
      "z": 1,
      "name": "Zone_Empty"
    },
    {
      "x": 2,
      "y": 5,
      "z": 1,
      "name": "Zone_Empty"
    },
    {
      "x": 2,
      "y": 6,
      "z": 1,
      "name": "Zone_Empty"
    },
    {
      "x": 2,
      "y": 7,
      "z": 1,
      "name": "Zone_Empty"
    },
    {
      "x": 2,
      "y": 8,
      "z": 1,
      "name": "Zone_Empty"
    },
    {
      "x": 2,
      "y": 0,
      "z": 2,
      "name": "Block_White"
    },
    {
      "x": 2,
      "y": 1,
      "z": 2,
      "name": "Neon_Blue"
    },
    {
      "x": 2,
      "y": 2,
      "z": 2,
      "name": "Zone_Empty"
    },
    {
      "x": 2,
      "y": 3,
      "z": 2,
      "name": "Zone_Empty"
    },
    {
      "x": 2,
      "y": 4,
      "z": 2,
      "name": "Zone_Empty"
    },
    {
      "x": 2,
      "y": 5,
      "z": 2,
      "name": "Zone_Empty"
    },
    {
      "x": 2,
      "y": 6,
      "z": 2,
      "name": "Zone_Empty"
    },
    {
      "x": 2,
      "y": 7,
      "z": 2,
      "name": "Zone_Empty"
    },
    {
      "x": 2,
      "y": 8,
      "z": 2,
      "name": "Zone_Empty"
    },
    {
      "x": 2,
      "y": 0,
      "z": 3,
      "name": "Block_White"
    },
    {
      "x": 2,
      "y": 1,
      "z": 3,
      "name": "Block_White"
    },
    {
      "x": 2,
      "y": 2,
      "z": 3,
      "name": "Zone_Empty"
    },
    {
      "x": 2,
      "y": 3,
      "z": 3,
      "name": "Zone_Empty"
    },
    {
      "x": 2,
      "y": 4,
      "z": 3,
      "name": "Zone_Empty"
    },
    {
      "x": 2,
      "y": 5,
      "z": 3,
      "name": "Zone_Empty"
    },
    {
      "x": 2,
      "y": 6,
      "z": 3,
      "name": "Zone_Empty"
    },
    {
      "x": 2,
      "y": 7,
      "z": 3,
      "name": "Zone_Empty"
    },
    {
      "x": 2,
      "y": 8,
      "z": 3,
      "name": "Zone_Empty"
    },
    {
      "x": 2,
      "y": 0,
      "z": 4,
      "name": "Block_White"
    },
    {
      "x": 2,
      "y": 1,
      "z": 4,
      "name": "Stair_White"
    },
    {
      "x": 2,
      "y": 2,
      "z": 4,
      "name": "Zone_Empty"
    },
    {
      "x": 2,
      "y": 3,
      "z": 4,
      "name": "Zone_Empty"
    },
    {
      "x": 2,
      "y": 4,
      "z": 4,
      "name": "Zone_Empty"
    },
    {
      "x": 2,
      "y": 5,
      "z": 4,
      "name": "Zone_Empty"
    },
    {
      "x": 2,
      "y": 6,
      "z": 4,
      "name": "Zone_Empty"
    },
    {
      "x": 2,
      "y": 7,
      "z": 4,
      "name": "Zone_Empty"
    },
    {
      "x": 2,
      "y": 8,
      "z": 4,
      "name": "Zone_Empty"
    },
    {
      "x": 2,
      "y": 0,
      "z": 5,
      "name": "Stair_White"
    },
    {
      "x": 2,
      "y": 1,
      "z": 5,
      "name": "Zone_Empty"
    },
    {
      "x": 2,
      "y": 2,
      "z": 5,
      "name": "Zone_Empty"
    },
    {
      "x": 2,
      "y": 3,
      "z": 5,
      "name": "Zone_Empty"
    },
    {
      "x": 2,
      "y": 4,
      "z": 5,
      "name": "Zone_Empty"
    },
    {
      "x": 2,
      "y": 5,
      "z": 5,
      "name": "Zone_Empty"
    },
    {
      "x": 2,
      "y": 6,
      "z": 5,
      "name": "Zone_Empty"
    },
    {
      "x": 2,
      "y": 7,
      "z": 5,
      "name": "Zone_Empty"
    },
    {
      "x": 2,
      "y": 8,
      "z": 5,
      "name": "Zone_Empty"
    },
    {
      "x": 3,
      "y": 0,
      "z": -5,
      "name": "Block_White"
    },
    {
      "x": 3,
      "y": 1,
      "z": -5,
      "name": "Stair_White",
      "rotation": 2
    },
    {
      "x": 3,
      "y": 2,
      "z": -5,
      "name": "Zone_Empty"
    },
    {
      "x": 3,
      "y": 3,
      "z": -5,
      "name": "Zone_Empty"
    },
    {
      "x": 3,
      "y": 4,
      "z": -5,
      "name": "Zone_Empty"
    },
    {
      "x": 3,
      "y": 5,
      "z": -5,
      "name": "Zone_Empty"
    },
    {
      "x": 3,
      "y": 6,
      "z": -5,
      "name": "Zone_Empty"
    },
    {
      "x": 3,
      "y": 7,
      "z": -5,
      "name": "Zone_Empty"
    },
    {
      "x": 3,
      "y": 8,
      "z": -5,
      "name": "Zone_Empty"
    },
    {
      "x": 3,
      "y": 0,
      "z": -4,
      "name": "Block_White"
    },
    {
      "x": 3,
      "y": 1,
      "z": -4,
      "name": "Block_White"
    },
    {
      "x": 3,
      "y": 2,
      "z": -4,
      "name": "Zone_Empty"
    },
    {
      "x": 3,
      "y": 3,
      "z": -4,
      "name": "Zone_Empty"
    },
    {
      "x": 3,
      "y": 4,
      "z": -4,
      "name": "Zone_Empty"
    },
    {
      "x": 3,
      "y": 5,
      "z": -4,
      "name": "Zone_Empty"
    },
    {
      "x": 3,
      "y": 6,
      "z": -4,
      "name": "Zone_Empty"
    },
    {
      "x": 3,
      "y": 7,
      "z": -4,
      "name": "Zone_Empty"
    },
    {
      "x": 3,
      "y": 8,
      "z": -4,
      "name": "Zone_Empty"
    },
    {
      "x": 3,
      "y": 0,
      "z": -3,
      "name": "Block_White"
    },
    {
      "x": 3,
      "y": 1,
      "z": -3,
      "name": "Block_White"
    },
    {
      "x": 3,
      "y": 2,
      "z": -3,
      "name": "Zone_Empty"
    },
    {
      "x": 3,
      "y": 3,
      "z": -3,
      "name": "Zone_Empty"
    },
    {
      "x": 3,
      "y": 4,
      "z": -3,
      "name": "Zone_Empty"
    },
    {
      "x": 3,
      "y": 5,
      "z": -3,
      "name": "Zone_Empty"
    },
    {
      "x": 3,
      "y": 6,
      "z": -3,
      "name": "Zone_Empty"
    },
    {
      "x": 3,
      "y": 7,
      "z": -3,
      "name": "Zone_Empty"
    },
    {
      "x": 3,
      "y": 8,
      "z": -3,
      "name": "Zone_Empty"
    },
    {
      "x": 3,
      "y": 0,
      "z": -2,
      "name": "Block_White"
    },
    {
      "x": 3,
      "y": 1,
      "z": -2,
      "name": "Block_White"
    },
    {
      "x": 3,
      "y": 2,
      "z": -2,
      "name": "Zone_Empty"
    },
    {
      "x": 3,
      "y": 3,
      "z": -2,
      "name": "Zone_Empty"
    },
    {
      "x": 3,
      "y": 4,
      "z": -2,
      "name": "Zone_Empty"
    },
    {
      "x": 3,
      "y": 5,
      "z": -2,
      "name": "Zone_Empty"
    },
    {
      "x": 3,
      "y": 6,
      "z": -2,
      "name": "Zone_Empty"
    },
    {
      "x": 3,
      "y": 7,
      "z": -2,
      "name": "Zone_Empty"
    },
    {
      "x": 3,
      "y": 8,
      "z": -2,
      "name": "Zone_Empty"
    },
    {
      "x": 3,
      "y": 0,
      "z": -1,
      "name": "Block_White"
    },
    {
      "x": 3,
      "y": 1,
      "z": -1,
      "name": "Block_White"
    },
    {
      "x": 3,
      "y": 2,
      "z": -1,
      "name": "Zone_Empty"
    },
    {
      "x": 3,
      "y": 3,
      "z": -1,
      "name": "Zone_Empty"
    },
    {
      "x": 3,
      "y": 4,
      "z": -1,
      "name": "Zone_Empty"
    },
    {
      "x": 3,
      "y": 5,
      "z": -1,
      "name": "Zone_Empty"
    },
    {
      "x": 3,
      "y": 6,
      "z": -1,
      "name": "Zone_Empty"
    },
    {
      "x": 3,
      "y": 7,
      "z": -1,
      "name": "Zone_Empty"
    },
    {
      "x": 3,
      "y": 8,
      "z": -1,
      "name": "Zone_Empty"
    },
    {
      "x": 3,
      "y": 0,
      "z": 0,
      "name": "Block_White"
    },
    {
      "x": 3,
      "y": 1,
      "z": 0,
      "name": "Neon_Cyan"
    },
    {
      "x": 3,
      "y": 2,
      "z": 0,
      "name": "Zone_Empty"
    },
    {
      "x": 3,
      "y": 3,
      "z": 0,
      "name": "Zone_Empty"
    },
    {
      "x": 3,
      "y": 4,
      "z": 0,
      "name": "Zone_Empty"
    },
    {
      "x": 3,
      "y": 5,
      "z": 0,
      "name": "Zone_Empty"
    },
    {
      "x": 3,
      "y": 6,
      "z": 0,
      "name": "Zone_Empty"
    },
    {
      "x": 3,
      "y": 7,
      "z": 0,
      "name": "Zone_Empty"
    },
    {
      "x": 3,
      "y": 8,
      "z": 0,
      "name": "Zone_Empty"
    },
    {
      "x": 3,
      "y": 0,
      "z": 1,
      "name": "Block_White"
    },
    {
      "x": 3,
      "y": 1,
      "z": 1,
      "name": "Block_White"
    },
    {
      "x": 3,
      "y": 2,
      "z": 1,
      "name": "Zone_Empty"
    },
    {
      "x": 3,
      "y": 3,
      "z": 1,
      "name": "Zone_Empty"
    },
    {
      "x": 3,
      "y": 4,
      "z": 1,
      "name": "Zone_Empty"
    },
    {
      "x": 3,
      "y": 5,
      "z": 1,
      "name": "Zone_Empty"
    },
    {
      "x": 3,
      "y": 6,
      "z": 1,
      "name": "Zone_Empty"
    },
    {
      "x": 3,
      "y": 7,
      "z": 1,
      "name": "Zone_Empty"
    },
    {
      "x": 3,
      "y": 8,
      "z": 1,
      "name": "Zone_Empty"
    },
    {
      "x": 3,
      "y": 0,
      "z": 2,
      "name": "Block_White"
    },
    {
      "x": 3,
      "y": 1,
      "z": 2,
      "name": "Block_White"
    },
    {
      "x": 3,
      "y": 2,
      "z": 2,
      "name": "Zone_Empty"
    },
    {
      "x": 3,
      "y": 3,
      "z": 2,
      "name": "Zone_Empty"
    },
    {
      "x": 3,
      "y": 4,
      "z": 2,
      "name": "Zone_Empty"
    },
    {
      "x": 3,
      "y": 5,
      "z": 2,
      "name": "Zone_Empty"
    },
    {
      "x": 3,
      "y": 6,
      "z": 2,
      "name": "Zone_Empty"
    },
    {
      "x": 3,
      "y": 7,
      "z": 2,
      "name": "Zone_Empty"
    },
    {
      "x": 3,
      "y": 8,
      "z": 2,
      "name": "Zone_Empty"
    },
    {
      "x": 3,
      "y": 0,
      "z": 3,
      "name": "Block_White"
    },
    {
      "x": 3,
      "y": 1,
      "z": 3,
      "name": "Block_White"
    },
    {
      "x": 3,
      "y": 2,
      "z": 3,
      "name": "Zone_Empty"
    },
    {
      "x": 3,
      "y": 3,
      "z": 3,
      "name": "Zone_Empty"
    },
    {
      "x": 3,
      "y": 4,
      "z": 3,
      "name": "Zone_Empty"
    },
    {
      "x": 3,
      "y": 5,
      "z": 3,
      "name": "Zone_Empty"
    },
    {
      "x": 3,
      "y": 6,
      "z": 3,
      "name": "Zone_Empty"
    },
    {
      "x": 3,
      "y": 7,
      "z": 3,
      "name": "Zone_Empty"
    },
    {
      "x": 3,
      "y": 8,
      "z": 3,
      "name": "Zone_Empty"
    },
    {
      "x": 3,
      "y": 0,
      "z": 4,
      "name": "Block_White"
    },
    {
      "x": 3,
      "y": 1,
      "z": 4,
      "name": "Block_White"
    },
    {
      "x": 3,
      "y": 2,
      "z": 4,
      "name": "Zone_Empty"
    },
    {
      "x": 3,
      "y": 3,
      "z": 4,
      "name": "Zone_Empty"
    },
    {
      "x": 3,
      "y": 4,
      "z": 4,
      "name": "Zone_Empty"
    },
    {
      "x": 3,
      "y": 5,
      "z": 4,
      "name": "Zone_Empty"
    },
    {
      "x": 3,
      "y": 6,
      "z": 4,
      "name": "Zone_Empty"
    },
    {
      "x": 3,
      "y": 7,
      "z": 4,
      "name": "Zone_Empty"
    },
    {
      "x": 3,
      "y": 8,
      "z": 4,
      "name": "Zone_Empty"
    },
    {
      "x": 3,
      "y": 0,
      "z": 5,
      "name": "Block_White"
    },
    {
      "x": 3,
      "y": 1,
      "z": 5,
      "name": "Stair_White"
    },
    {
      "x": 3,
      "y": 2,
      "z": 5,
      "name": "Zone_Empty"
    },
    {
      "x": 3,
      "y": 3,
      "z": 5,
      "name": "Zone_Empty"
    },
    {
      "x": 3,
      "y": 4,
      "z": 5,
      "name": "Zone_Empty"
    },
    {
      "x": 3,
      "y": 5,
      "z": 5,
      "name": "Zone_Empty"
    },
    {
      "x": 3,
      "y": 6,
      "z": 5,
      "name": "Zone_Empty"
    },
    {
      "x": 3,
      "y": 7,
      "z": 5,
      "name": "Zone_Empty"
    },
    {
      "x": 3,
      "y": 8,
      "z": 5,
      "name": "Zone_Empty"
    },
    {
      "x": 4,
      "y": 0,
      "z": -3,
      "name": "Block_White"
    },
    {
      "x": 4,
      "y": 1,
      "z": -3,
      "name": "Block_White"
    },
    {
      "x": 4,
      "y": 2,
      "z": -3,
      "name": "Zone_Empty"
    },
    {
      "x": 4,
      "y": 3,
      "z": -3,
      "name": "Zone_Empty"
    },
    {
      "x": 4,
      "y": 4,
      "z": -3,
      "name": "Zone_Empty"
    },
    {
      "x": 4,
      "y": 5,
      "z": -3,
      "name": "Zone_Empty"
    },
    {
      "x": 4,
      "y": 6,
      "z": -3,
      "name": "Zone_Empty"
    },
    {
      "x": 4,
      "y": 7,
      "z": -3,
      "name": "Zone_Empty"
    },
    {
      "x": 4,
      "y": 8,
      "z": -3,
      "name": "Zone_Empty"
    },
    {
      "x": 4,
      "y": 0,
      "z": -2,
      "name": "Block_White"
    },
    {
      "x": 4,
      "y": 1,
      "z": -2,
      "name": "Stair_White",
      "rotation": 1
    },
    {
      "x": 4,
      "y": 2,
      "z": -2,
      "name": "Zone_Empty"
    },
    {
      "x": 4,
      "y": 3,
      "z": -2,
      "name": "Zone_Empty"
    },
    {
      "x": 4,
      "y": 4,
      "z": -2,
      "name": "Zone_Empty"
    },
    {
      "x": 4,
      "y": 5,
      "z": -2,
      "name": "Zone_Empty"
    },
    {
      "x": 4,
      "y": 6,
      "z": -2,
      "name": "Zone_Empty"
    },
    {
      "x": 4,
      "y": 7,
      "z": -2,
      "name": "Zone_Empty"
    },
    {
      "x": 4,
      "y": 8,
      "z": -2,
      "name": "Zone_Empty"
    },
    {
      "x": 4,
      "y": 0,
      "z": -1,
      "name": "Block_White"
    },
    {
      "x": 4,
      "y": 1,
      "z": -1,
      "name": "Stair_White",
      "rotation": 1
    },
    {
      "x": 4,
      "y": 2,
      "z": -1,
      "name": "Zone_Empty"
    },
    {
      "x": 4,
      "y": 3,
      "z": -1,
      "name": "Zone_Empty"
    },
    {
      "x": 4,
      "y": 4,
      "z": -1,
      "name": "Zone_Empty"
    },
    {
      "x": 4,
      "y": 5,
      "z": -1,
      "name": "Zone_Empty"
    },
    {
      "x": 4,
      "y": 6,
      "z": -1,
      "name": "Zone_Empty"
    },
    {
      "x": 4,
      "y": 7,
      "z": -1,
      "name": "Zone_Empty"
    },
    {
      "x": 4,
      "y": 8,
      "z": -1,
      "name": "Zone_Empty"
    },
    {
      "x": 4,
      "y": 0,
      "z": 0,
      "name": "Block_White"
    },
    {
      "x": 4,
      "y": 1,
      "z": 0,
      "name": "Stair_White",
      "rotation": 1
    },
    {
      "x": 4,
      "y": 2,
      "z": 0,
      "name": "Zone_Empty"
    },
    {
      "x": 4,
      "y": 3,
      "z": 0,
      "name": "Zone_Empty"
    },
    {
      "x": 4,
      "y": 4,
      "z": 0,
      "name": "Zone_Empty"
    },
    {
      "x": 4,
      "y": 5,
      "z": 0,
      "name": "Zone_Empty"
    },
    {
      "x": 4,
      "y": 6,
      "z": 0,
      "name": "Zone_Empty"
    },
    {
      "x": 4,
      "y": 7,
      "z": 0,
      "name": "Zone_Empty"
    },
    {
      "x": 4,
      "y": 8,
      "z": 0,
      "name": "Zone_Empty"
    },
    {
      "x": 4,
      "y": 0,
      "z": 1,
      "name": "Block_White"
    },
    {
      "x": 4,
      "y": 1,
      "z": 1,
      "name": "Stair_White",
      "rotation": 1
    },
    {
      "x": 4,
      "y": 2,
      "z": 1,
      "name": "Zone_Empty"
    },
    {
      "x": 4,
      "y": 3,
      "z": 1,
      "name": "Zone_Empty"
    },
    {
      "x": 4,
      "y": 4,
      "z": 1,
      "name": "Zone_Empty"
    },
    {
      "x": 4,
      "y": 5,
      "z": 1,
      "name": "Zone_Empty"
    },
    {
      "x": 4,
      "y": 6,
      "z": 1,
      "name": "Zone_Empty"
    },
    {
      "x": 4,
      "y": 7,
      "z": 1,
      "name": "Zone_Empty"
    },
    {
      "x": 4,
      "y": 8,
      "z": 1,
      "name": "Zone_Empty"
    },
    {
      "x": 4,
      "y": 0,
      "z": 2,
      "name": "Block_White"
    },
    {
      "x": 4,
      "y": 1,
      "z": 2,
      "name": "Stair_White",
      "rotation": 1
    },
    {
      "x": 4,
      "y": 2,
      "z": 2,
      "name": "Zone_Empty"
    },
    {
      "x": 4,
      "y": 3,
      "z": 2,
      "name": "Zone_Empty"
    },
    {
      "x": 4,
      "y": 4,
      "z": 2,
      "name": "Zone_Empty"
    },
    {
      "x": 4,
      "y": 5,
      "z": 2,
      "name": "Zone_Empty"
    },
    {
      "x": 4,
      "y": 6,
      "z": 2,
      "name": "Zone_Empty"
    },
    {
      "x": 4,
      "y": 7,
      "z": 2,
      "name": "Zone_Empty"
    },
    {
      "x": 4,
      "y": 8,
      "z": 2,
      "name": "Zone_Empty"
    },
    {
      "x": 4,
      "y": 0,
      "z": 3,
      "name": "Block_White"
    },
    {
      "x": 4,
      "y": 1,
      "z": 3,
      "name": "Block_White"
    },
    {
      "x": 4,
      "y": 2,
      "z": 3,
      "name": "Zone_Empty"
    },
    {
      "x": 4,
      "y": 3,
      "z": 3,
      "name": "Zone_Empty"
    },
    {
      "x": 4,
      "y": 4,
      "z": 3,
      "name": "Zone_Empty"
    },
    {
      "x": 4,
      "y": 5,
      "z": 3,
      "name": "Zone_Empty"
    },
    {
      "x": 4,
      "y": 6,
      "z": 3,
      "name": "Zone_Empty"
    },
    {
      "x": 4,
      "y": 7,
      "z": 3,
      "name": "Zone_Empty"
    },
    {
      "x": 4,
      "y": 8,
      "z": 3,
      "name": "Zone_Empty"
    },
    {
      "x": 5,
      "y": 0,
      "z": -3,
      "name": "Block_White"
    },
    {
      "x": 5,
      "y": 1,
      "z": -3,
      "name": "Stair_White",
      "rotation": 1
    },
    {
      "x": 5,
      "y": 2,
      "z": -3,
      "name": "Zone_Empty"
    },
    {
      "x": 5,
      "y": 3,
      "z": -3,
      "name": "Zone_Empty"
    },
    {
      "x": 5,
      "y": 4,
      "z": -3,
      "name": "Zone_Empty"
    },
    {
      "x": 5,
      "y": 5,
      "z": -3,
      "name": "Zone_Empty"
    },
    {
      "x": 5,
      "y": 6,
      "z": -3,
      "name": "Zone_Empty"
    },
    {
      "x": 5,
      "y": 7,
      "z": -3,
      "name": "Zone_Empty"
    },
    {
      "x": 5,
      "y": 8,
      "z": -3,
      "name": "Zone_Empty"
    },
    {
      "x": 5,
      "y": 0,
      "z": -2,
      "name": "Stair_White",
      "rotation": 1
    },
    {
      "x": 5,
      "y": 1,
      "z": -2,
      "name": "Zone_Empty"
    },
    {
      "x": 5,
      "y": 2,
      "z": -2,
      "name": "Zone_Empty"
    },
    {
      "x": 5,
      "y": 3,
      "z": -2,
      "name": "Zone_Empty"
    },
    {
      "x": 5,
      "y": 4,
      "z": -2,
      "name": "Zone_Empty"
    },
    {
      "x": 5,
      "y": 5,
      "z": -2,
      "name": "Zone_Empty"
    },
    {
      "x": 5,
      "y": 6,
      "z": -2,
      "name": "Zone_Empty"
    },
    {
      "x": 5,
      "y": 7,
      "z": -2,
      "name": "Zone_Empty"
    },
    {
      "x": 5,
      "y": 8,
      "z": -2,
      "name": "Zone_Empty"
    },
    {
      "x": 5,
      "y": 0,
      "z": -1,
      "name": "Stair_White",
      "rotation": 1
    },
    {
      "x": 5,
      "y": 1,
      "z": -1,
      "name": "Zone_Empty"
    },
    {
      "x": 5,
      "y": 2,
      "z": -1,
      "name": "Zone_Empty"
    },
    {
      "x": 5,
      "y": 3,
      "z": -1,
      "name": "Zone_Empty"
    },
    {
      "x": 5,
      "y": 4,
      "z": -1,
      "name": "Zone_Empty"
    },
    {
      "x": 5,
      "y": 5,
      "z": -1,
      "name": "Zone_Empty"
    },
    {
      "x": 5,
      "y": 6,
      "z": -1,
      "name": "Zone_Empty"
    },
    {
      "x": 5,
      "y": 7,
      "z": -1,
      "name": "Zone_Empty"
    },
    {
      "x": 5,
      "y": 8,
      "z": -1,
      "name": "Zone_Empty"
    },
    {
      "x": 5,
      "y": 0,
      "z": 0,
      "name": "Stair_White",
      "rotation": 1
    },
    {
      "x": 5,
      "y": 1,
      "z": 0,
      "name": "Zone_Empty"
    },
    {
      "x": 5,
      "y": 2,
      "z": 0,
      "name": "Zone_Empty"
    },
    {
      "x": 5,
      "y": 3,
      "z": 0,
      "name": "Zone_Empty"
    },
    {
      "x": 5,
      "y": 4,
      "z": 0,
      "name": "Zone_Empty"
    },
    {
      "x": 5,
      "y": 5,
      "z": 0,
      "name": "Zone_Empty"
    },
    {
      "x": 5,
      "y": 6,
      "z": 0,
      "name": "Zone_Empty"
    },
    {
      "x": 5,
      "y": 7,
      "z": 0,
      "name": "Zone_Empty"
    },
    {
      "x": 5,
      "y": 8,
      "z": 0,
      "name": "Zone_Empty"
    },
    {
      "x": 5,
      "y": 0,
      "z": 1,
      "name": "Stair_White",
      "rotation": 1
    },
    {
      "x": 5,
      "y": 1,
      "z": 1,
      "name": "Zone_Empty"
    },
    {
      "x": 5,
      "y": 2,
      "z": 1,
      "name": "Zone_Empty"
    },
    {
      "x": 5,
      "y": 3,
      "z": 1,
      "name": "Zone_Empty"
    },
    {
      "x": 5,
      "y": 4,
      "z": 1,
      "name": "Zone_Empty"
    },
    {
      "x": 5,
      "y": 5,
      "z": 1,
      "name": "Zone_Empty"
    },
    {
      "x": 5,
      "y": 6,
      "z": 1,
      "name": "Zone_Empty"
    },
    {
      "x": 5,
      "y": 7,
      "z": 1,
      "name": "Zone_Empty"
    },
    {
      "x": 5,
      "y": 8,
      "z": 1,
      "name": "Zone_Empty"
    },
    {
      "x": 5,
      "y": 0,
      "z": 2,
      "name": "Stair_White",
      "rotation": 1
    },
    {
      "x": 5,
      "y": 1,
      "z": 2,
      "name": "Zone_Empty"
    },
    {
      "x": 5,
      "y": 2,
      "z": 2,
      "name": "Zone_Empty"
    },
    {
      "x": 5,
      "y": 3,
      "z": 2,
      "name": "Zone_Empty"
    },
    {
      "x": 5,
      "y": 4,
      "z": 2,
      "name": "Zone_Empty"
    },
    {
      "x": 5,
      "y": 5,
      "z": 2,
      "name": "Zone_Empty"
    },
    {
      "x": 5,
      "y": 6,
      "z": 2,
      "name": "Zone_Empty"
    },
    {
      "x": 5,
      "y": 7,
      "z": 2,
      "name": "Zone_Empty"
    },
    {
      "x": 5,
      "y": 8,
      "z": 2,
      "name": "Zone_Empty"
    },
    {
      "x": 5,
      "y": 0,
      "z": 3,
      "name": "Block_White"
    },
    {
      "x": 5,
      "y": 1,
      "z": 3,
      "name": "Stair_White",
      "rotation": 1
    },
    {
      "x": 5,
      "y": 2,
      "z": 3,
      "name": "Zone_Empty"
    },
    {
      "x": 5,
      "y": 3,
      "z": 3,
      "name": "Zone_Empty"
    },
    {
      "x": 5,
      "y": 4,
      "z": 3,
      "name": "Zone_Empty"
    },
    {
      "x": 5,
      "y": 5,
      "z": 3,
      "name": "Zone_Empty"
    },
    {
      "x": 5,
      "y": 6,
      "z": 3,
      "name": "Zone_Empty"
    },
    {
      "x": 5,
      "y": 7,
      "z": 3,
      "name": "Zone_Empty"
    },
    {
      "x": 5,
      "y": 8,
      "z": 3,
      "name": "Zone_Empty"
    }
  ],
  "entities": [
    {
      "Components": {
        "Transform": {
          "Position": {
            "X": 0.5,
            "Y": 5.0,
            "Z": 0.5
          },
          "Rotation": {
            "Pitch": 0.0,
            "Yaw": 0.0,
            "Roll": 0.0
          }
        },
        "TriggerVolume": {
          "Shape": {
            "Type": "Box",
            "Min": {
              "X": -4.0,
              "Y": -3.0,
              "Z": -4.0
            },
            "Max": {
              "X": 4.0,
              "Y": 3.0,
              "Z": 4.0
            }
          },
          "Effects": [
            {
              "Type": "PlaceBlock",
              "Event": "ENTER",
              "Interval": 0.0,
              "Delay": 0.0,
              "BlockType": "Extraction_Active",
              "Position": {
                "X": 0.0,
                "Y": -4.0,
                "Z": 0.0
              },
              "Origin": "VolumeOrigin",
              "ReplaceMode": "Always"
            },
            {
              "Type": "ShowEventTitle",
              "Event": "ENTER",
              "Interval": 0.0,
              "Delay": 0.0,
              "PrimaryTitle": "Extraction",
              "SecondaryTitle": "Stay 3 Seconds",
              "IsMajor": false,
              "Icon": "",
              "Duration": 1.0,
              "FadeInDuration": 0.10000000149011612,
              "FadeOutDuration": 0.3499999940395355
            },
            {
              "Type": "PlayVfx",
              "Event": "TICK",
              "Interval": 0.0,
              "Delay": 0.0,
              "ParticleSystem": "Sword_Signature_Dash_Trail",
              "Offset": {
                "X": 0.0,
                "Y": 0.0,
                "Z": -2.5
              },
              "AtEntity": true,
              "Scale": 5.0,
              "Rotation": {
                "X": 90.0,
                "Y": 180.0,
                "Z": 90.0
              },
              "Duration": 0.0
            },
            {
              "Type": "PlaySound",
              "Event": "TICK",
              "Interval": 0.0,
              "Delay": 0.0,
              "SoundEvent": "SFX_Extraction_Teleport",
              "Volume": 1.0,
              "Pitch": 1.0
            },
            {
              "Type": "PlayVfx",
              "Event": "ENTER",
              "Interval": 0.0,
              "Delay": 0.0,
              "ParticleSystem": "Extraction_Enter_Particles",
              "Offset": {
                "X": 0.0,
                "Y": -4.0,
                "Z": 0.0
              },
              "AtEntity": false,
              "Scale": 5.5,
              "Rotation": {
                "X": 0.0,
                "Y": 0.0,
                "Z": 0.0
              },
              "Duration": 0.0
            },
            {
              "Type": "EntityEffect",
              "Event": "TICK",
              "Interval": 0.0,
              "Delay": 0.0,
              "Effect": "Life_Effect",
              "Mode": "Apply",
              "Duration": -1.0
            },
            {
              "Type": "Teleport",
              "Event": "TICK",
              "Interval": 0.0,
              "Delay": 0.009999999776482582,
              "Position": {
                "X": 0.5,
                "Y": 205.0,
                "Z": 0.5
              },
              "World": "",
              "ResetVelocity": false,
              "RelativeToEntity": false,
              "RelativeToVolume": false,
              "UseRotation": false,
              "Rotation": {
                "X": 0.0,
                "Y": 0.0,
                "Z": 0.0
              }
            },
            {
              "Type": "PlaceBlock",
              "Event": "TICK",
              "Interval": 0.0,
              "Delay": 0.0,
              "BlockType": "Block_White",
              "Position": {
                "X": 0.0,
                "Y": -4.0,
                "Z": 0.0
              },
              "Origin": "VolumeOrigin",
              "ReplaceMode": "Always"
            },
            {
              "Type": "DisableVolume",
              "Event": "TICK",
              "Interval": 0.0,
              "Delay": 0.0,
              "MatchKey": "",
              "MatchValue": "",
              "Radius": 15.0,
              "Center": "Volume"
            },
            {
              "Type": "PlaySound",
              "Event": "ENTER",
              "Interval": 0.0,
              "Delay": 0.0,
              "SoundEvent": "SFX_Wood_Build",
              "Volume": 10.0,
              "Pitch": 5.0
            },
            {
              "Type": "PlaySound",
              "Event": "ENTER",
              "Interval": 0.0,
              "Delay": 0.0,
              "SoundEvent": "SFX_Arrow_Whistle",
              "Volume": 10.0,
              "Pitch": 1.0
            },
            {
              "Type": "PlaySound",
              "Event": "ENTER",
              "Interval": 0.0,
              "Delay": 0.25,
              "SoundEvent": "SFX_Arrow_Whistle",
              "Volume": 10.0,
              "Pitch": 0.8500000238418579
            },
            {
              "Type": "PlaceBlock",
              "Event": "TICK",
              "Interval": 0.0,
              "Delay": 28.5,
              "BlockType": "Extraction_Active",
              "Position": {
                "X": 0.0,
                "Y": -4.0,
                "Z": 0.0
              },
              "Origin": "VolumeOrigin",
              "ReplaceMode": "Always"
            },
            {
              "Type": "EnableVolume",
              "Event": "TICK",
              "Interval": 0.0,
              "Delay": 30.0,
              "MatchKey": "",
              "MatchValue": "",
              "Radius": 10.0,
              "Center": "Volume"
            }
          ],
          "Conditions": [
            {
              "Type": "CooldownCondition",
              "Event": "TICK",
              "Cooldown": 2.75,
              "Scope": "PER_PLAYER"
            }
          ],
          "Enabled": true,
          "TargetTypes": [
            "Player"
          ],
          "KeepLoaded": true,
          "Color": {
            "X": 0.0,
            "Y": 0.0784313753247261,
            "Z": 1.0
          }
        }
      }
    }
  ]
}